Workbook

Sheet Defunciones
A1: MEDIDAS DE MORTALIDAD
Z2: Tasa Especifica de Mortalidad | AG2: Tasa de Mortalidad Infantil | AL2: Tasa Tifipicada de Mortalidad
AA3: 2010 | AC3: 2020 | AG3: 2010 | AI3: 2020 | AL3: Hombre | AN3: Mujer
B4: TABLA ORIGINAL | K4: TABLA PRORRATEADA | Z4: Edades | AA4: Hombres | AB4: Mujeres | AC4: Hombres | AD4: Mujeres | AG4: Hombres | AH4: Mujeres | AI4: Hombres | AJ4: Mujeres | AL4: =((SUM(AM9:AM27))/Poblacion!Q24)*1000 -> 2.8519196 | AN4: =((SUM(AN9:AN27))/Poblacion!R24)*1000 -> 2.3738315
T5: Tasa Bruta de Mortalidad | Z5: 0 | AA5: =(N8/Poblacion!M5)*1000 -> 4.9706693 | AB5: =(O8/Poblacion!N5)*1000 -> 3.3820336 | AC5: =(Q8/Poblacion!Q5)*1000 -> 6.4290088 | AD5: =(R8/Poblacion!R5)*1000 -> 6.5623963 | AG5: =(N8/Nacimientos!C59)*1000 -> 12.881684 | AH5: =(O8/Nacimientos!D59)*1000 -> 8.8152524 | AI5: =(Q8/Nacimientos!E59)*1000 -> 7.3668645 | AJ5: =(R8/Nacimientos!F59)*1000 -> 7.5930218
B6: Edad inicial | C6: Edad Final | D6: 2010 | G6: 2020 | K6: Edad inicial | L6: Edad Final | M6: 2010 | P6: 2020 | T6: 2010 | V6: 2020 | Z6: 1 a 4 | AA6: =(N9/Poblacion!M6)*1000 -> 0.28108856 | AB6: =(O9/Poblacion!N6)*1000 -> 0.057591366 | AC6: =(Q9/Poblacion!Q6)*1000 -> 0.13440137 | AD6: =(R9/Poblacion!R6)*1000 -> 0.069355113
D7: Total | E7: Hombre | F7: Mujer | G7: Total | H7: Hombre | I7: Mujer | M7: Total | N7: Hombre | O7: Mujer | P7: Total | Q7: Hombre | R7: Mujer | T7: Hombres | U7: Mujeres | V7: Hombres | W7: Mujeres | Z7: 5 a 9 | AA7: =(N10/Poblacion!M7)*1000 -> 0.130681 | AB7: =(O10/Poblacion!N7)*1000 -> 0.089794313 | AC7: =(Q10/Poblacion!Q7)*1000 -> 0.25982538 | AD7: =(R10/Poblacion!R7)*1000 -> 0.053276796 | AG7: Global | AI7: Global | AM7: Numerador
B8: 0 | C8: 0 | D8: =E8+F8 -> 32 | E8: 19 | F8: 13 | G8: =H8+I8 -> 40 | H8: 20 | I8: 20 | K8: 0 | L8: 0 | M8: =N8+O8 -> 32.491367 | N8: =E8*(1+$E$33) -> 19.421286 | O8: =F8*(1+$F$33) -> 13.070081 | P8: =Q8+R8 -> 40.068376 | Q8: =H8*(1+$H$33) -> 20.034188 | R8: =I8*(1+$H$33) -> 20.034188 | T8: =(SUM(N8:N26)/Poblacion!M24)*1000 -> 1.9313063 | U8: =(SUM(O8:O26)/Poblacion!N24)*1000 -> 1.4983053 | V8: =(SUM(Q8:Q26)/Poblacion!Q24)*1000 -> 9.3095124 | W8: =(SUM(R8:R26)/Poblacion!R24)*1000 -> 5.9529724 | Z8: 10 a 14 | AA8: =(N11/Poblacion!M8)*1000 -> 0.044592319 | AB8: =(O11/Poblacion!N8)*1000 -> 0.18025115 | AC8: =(Q11/Poblacion!Q8)*1000 -> 0.14505747 | AD8: =(R11/Poblacion!R8)*1000 -> 0.30383367 | AG8: =((N8+O8)/(Nacimientos!C59+Nacimientos!D59))*1000 -> 10.865467 | AI8: =((Q8+R8)/(Nacimientos!E59+Nacimientos!F59))*1000 -> 7.4782337 | AM8: Hombres | AN8: Mujeres
B9: 1 | C9: 4 | D9: =E9+F9 -> 6 | E9: 5 | F9: 1 | G9: =H9+I9 -> 3 | H9: 2 | I9: 1 | K9: 1 | L9: 4 | M9: =N9+O9 -> 6.1162556 | N9: =E9*(1+$E$33) -> 5.1108647 | O9: =F9*(1+$F$33) -> 1.0053908 | P9: =Q9+R9 -> 3.0051282 | Q9: =H9*(1+$H$33) -> 2.0034188 | R9: =I9*(1+$H$33) -> 1.0017094 | Z9: 15 a 19 | AA9: =(N12/Poblacion!M9)*1000 -> 0.56553813 | AB9: =(O12/Poblacion!N9)*1000 -> 0.12996089 | AC9: =(Q12/Poblacion!Q9)*1000 -> 1.2103188 | AD9: =(R12/Poblacion!R9)*1000 -> 0.14589835 | AM9: =AA5/1000*Poblacion!Q5 -> 15.489685 | AN9: =AB5/1000*Poblacion!R5 -> 10.324932
B10: 5 | C10: 9 | D10: =E10+F10 -> 5 | E10: 3 | F10: 2 | G10: =H10+I10 -> 6 | H10: 5 | I10: 1 | K10: 5 | L10: 9 | M10: =N10+O10 -> 5.0773005 | N10: =E10*(1+$E$33) -> 3.0665188 | O10: =F10*(1+$F$33) -> 2.0107817 | P10: =Q10+R10 -> 6.0102564 | Q10: =H10*(1+$H$33) -> 5.008547 | R10: =I10*(1+$H$33) -> 1.0017094 | Z10: 20 a 24 | AA10: =(N13/Poblacion!M10)*1000 -> 0.75799708 | AB10: =(O13/Poblacion!N10)*1000 -> 0.4367489 | AC10: =(Q13/Poblacion!Q10)*1000 -> 2.0887844 | AD10: =(R13/Poblacion!R10)*1000 -> 0.61542271 | AM10: =AA6/1000*Poblacion!Q6 -> 4.1899728 | AN10: =AB6/1000*Poblacion!R6 -> 0.83180331
B11: 10 | C11: 14 | D11: =E11+F11 -> 5 | E11: 1 | F11: 4 | G11: =H11+I11 -> 9 | H11: 3 | I11: 6 | K11: 10 | L11: 14 | M11: =N11+O11 -> 5.0437363 | N11: =E11*(1+$E$33) -> 1.0221729 | O11: =F11*(1+$F$33) -> 4.0215633 | P11: =Q11+R11 -> 9.0153846 | Q11: =H11*(1+$H$33) -> 3.0051282 | R11: =I11*(1+$H$33) -> 6.0102564 | Z11: 25 a 29 | AA11: =(N14/Poblacion!M11)*1000 -> 1.11638 | AB11: =(O14/Poblacion!N11)*1000 -> 0.28489344 | AC11: =(Q14/Poblacion!Q11)*1000 -> 2.6831476 | AD11: =(R14/Poblacion!R11)*1000 -> 0.37651311 | AM11: =AA7/1000*Poblacion!Q7 -> 2.5190839 | AN11: =AB7/1000*Poblacion!R7 -> 1.6883111
B12: 15 | C12: 19 | D12: =E12+F12 -> 16 | E12: 13 | F12: 3 | G12: =H12+I12 -> 29 | H12: 26 | I12: 3 | K12: 15 | L12: 19 | M12: =N12+O12 -> 16.304421 | N12: =E12*(1+$E$33) -> 13.288248 | O12: =F12*(1+$F$33) -> 3.0161725 | P12: =Q12+R12 -> 29.049573 | Q12: =H12*(1+$H$33) -> 26.044444 | R12: =I12*(1+$H$33) -> 3.0051282 | Z12: 30 a 34 | AA12: =(N15/Poblacion!M12)*1000 -> 1.0091942 | AB12: =(O15/Poblacion!N12)*1000 -> 0.19812345 | AC12: =(Q15/Poblacion!Q12)*1000 -> 3.3791146 | AD12: =(R15/Poblacion!R12)*1000 -> 0.82393539 | AM12: =AA8/1000*Poblacion!Q8 -> 0.92381064 | AN12: =AB8/1000*Poblacion!R8 -> 3.5656207
B13: 20 | C13: 24 | D13: =E13+F13 -> 27 | E13: 17 | F13: 10 | G13: =H13+I13 -> 58 | H13: 45 | I13: 13 | K13: 20 | L13: 24 | M13: =N13+O13 -> 27.430848 | N13: =E13*(1+$E$33) -> 17.37694 | O13: =F13*(1+$F$33) -> 10.053908 | P13: =Q13+R13 -> 58.099145 | Q13: =H13*(1+$H$33) -> 45.076923 | R13: =I13*(1+$H$33) -> 13.022222 | Z13: 35 a 39 | AA13: =(N16/Poblacion!M13)*1000 -> 1.3072661 | AB13: =(O16/Poblacion!N13)*1000 -> 0.24600946 | AC13: =(Q16/Poblacion!Q13)*1000 -> 4.585402 | AD13: =(R16/Poblacion!R13)*1000 -> 1.1220704 | AM13: =AA9/1000*Poblacion!Q9 -> 12.169626 | AN13: =AB9/1000*Poblacion!R9 -> 2.676858
B14: 25 | C14: 29 | D14: =E14+F14 -> 28 | E14: 22 | F14: 6 | G14: =H14+I14 -> 64 | H14: 56 | I14: 8 | K14: 25 | L14: 29 | M14: =N14+O14 -> 28.52015 | N14: =E14*(1+$E$33) -> 22.487805 | O14: =F14*(1+$F$33) -> 6.032345 | P14: =Q14+R14 -> 64.109402 | Q14: =H14*(1+$H$33) -> 56.095726 | R14: =I14*(1+$H$33) -> 8.0136752 | Z14: 40 a 44 | AA14: =(N17/Poblacion!M14)*1000 -> 1.0883482 | AB14: =(O17/Poblacion!N14)*1000 -> 0.63503938 | AC14: =(Q17/Poblacion!Q14)*1000 -> 6.1953266 | AD14: =(R17/Poblacion!R14)*1000 -> 2.1028735 | AM14: =AA10/1000*Poblacion!Q10 -> 16.357924 | AN14: =AB10/1000*Poblacion!R10 -> 9.2415199
B15: 30 | C15: 34 | D15: =E15+F15 -> 22 | E15: 18 | F15: 4 | G15: =H15+I15 -> 83 | H15: 66 | I15: 17 | K15: 30 | L15: 34 | M15: =N15+O15 -> 22.420676 | N15: =E15*(1+$E$33) -> 18.399113 | O15: =F15*(1+$F$33) -> 4.0215633 | P15: =Q15+R15 -> 83.14188 | Q15: =H15*(1+$H$33) -> 66.112821 | R15: =I15*(1+$H$33) -> 17.02906 | Z15: 45 a 49 | AA15: =(N18/Poblacion!M15)*1000 -> 2.2216791 | AB15: =(O18/Poblacion!N15)*1000 -> 0.61521172 | AC15: =(Q18/Poblacion!Q15)*1000 -> 7.9770571 | AD15: =(R18/Poblacion!R15)*1000 -> 3.1757699 | AM15: =AA11/1000*Poblacion!Q11 -> 23.339807 | AN15: =AB11/1000*Poblacion!R11 -> 6.0636495
B16: 35 | C16: 39 | D16: =E16+F16 -> 28 | E16: 23 | F16: 5 | G16: =H16+I16 -> 104 | H16: 82 | I16: 22 | K16: 35 | L16: 39 | M16: =N16+O16 -> 28.536932 | N16: =E16*(1+$E$33) -> 23.509978 | O16: =F16*(1+$F$33) -> 5.0269542 | P16: =Q16+R16 -> 104.17778 | Q16: =H16*(1+$H$33) -> 82.140171 | R16: =I16*(1+$H$33) -> 22.037607 | Z16: 50 a 54 | AA16: =(N19/Poblacion!M16)*1000 -> 2.265324 | AB16: =(O19/Poblacion!N16)*1000 -> 1.2807696 | AC16: =(Q19/Poblacion!Q16)*1000 -> 10.153174 | AD16: =(R19/Poblacion!R16)*1000 -> 5.0910614 | AM16: =AA12/1000*Poblacion!Q12 -> 19.745018 | AN16: =AB12/1000*Poblacion!R12 -> 4.0948066
B17: 40 | C17: 44 | D17: =E17+F17 -> 30 | E17: 18 | F17: 12 | G17: =H17+I17 -> 144 | H17: 104 | I17: 40 | K17: 40 | L17: 44 | M17: =N17+O17 -> 30.463803 | N17: =E17*(1+$E$33) -> 18.399113 | O17: =F17*(1+$F$33) -> 12.06469 | P17: =Q17+R17 -> 144.24615 | Q17: =H17*(1+$H$33) -> 104.17778 | R17: =I17*(1+$H$33) -> 40.068376 | Z17: 55 a 59 | AA17: =(N20/Poblacion!M17)*1000 -> 3.2400008 | AB17: =(O20/Poblacion!N17)*1000 -> 2.2953144 | AC17: =(Q20/Poblacion!Q17)*1000 -> 18.573425 | AD17: =(R20/Poblacion!R17)*1000 -> 9.1361097 | AM17: =AA13/1000*Poblacion!Q13 -> 23.41759 | AN17: =AB13/1000*Poblacion!R13 -> 4.8316574
B18: 45 | C18: 49 | D18: =E18+F18 -> 42 | E18: 32 | F18: 10 | G18: =H18+I18 -> 194 | H18: 133 | I18: 61 | K18: 45 | L18: 49 | M18: =N18+O18 -> 42.763443 | N18: =E18*(1+$E$33) -> 32.709534 | O18: =F18*(1+$F$33) -> 10.053908 | P18: =Q18+R18 -> 194.33162 | Q18: =H18*(1+$H$33) -> 133.22735 | R18: =I18*(1+$H$33) -> 61.104274 | Z18: 60 a 64 | AA18: =(N21/Poblacion!M18)*1000 -> 5.8345892 | AB18: =(O21/Poblacion!N18)*1000 -> 3.5298152 | AC18: =(Q21/Poblacion!Q18)*1000 -> 24.412499 | AD18: =(R21/Poblacion!R18)*1000 -> 14.47644 | AM18: =AA14/1000*Poblacion!Q14 -> 18.301166 | AN18: =AB14/1000*Poblacion!R14 -> 12.100108
B19: 50 | C19: 54 | D19: =E19+F19 -> 44 | E19: 27 | F19: 17 | G19: =H19+I19 -> 254 | H19: 161 | I19: 93 | K19: 50 | L19: 54 | M19: =N19+O19 -> 44.690314 | N19: =E19*(1+$E$33) -> 27.59867 | O19: =F19*(1+$F$33) -> 17.091644 | P19: =Q19+R19 -> 254.43419 | Q19: =H19*(1+$H$33) -> 161.27521 | R19: =I19*(1+$H$33) -> 93.158974 | Z19: 65 a 69 | AA19: =(N22/Poblacion!M19)*1000 -> 9.4031847 | AB19: =(O22/Poblacion!N19)*1000 -> 7.3604907 | AC19: =(Q22/Poblacion!Q19)*1000 -> 36.161304 | AD19: =(R22/Poblacion!R19)*1000 -> 20.630712 | AM19: =AA15/1000*Poblacion!Q15 -> 37.104964 | AN19: =AB15/1000*Poblacion!R15 -> 11.83715
B20: 55 | C20: 59 | D20: =E20+F20 -> 51 | E20: 29 | F20: 22 | G20: =H20+I20 -> 399 | H20: 256 | I20: 143 | K20: 55 | L20: 59 | M20: =N20+O20 -> 51.761614 | N20: =E20*(1+$E$33) -> 29.643016 | O20: =F20*(1+$F$33) -> 22.118598 | P20: =Q20+R20 -> 399.68205 | Q20: =H20*(1+$H$33) -> 256.43761 | R20: =I20*(1+$H$33) -> 143.24444 | Z20: 70 a 74 | AA20: =(N23/Poblacion!M20)*1000 -> 16.605006 | AB20: =(O23/Poblacion!N20)*1000 -> 13.36577 | AC20: =(Q23/Poblacion!Q20)*1000 -> 55.471223 | AD20: =(R23/Poblacion!R20)*1000 -> 35.243942 | AM20: =AA16/1000*Poblacion!Q16 -> 35.982897 | AN20: =AB16/1000*Poblacion!R16 -> 23.43621
... B23: 70 | C23: 74 | D23: =E23+F23 -> 69 | E23: 35 | F23: 34 | G23: =H23+I23 -> 474 | H23: 281 | I23: 193 | K23: 70 | L23: 74 | M23: =N23+O23 -> 69.959342 | N23: =E23*(1+$E$33) -> 35.776053 | O23: =F23*(1+$F$33) -> 34.183288 | P23: =Q23+R23 -> 474.81026 | Q23: =H23*(1+$H$33) -> 281.48034 | R23: =I23*(1+$H$33) -> 193.32991 | Z23: 85 y más | AA23: =(N26/Poblacion!M23)*1000 -> 116.98582 | AB23: =(O26/Poblacion!N23)*1000 -> 93.312858 | AC23: =(Q26/Poblacion!Q23)*1000 -> 207.98843 | AD23: =(R26/Poblacion!R23)*1000 -> 156.42339 | AM23: =AA19/1000*Poblacion!Q19 -> 76.841291 | AN23: =AB19/1000*Poblacion!R19 -> 67.188067
B24: 75 | C24: 79 | D24: =E24+F24 -> 91 | E24: 38 | F24: 53 | G24: =H24+I24 -> 375 | H24: 200 | I24: 175 | K24: 75 | L24: 79 | M24: =N24+O24 -> 92.128286 | N24: =E24*(1+$E$33) -> 38.842572 | O24: =F24*(1+$F$33) -> 53.285714 | P24: =Q24+R24 -> 375.64103 | Q24: =H24*(1+$H$33) -> 200.34188 | R24: =I24*(1+$H$33) -> 175.29915 | AM24: =AA20/1000*Poblacion!Q20 -> 84.259593 | AN24: =AB20/1000*Poblacion!R20 -> 73.317655
B25: 80 | C25: 84 | D25: =E25+F25 -> 66 | E25: 24 | F25: 42 | G25: =H25+I25 -> 296 | H25: 143 | I25: 153 | K25: 80 | L25: 84 | M25: =N25+O25 -> 66.758566 | N25: =E25*(1+$E$33) -> 24.532151 | O25: =F25*(1+$F$33) -> 42.226415 | P25: =Q25+R25 -> 296.50598 | Q25: =H25*(1+$H$33) -> 143.24444 | R25: =I25*(1+$H$33) -> 153.26154 | AM25: =AA21/1000*Poblacion!Q21 -> 81.251439 | AN25: =AB21/1000*Poblacion!R21 -> 94.734599
B26: 85 | C26: 100 | D26: =E26+F26 -> 140 | E26: 58 | F26: 82 | G26: =H26+I26 -> 449 | H26: 192 | I26: 257 | K26: 85 | L26: 100 | M26: =N26+O26 -> 141.72808 | N26: =E26*(1+$E$33) -> 59.286031 | O26: =F26*(1+$F$33) -> 82.442049 | P26: =Q26+R26 -> 449.76752 | Q26: =H26*(1+$H$33) -> 192.32821 | R26: =I26*(1+$H$33) -> 257.43932 | AM26: =AA22/1000*Poblacion!Q22 -> 48.896346 | AN26: =AB22/1000*Poblacion!R22 -> 69.889677
B27: no especificados | D27: =E27+F27 -> 12 | E27: 10 | F27: 2 | G27: =H27+I27 -> 7 | H27: 4 | I27: 3 | AM27: =AA23/1000*Poblacion!Q23 -> 108.17752 | AN27: =AB23/1000*Poblacion!R23 -> 153.57293
E31: Alpha | H31: Alpha
E32: Hombres | F32: Mujeres | H32: Hombres | I32: Mujeres
E33: =E27/SUM(E8:E26) -> 0.022172949 | F33: =F27/SUM(F8:F26) -> 0.0053908356 | H33: =H27/((SUM(H8:H26))-H27) -> 0.0017094017 | I33: =I27/((SUM(I8:I26))-I27) -> 0.0019047619

Sheet Nacimientos
A1: NACIMIENTOS
B3: DESCARGA DE INEGI | C3: .
C4: 2009 | E4: 2010 | G4: 2011 | I4: 2019 | K4: 2020
B5: edad | C5: Hombre | D5: Mujer | E5: Hombre | F5: Mujer | G5: Hombre | H5: Mujer | I5: Hombre | J5: Mujer | K5: Hombre | L5: Mujer
B6: Menor de 15 años | C6: 3 | D6: 8 | E6: 3 | F6: 6 | G6: 3 | H6: 7 | I6: 3 | J6: 7 | K6: 4 | L6: 2
B7: De 15 a 19 años | C7: 283 | D7: 275 | E7: 270 | F7: 283 | G7: 341 | H7: 292 | I7: 484 | J7: 429 | K7: 254 | L7: 235
B8: De 20 a 24 años | C8: 405 | D8: 393 | E8: 438 | F8: 410 | G8: 531 | H8: 500 | I8: 827 | J8: 800 | K8: 559 | L8: 587
B9: De 25 a 29 años | C9: 312 | D9: 305 | E9: 315 | F9: 334 | G9: 525 | H9: 453 | I9: 883 | J9: 878 | K9: 648 | L9: 592
B10: De 30 a 34 años | C10: 180 | D10: 204 | E10: 173 | F10: 193 | G10: 260 | H10: 285 | I10: 658 | J10: 641 | K10: 442 | L10: 468
B11: De 35 a 39 años | C11: 86 | D11: 81 | E11: 89 | F11: 101 | G11: 165 | H11: 143 | I11: 298 | J11: 277 | K11: 195 | L11: 197
B12: De 40 a 44 años | C12: 24 | D12: 20 | E12: 21 | F12: 12 | G12: 19 | H12: 28 | I12: 70 | J12: 67 | K12: 49 | L12: 49
B13: De 45 a 49 años | D13: 3 | E13: 1 | F13: 2 | G13: 1 | H13: 2 | I13: 2 | J13: 3 | K13: 6 | L13: 1
B14: De 50 y más años | I14: 1 | J14: 2
B15: No especificado | C15: 20 | D15: 19 | E15: 18 | F15: 53 | G15: 37 | H15: 36 | I15: 12 | J15: 7 | K15: 44 | L15: 35
B19: PRORRATEO
C20: 2009 | E20: 2010 | G20: 2011 | I20: 2019 | K20: 2020
B21: edad | C21: Hombre | D21: Mujer | E21: Hombre | F21: Mujer | G21: Hombre | H21: Mujer | I21: Hombre | J21: Mujer | K21: Hombre | L21: Mujer
B22: Menor de 15 años | C22: =C6+C6*($C$15/SUM($C$6:$C$14)) -> 3.0464037 | D22: =D6+D6*($D$15/SUM($D$6:$D$14)) -> 8.1179209 | E22: =E6+E6*($E$15/SUM($E$6:$E$14)) -> 3.0412214 | F22: =F6+F6*($F$15/SUM($F$6:$F$14)) -> 6.2371365 | G22: =G6+G6*($G$15/SUM($G$6:$G$14)) -> 3.0601626 | H22: =H6+H6*($H$15/SUM($H$6:$H$14)) -> 7.1473684 | I22: =I6+I6*($I$15/SUM($I$6:$I$14)) -> 3.0111593 | J22: =J6+J6*($J$15/SUM($J$6:$J$14)) -> 7.0157861 | K22: =K6+K6*($K$15/SUM($K$6:$K$14)) -> 4.0815948 | L22: =L6+L6*($L$15/SUM($L$6:$L$14)) -> 2.0328484
B23: De 15 a 19 años | C23: =C7+C7*($C$15/SUM($C$6:$C$14)) -> 287.37742 | D23: =D7+D7*($D$15/SUM($D$6:$D$14)) -> 279.05353 | E23: =E7+E7*($E$15/SUM($E$6:$E$14)) -> 273.70992 | F23: =F7+F7*($F$15/SUM($F$6:$F$14)) -> 294.18494 | G23: =G7+G7*($G$15/SUM($G$6:$G$14)) -> 347.83848 | H23: =H7+H7*($H$15/SUM($H$6:$H$14)) -> 298.14737 | I23: =I7+I7*($I$15/SUM($I$6:$I$14)) -> 485.80037 | J23: =J7+J7*($J$15/SUM($J$6:$J$14)) -> 429.96746 | K23: =K7+K7*($K$15/SUM($K$6:$K$14)) -> 259.18127 | L23: =L7+L7*($L$15/SUM($L$6:$L$14)) -> 238.85969
B24: De 20 a 24 años | C24: =C8+C8*($C$15/SUM($C$6:$C$14)) -> 411.2645 | D24: =D8+D8*($D$15/SUM($D$6:$D$14)) -> 398.79286 | E24: =E8+E8*($E$15/SUM($E$6:$E$14)) -> 444.01832 | F24: =F8+F8*($F$15/SUM($F$6:$F$14)) -> 426.20433 | G24: =G8+G8*($G$15/SUM($G$6:$G$14)) -> 541.64878 | H24: =H8+H8*($H$15/SUM($H$6:$H$14)) -> 510.52632 | I24: =I8+I8*($I$15/SUM($I$6:$I$14)) -> 830.07626 | J24: =J8+J8*($J$15/SUM($J$6:$J$14)) -> 801.80412 | K24: =K8+K8*($K$15/SUM($K$6:$K$14)) -> 570.40287 | L24: =L8+L8*($L$15/SUM($L$6:$L$14)) -> 596.64101
B25: De 25 a 29 años | C25: =C9+C9*($C$15/SUM($C$6:$C$14)) -> 316.82599 | D25: =D9+D9*($D$15/SUM($D$6:$D$14)) -> 309.49573 | E25: =E9+E9*($E$15/SUM($E$6:$E$14)) -> 319.32824 | F25: =F9+F9*($F$15/SUM($F$6:$F$14)) -> 347.2006 | G25: =G9+G9*($G$15/SUM($G$6:$G$14)) -> 535.52846 | H25: =H9+H9*($H$15/SUM($H$6:$H$14)) -> 462.53684 | I25: =I9+I9*($I$15/SUM($I$6:$I$14)) -> 886.28456 | J25: =J9+J9*($J$15/SUM($J$6:$J$14)) -> 879.98003 | K25: =K9+K9*($K$15/SUM($K$6:$K$14)) -> 661.21836 | L25: =L9+L9*($L$15/SUM($L$6:$L$14)) -> 601.72313
B26: De 30 a 34 años | C26: =C10+C10*($C$15/SUM($C$6:$C$14)) -> 182.78422 | D26: =D10+D10*($D$15/SUM($D$6:$D$14)) -> 207.00698 | E26: =E10+E10*($E$15/SUM($E$6:$E$14)) -> 175.3771 | F26: =F10+F10*($F$15/SUM($F$6:$F$14)) -> 200.62789 | G26: =G10+G10*($G$15/SUM($G$6:$G$14)) -> 265.21409 | H26: =H10+H10*($H$15/SUM($H$6:$H$14)) -> 291 | I26: =I10+I10*($I$15/SUM($I$6:$I$14)) -> 660.44761 | J26: =J10+J10*($J$15/SUM($J$6:$J$14)) -> 642.44555 | K26: =K10+K10*($K$15/SUM($K$6:$K$14)) -> 451.01623 | L26: =L10+L10*($L$15/SUM($L$6:$L$14)) -> 475.68653
B27: De 35 a 39 años | C27: =C11+C11*($C$15/SUM($C$6:$C$14)) -> 87.33024 | D27: =D11+D11*($D$15/SUM($D$6:$D$14)) -> 82.193949 | E27: =E11+E11*($E$15/SUM($E$6:$E$14)) -> 90.222901 | F27: =F11+F11*($F$15/SUM($F$6:$F$14)) -> 104.9918 | G27: =G11+G11*($G$15/SUM($G$6:$G$14)) -> 168.30894 | H27: =H11+H11*($H$15/SUM($H$6:$H$14)) -> 146.01053 | I27: =I11+I11*($I$15/SUM($I$6:$I$14)) -> 299.10849 | J27: =J11+J11*($J$15/SUM($J$6:$J$14)) -> 277.62468 | K27: =K11+K11*($K$15/SUM($K$6:$K$14)) -> 198.97775 | L27: =L11+L11*($L$15/SUM($L$6:$L$14)) -> 200.23557
B28: De 40 a 44 años | C28: =C12+C12*($C$15/SUM($C$6:$C$14)) -> 24.37123 | D28: =D12+D12*($D$15/SUM($D$6:$D$14)) -> 20.294802 | E28: =E12+E12*($E$15/SUM($E$6:$E$14)) -> 21.28855 | F28: =F12+F12*($F$15/SUM($F$6:$F$14)) -> 12.474273 | G28: =G12+G12*($G$15/SUM($G$6:$G$14)) -> 19.38103 | H28: =H12+H12*($H$15/SUM($H$6:$H$14)) -> 28.589474 | I28: =I12+I12*($I$15/SUM($I$6:$I$14)) -> 70.260384 | J28: =J12+J12*($J$15/SUM($J$6:$J$14)) -> 67.151095 | K28: =K12+K12*($K$15/SUM($K$6:$K$14)) -> 49.999536 | L28: =L12+L12*($L$15/SUM($L$6:$L$14)) -> 49.804786
B29: De 45 a 49 años | C29: =C13+C13*($C$15/SUM($C$6:$C$14)) -> 0 | D29: =D13+D13*($D$15/SUM($D$6:$D$14)) -> 3.0442203 | E29: =E13+E13*($E$15/SUM($E$6:$E$14)) -> 1.0137405 | F29: =F13+F13*($F$15/SUM($F$6:$F$14)) -> 2.0790455 | G29: =G13+G13*($G$15/SUM($G$6:$G$14)) -> 1.0200542 | H29: =H13+H13*($H$15/SUM($H$6:$H$14)) -> 2.0421053 | I29: =I13+I13*($I$15/SUM($I$6:$I$14)) -> 2.0074396 | J29: =J13+J13*($J$15/SUM($J$6:$J$14)) -> 3.0067655 | K29: =K13+K13*($K$15/SUM($K$6:$K$14)) -> 6.1223922 | L29: =L13+L13*($L$15/SUM($L$6:$L$14)) -> 1.0164242
B30: De 50 y más años | C30: =C14+C14*($C$15/SUM($C$6:$C$14)) -> 0 | D30: =D14+D14*($D$15/SUM($D$6:$D$14)) -> 0 | E30: =E14+E14*($E$15/SUM($E$6:$E$14)) -> 0 | F30: =F14+F14*($F$15/SUM($F$6:$F$14)) -> 0 | G30: =G14+G14*($G$15/SUM($G$6:$G$14)) -> 0 | H30: =H14+H14*($H$15/SUM($H$6:$H$14)) -> 0 | I30: =I14+I14*($I$15/SUM($I$6:$I$14)) -> 1.0037198 | J30: =J14+J14*($J$15/SUM($J$6:$J$14)) -> 2.0045103 | K30: 0 | L30: 0
B34: PROMEDIO
C35: 2010 | E35: 2020
B36: edad | C36: Hombre | D36: Mujer | E36: Hombre | F36: Mujer
B37: Menor de 15 años | C37: =(C22+E22+G22)/3 -> 3.0492626 | D37: =(D22+F22+H22)/3 -> 7.1674753 | E37: =(I22+K22)/2 -> 3.5463771 | F37: =(J22+L22)/2 -> 4.5243173
B38: De 15 a 19 años | C38: =(C23+E23+G23)/3 -> 302.97527 | D38: =(D23+F23+H23)/3 -> 290.46194 | E38: =(I23+K23)/2 -> 372.49082 | F38: =(J23+L23)/2 -> 334.41358
B39: De 20 a 24 años | C39: =(C24+E24+G24)/3 -> 465.64387 | D39: =(D24+F24+H24)/3 -> 445.1745 | E39: =(I24+K24)/2 -> 700.23956 | F39: =(J24+L24)/2 -> 699.22257
B40: De 25 a 29 años | C40: =(C25+E25+G25)/3 -> 390.5609 | D40: =(D25+F25+H25)/3 -> 373.07772 | E40: =(I25+K25)/2 -> 773.75146 | F40: =(J25+L25)/2 -> 740.85158
B41: De 30 a 34 años | C41: =(C26+E26+G26)/3 -> 207.7918 | D41: =(D26+F26+H26)/3 -> 232.87829 | E41: =(I26+K26)/2 -> 555.73192 | F41: =(J26+L26)/2 -> 559.06604
B42: De 35 a 39 años | C42: =(C27+E27+G27)/3 -> 115.28736 | D42: =(D27+F27+H27)/3 -> 111.06542 | E42: =(I27+K27)/2 -> 249.04312 | F42: =(J27+L27)/2 -> 238.93012
B43: De 40 a 44 años | C43: =(C28+E28+G28)/3 -> 21.68027 | D43: =(D28+F28+H28)/3 -> 20.45285 | E43: =(I28+K28)/2 -> 60.12996 | F43: =(J28+L28)/2 -> 58.477941
B44: De 45 a 49 años | C44: =(C29+E29+G29)/3 -> 0.67793155 | D44: =(D29+F29+H29)/3 -> 2.388457 | E44: =(I29+K29)/2 -> 4.0649159 | F44: =(J29+L29)/2 -> 2.0115948
B45: De 50 y más años | C45: =(C30+E30+G30)/3 -> 0 | D45: =(D30+F30+H30)/3 -> 0 | E45: =(I30+K30)/2 -> 0.50185989 | F45: =(J30+L30)/2 -> 1.0022552
B49: AGREGACIÓN DE GRUPOS
C50: 2010 | E50: 2020
...

Sheet Poblacion
A1: POBLACION
A3: Grupos quinquenales | D3: Censo 2010 | G3: Censo 2020 | J3: Tasa geometrica | M3: Proyeccion mitad de año 2010 | Q3: Proyeccion mitad de año 2020
A4: Edad inicial | B4: Edad final | D4: Hombres | E4: Mujeres | G4: Hombres | H4: Mujeres | J4: Hombres | K4: Mujeres | M4: Hombres | N4: Mujeres | O4: Total | Q4: Hombres | R4: Mujeres | S4: Total
A5: 0 | B5: 0 | D5: 5800 | E5: 5528 | G5: 5414 | H5: 5201 | J5: -0.0070293241 | K5: -0.0062260648 | M5: 3907.1773 | N5: 3864.5627 | O5: 7771.74 | Q5: 3116.2172 | R5: 3052.8769 | S5: 6169.0941
A6: 1 | B6: 4 | D6: 51967 | E6: 24602 | G6: 24052 | H6: 23511 | J6: -0.075876088 | K6: -0.004635263 | M6: 18182.401 | N6: 17457.319 | O6: 35639.719 | Q6: 14906.237 | R6: 14443.195 | S6: 29349.432
A7: 5 | B7: 9 | D7: 29053 | E7: 28035 | G7: 31348 | H7: 30369 | J7: 0.0078178242 | K7: 0.0082246149 | M7: 23465.682 | N7: 22393.196 | O7: 45858.879 | Q7: 19276.589 | R7: 18801.983 | S7: 38078.571
A8: 10 | B8: 14 | D8: 25563 | E8: 24867 | G8: 32113 | H8: 31042 | J8: 0.023640323 | K8: 0.022978371 | M8: 22922.623 | N8: 22310.889 | O8: 45233.512 | Q8: 20716.811 | R8: 19781.403 | S8: 40498.214
A9: 15 | B9: 19 | D9: 24223 | E9: 24094 | G9: 29781 | H9: 28727 | J9: 0.021383644 | K9: 0.018177614 | M9: 23496.644 | N9: 23208.308 | O9: 46704.953 | Q9: 21518.666 | R9: 20597.411 | S9: 42116.077
A10: 20 | B10: 24 | D10: 27557 | E10: 27601 | G10: 30355 | H10: 30026 | J10: 0.0099544249 | K10: 0.0086628889 | M10: 22924.811 | N10: 23019.882 | O10: 45944.694 | Q10: 21580.458 | R10: 21159.801 | S10: 42740.259
A11: 25 | B11: 29 | D11: 27704 | E11: 27688 | G11: 30217 | H11: 30588 | J11: 0.0089332174 | K11: 0.01025488 | M11: 20143.504 | N11: 21174.039 | O11: 41317.543 | Q11: 20906.686 | R11: 21283.921 | S11: 42190.607
A12: 30 | B12: 34 | D12: 25820 | E12: 52599 | G12: 30522 | H12: 31113 | J12: 0.017283595 | K12: -0.052361036 | M12: 18231.488 | N12: 20298.27 | O12: 38529.759 | Q12: 19565.131 | R12: 20667.955 | S12: 40233.086
A13: 35 | B13: 39 | D13: 23177 | E13: 23125 | G13: 29594 | H13: 29956 | J13: 0.025350396 | K13: 0.026864291 | M13: 17984.079 | N13: 20433.987 | O13: 38418.067 | Q13: 17913.407 | R13: 19640.129 | S13: 37553.535
A14: 40 | B14: 44 | D14: 17755 | E14: 17704 | G14: 26177 | H14: 26785 | J14: 0.040564907 | K14: 0.043322369 | M14: 16905.539 | N14: 18998.334 | O14: 35903.873 | Q14: 16815.543 | R14: 19054.107 | S14: 35869.65
A15: 45 | B15: 49 | D15: 13355 | E15: 13443 | G15: 22942 | H15: 22890 | J15: 0.056985779 | K15: 0.056029498 | M15: 14722.889 | N15: 16342.192 | O15: 31065.081 | Q15: 16701.316 | R15: 19240.775 | S15: 35942.091
A16: 50 | B16: 54 | D16: 9828 | E16: 10571 | G16: 18324 | H16: 18815 | J16: 0.065889677 | K16: 0.060831982 | M16: 12183.1 | N16: 13344.823 | O16: 25527.923 | Q16: 15884.216 | R16: 18298.537 | S16: 34182.753
... A22: 80 | B22: 84 | D22: 964 | E22: 1274 | G22: 1747 | H22: 2363 | J22: 0.062792247 | K22: 0.06532148 | M22: 706.93543 | N22: 1098.914 | O22: 1805.8494 | Q22: 1409.0309 | R22: 1818.8317 | S22: 3227.8626
A23: 85 y mas | D23: 732 | E23: 1077 | G23: 1209 | H23: 1849 | J23: 0.052738454 | K23: 0.056919426 | M23: 506.77963 | N23: 883.50148 | O23: 1390.2811 | Q23: 924.70626 | R23: 1645.7853 | S23: 2570.4915
A24: TOTAL | D24: 303853 | E24: 305038 | G24: 350361 | H24: 354406 | J24: 0.014694631 | K24: 0.015483449 | M24: 238698.55 | N24: 248947.92 | O24: 487646.47 | Q24: 252215.88 | R24: 265530.79 | S24: 517746.67
A25: TOTAL GLOBAL | E25: =D24+E24 -> 608891 | H25: =G24+H24 -> 704767 | K25: 0.015090479

Sheet Causas de Mortalidad
A1: CAUSAS DE MORTALIDAD
K3: HOMBRES | V3: MUJERES
A4: 2010 | E4: 2020 | K4: Tasa de Mortalidad por causa | P4: Proporción por Causa | V4: Tasa de Mortalidad por causa | AA4: Proporción por Causa
B5: Hombre | C5: Mujer | F5: Hombre | G5: Mujer | K5: 2010 | M5: 2020 | P5: 2010 | R5: 2020 | V5: 2010 | X5: 2020 | AA5: 2010 | AC5: 2020
A6: (01) Enfermedades infecciosas intestinales | B6: 1 | C6: 2 | E6: (01) Enfermedades infecciosas intestinales | F6: 5 | G6: 5
A7: (02) Tuberculosis | E7: (02) Tuberculosis | F7: 2 | K7: Causa | L7: TMPC | M7: Causa | N7: TMPC | P7: Causa | Q7: PPC | R7: Causa | S7: PPC | V7: Causa | W7: TMPC | X7: Causa | Y7: TMPC | AA7: Causa | AB7: PPC | AC7: Causa | AD7: PPC
A8: (03) Otras enfermedades bacterianas | E8: (03) Otras enfermedades bacterianas | F8: 4 | G8: 7 | K8: (01) Enfermedades infecciosas intestinales | L8: =(B6/Poblacion!$M$24)*1000 -> 0.0041893846 | M8: (01) Enfermedades infecciosas intestinales | N8: =(F6/Poblacion!$Q$24)*1000 -> 0.019824287 | P8: (01) Enfermedades infecciosas intestinales | Q8: =(B6/$B$53)*100 -> 0.21691974 | R8: (01) Enfermedades infecciosas intestinales | S8: =(F6/$F$53)*100 -> 0.21294719 | V8: (01) Enfermedades infecciosas intestinales | W8: =(C6/Poblacion!$N$24)*1000 -> 0.0080338088 | X8: (01) Enfermedades infecciosas intestinales | Y8: =(G6/Poblacion!$R$24)*1000 -> 0.018830208 | AA8: (01) Enfermedades infecciosas intestinales | AB8: =(C6/$C$53)*100 -> 0.53619303 | AC8: (01) Enfermedades infecciosas intestinales | AD8: =(G6/$G$53)*100 -> 0.3164557
A9: (05) Otras enfermedades infecciosas y parasitarias y efectos tardíos de las enfermedades infecciosas y parasitarias | E9: (05) Otras enfermedades infecciosas y parasitarias y efectos tardíos de las enfermedades infecciosas y parasitarias | F9: 1 | K9: (02) Tuberculosis | L9: 0 | M9: (02) Tuberculosis | N9: =(F7/Poblacion!$Q$24)*1000 -> 0.0079297149 | P9: (02) Tuberculosis | Q9: 0 | R9: (02) Tuberculosis | S9: =(F7/$F$53)*100 -> 0.085178876 | V9: (02) Tuberculosis | W9: 0 | X9: (02) Tuberculosis | Y9: 0 | AA9: (02) Tuberculosis | AB9: 0 | AC9: (02) Tuberculosis | AD9: 0
A10: (06) Enfermedades víricas | B10: 2 | C10: 3 | E10: (06) Enfermedades víricas | F10: 565 | G10: 283 | K10: (03) Otras enfermedades bacterianas | L10: 0 | M10: (03) Otras enfermedades bacterianas | N10: =(F8/Poblacion!$Q$24)*1000 -> 0.01585943 | P10: (03) Otras enfermedades bacterianas | Q10: 0 | R10: (03) Otras enfermedades bacterianas | S10: =(F8/$F$53)*100 -> 0.17035775 | V10: (03) Otras enfermedades bacterianas | W10: 0 | X10: (03) Otras enfermedades bacterianas | Y10: =(G8/Poblacion!$R$24)*1000 -> 0.026362291 | AA10: (03) Otras enfermedades bacterianas | AB10: 0 | AC10: (03) Otras enfermedades bacterianas | AD10: =(G8/$G$53)*100 -> 0.44303797
A11: (08) Tumores malignos del labio, de la cavidad bucal y de la faringe | B11: 1 | C11: 1 | E11: (08) Tumores malignos del labio, de la cavidad bucal y de la faringe | F11: 4 | G11: 2 | K11: (05) Otras enfermedades infecciosas y parasitarias y efectos tardíos de las enfermedades infecciosas y parasitarias | L11: 0 | M11: (05) Otras enfermedades infecciosas y parasitarias y efectos tardíos de las enfermedades infecciosas y parasitarias | N11: =(F9/Poblacion!$Q$24)*1000 -> 0.0039648574 | P11: (05) Otras enfermedades infecciosas y parasitarias y efectos tardíos de las enfermedades infecciosas y parasitarias | Q11: 0 | R11: (05) Otras enfermedades infecciosas y parasitarias y efectos tardíos de las enfermedades infecciosas y parasitarias | S11: =(F9/$F$53)*100 -> 0.042589438 | V11: (05) Otras enfermedades infecciosas y parasitarias y efectos tardíos de las enfermedades infecciosas y parasitarias | W11: 0 | X11: (05) Otras enfermedades infecciosas y parasitarias y efectos tardíos de las enfermedades infecciosas y parasitarias | Y11: 0 | AA11: (05) Otras enfermedades infecciosas y parasitarias y efectos tardíos de las enfermedades infecciosas y parasitarias | AB11: 0 | AC11: (05) Otras enfermedades infecciosas y parasitarias y efectos tardíos de las enfermedades infecciosas y parasitarias | AD11: 0
A12: (09) Tumores malignos de los órganos digestivos | B12: 23 | C12: 20 | E12: (09) Tumores malignos de los órganos digestivos | F12: 46 | G12: 41 | K12: (06) Enfermedades víricas | L12: =(B10/Poblacion!$M$24)*1000 -> 0.0083787691 | M12: (06) Enfermedades víricas | N12: =(F10/Poblacion!$Q$24)*1000 -> 2.2401444 | P12: (06) Enfermedades víricas | Q12: =(B10/$B$53)*100 -> 0.43383948 | R12: (06) Enfermedades víricas | S12: =(F10/$F$53)*100 -> 24.063032 | V12: (06) Enfermedades víricas | W12: =(C10/Poblacion!$N$24)*1000 -> 0.012050713 | X12: (06) Enfermedades víricas | Y12: =(G10/Poblacion!$R$24)*1000 -> 1.0657898 | AA12: (06) Enfermedades víricas | AB12: =(C10/$C$53)*100 -> 0.80428954 | AC12: (06) Enfermedades víricas | AD12: =(G10/$G$53)*100 -> 17.911392
A13: (10) Tumor maligno de órganos respiratorios e intratorácicos | B13: 3 | C13: 6 | E13: (10) Tumor maligno de órganos respiratorios e intratorácicos | F13: 13 | G13: 6 | K13: (08) Tumores malignos del labio, de la cavidad bucal y de la faringe | L13: =(B11/Poblacion!$M$24)*1000 -> 0.0041893846 | M13: (08) Tumores malignos del labio, de la cavidad bucal y de la faringe | N13: =(F11/Poblacion!$Q$24)*1000 -> 0.01585943 | P13: (08) Tumores malignos del labio, de la cavidad bucal y de la faringe | Q13: =(B11/$B$53)*100 -> 0.21691974 | R13: (08) Tumores malignos del labio, de la cavidad bucal y de la faringe | S13: =(F11/$F$53)*100 -> 0.17035775 | V13: (08) Tumores malignos del labio, de la cavidad bucal y de la faringe | W13: =(C11/Poblacion!$N$24)*1000 -> 0.0040169044 | X13: (08) Tumores malignos del labio, de la cavidad bucal y de la faringe | Y13: =(G11/Poblacion!$R$24)*1000 -> 0.0075320833 | AA13: (08) Tumores malignos del labio, de la cavidad bucal y de la faringe | AB13: =(C11/$C$53)*100 -> 0.26809651 | AC13: (08) Tumores malignos del labio, de la cavidad bucal y de la faringe | AD13: =(G11/$G$53)*100 -> 0.12658228
A14: (11) Tumores malignos de los huesos, de los cartílagos articulares, del tejido conjuntivo, de la piel y de la mama | B14: 5 | C14: 13 | E14: (11) Tumores malignos de los huesos, de los cartílagos articulares, del tejido conjuntivo, de la piel y de la mama | F14: 9 | G14: 35 | K14: (09) Tumores malignos de los órganos digestivos | L14: =(B12/Poblacion!$M$24)*1000 -> 0.096355845 | M14: (09) Tumores malignos de los órganos digestivos | N14: =(F12/Poblacion!$Q$24)*1000 -> 0.18238344 | P14: (09) Tumores malignos de los órganos digestivos | Q14: =(B12/$B$53)*100 -> 4.989154 | R14: (09) Tumores malignos de los órganos digestivos | S14: =(F12/$F$53)*100 -> 1.9591141 | V14: (09) Tumores malignos de los órganos digestivos | W14: =(C12/Poblacion!$N$24)*1000 -> 0.080338088 | X14: (09) Tumores malignos de los órganos digestivos | Y14: =(G12/Poblacion!$R$24)*1000 -> 0.15440771 | AA14: (09) Tumores malignos de los órganos digestivos | AB14: =(C12/$C$53)*100 -> 5.3619303 | AC14: (09) Tumores malignos de los órganos digestivos | AD14: =(G12/$G$53)*100 -> 2.5949367
A15: (12) Tumores malignos de los órganos genitourinarios | B15: 11 | C15: 13 | E15: (12) Tumores malignos de los órganos genitourinarios | F15: 21 | G15: 36 | K15: (10) Tumor maligno de órganos respiratorios e intratorácicos | L15: =(B13/Poblacion!$M$24)*1000 -> 0.012568154 | M15: (10) Tumor maligno de órganos respiratorios e intratorácicos | N15: =(F13/Poblacion!$Q$24)*1000 -> 0.051543147 | P15: (10) Tumor maligno de órganos respiratorios e intratorácicos | Q15: =(B13/$B$53)*100 -> 0.65075922 | R15: (10) Tumor maligno de órganos respiratorios e intratorácicos | S15: =(F13/$F$53)*100 -> 0.55366269 | V15: (10) Tumor maligno de órganos respiratorios e intratorácicos | W15: =(C13/Poblacion!$N$24)*1000 -> 0.024101427 | X15: (10) Tumor maligno de órganos respiratorios e intratorácicos | Y15: =(G13/Poblacion!$R$24)*1000 -> 0.02259625 | AA15: (10) Tumor maligno de órganos respiratorios e intratorácicos | AB15: =(C13/$C$53)*100 -> 1.6085791 | AC15: (10) Tumor maligno de órganos respiratorios e intratorácicos | AD15: =(G13/$G$53)*100 -> 0.37974684
A16: (13) Tumores malignos de otros sitios y de los no especificados | B16: 8 | C16: 7 | E16: (13) Tumores malignos de otros sitios y de los no especificados | F16: 9 | G16: 6 | K16: (11) Tumores malignos de los huesos, de los cartílagos articulares, del tejido conjuntivo, de la piel y de la mama | L16: =(B14/Poblacion!$M$24)*1000 -> 0.020946923 | M16: (11) Tumores malignos de los huesos, de los cartílagos articulares, del tejido conjuntivo, de la piel y de la mama | N16: =(F14/Poblacion!$Q$24)*1000 -> 0.035683717 | P16: (11) Tumores malignos de los huesos, de los cartílagos articulares, del tejido conjuntivo, de la piel y de la mama | Q16: =(B14/$B$53)*100 -> 1.0845987 | R16: (11) Tumores malignos de los huesos, de los cartílagos articulares, del tejido conjuntivo, de la piel y de la mama | S16: =(F14/$F$53)*100 -> 0.38330494 | V16: (11) Tumores malignos de los huesos, de los cartílagos articulares, del tejido conjuntivo, de la piel y de la mama | W16: =(C14/Poblacion!$N$24)*1000 -> 0.052219757 | X16: (11) Tumores malignos de los huesos, de los cartílagos articulares, del tejido conjuntivo, de la piel y de la mama | Y16: =(G14/Poblacion!$R$24)*1000 -> 0.13181146 | AA16: (11) Tumores malignos de los huesos, de los cartílagos articulares, del tejido conjuntivo, de la piel y de la mama | AB16: =(C14/$C$53)*100 -> 3.4852547 | AC16: (11) Tumores malignos de los huesos, de los cartílagos articulares, del tejido conjuntivo, de la piel y de la mama | AD16: =(G14/$G$53)*100 -> 2.2151899
A17: (14) Tumores malignos del tejido linfático, de los órganos hematopoyéticos y tejidos afines | B17: 1 | C17: 3 | E17: (14) Tumores malignos del tejido linfático, de los órganos hematopoyéticos y tejidos afines | F17: 16 | G17: 7 | K17: (12) Tumores malignos de los órganos genitourinarios | L17: =(B15/Poblacion!$M$24)*1000 -> 0.04608323 | M17: (12) Tumores malignos de los órganos genitourinarios | N17: =(F15/Poblacion!$Q$24)*1000 -> 0.083262006 | P17: (12) Tumores malignos de los órganos genitourinarios | Q17: =(B15/$B$53)*100 -> 2.3861171 | R17: (12) Tumores malignos de los órganos genitourinarios | S17: =(F15/$F$53)*100 -> 0.89437819 | V17: (12) Tumores malignos de los órganos genitourinarios | W17: =(C15/Poblacion!$N$24)*1000 -> 0.052219757 | X17: (12) Tumores malignos de los órganos genitourinarios | Y17: =(G15/Poblacion!$R$24)*1000 -> 0.1355775 | AA17: (12) Tumores malignos de los órganos genitourinarios | AB17: =(C15/$C$53)*100 -> 3.4852547 | AC17: (12) Tumores malignos de los órganos genitourinarios | AD17: =(G15/$G$53)*100 -> 2.278481
A18: (15) Tumores malignos (primarios) de sitios múltiples independientes | B18: 5 | C18: 3 | E18: (15) Tumores malignos (primarios) de sitios múltiples independientes | K18: (13) Tumores malignos de otros sitios y de los no especificados | L18: =(B16/Poblacion!$M$24)*1000 -> 0.033515076 | M18: (13) Tumores malignos de otros sitios y de los no especificados | N18: =(F16/Poblacion!$Q$24)*1000 -> 0.035683717 | P18: (13) Tumores malignos de otros sitios y de los no especificados | Q18: =(B16/$B$53)*100 -> 1.7353579 | R18: (13) Tumores malignos de otros sitios y de los no especificados | S18: =(F16/$F$53)*100 -> 0.38330494 | V18: (13) Tumores malignos de otros sitios y de los no especificados | W18: =(C16/Poblacion!$N$24)*1000 -> 0.028118331 | X18: (13) Tumores malignos de otros sitios y de los no especificados | Y18: =(G16/Poblacion!$R$24)*1000 -> 0.02259625 | AA18: (13) Tumores malignos de otros sitios y de los no especificados | AB18: =(C16/$C$53)*100 -> 1.8766756 | AC18: (13) Tumores malignos de otros sitios y de los no especificados | AD18: =(G16/$G$53)*100 -> 0.37974684
A19: (17) Tumores Benignos | E19: (17) Tumores Benignos | F19: 2 | G19: 3 | K19: (14) Tumores malignos del tejido linfático, de los órganos hematopoyéticos y tejidos afines | L19: =(B17/Poblacion!$M$24)*1000 -> 0.0041893846 | M19: (14) Tumores malignos del tejido linfático, de los órganos hematopoyéticos y tejidos afines | N19: =(F17/Poblacion!$Q$24)*1000 -> 0.063437719 | P19: (14) Tumores malignos del tejido linfático, de los órganos hematopoyéticos y tejidos afines | Q19: =(B17/$B$53)*100 -> 0.21691974 | R19: (14) Tumores malignos del tejido linfático, de los órganos hematopoyéticos y tejidos afines | S19: =(F17/$F$53)*100 -> 0.68143101 | V19: (14) Tumores malignos del tejido linfático, de los órganos hematopoyéticos y tejidos afines | W19: =(C17/Poblacion!$N$24)*1000 -> 0.012050713 | X19: (14) Tumores malignos del tejido linfático, de los órganos hematopoyéticos y tejidos afines | Y19: =(G17/Poblacion!$R$24)*1000 -> 0.026362291 | AA19: (14) Tumores malignos del tejido linfático, de los órganos hematopoyéticos y tejidos afines | AB19: =(C17/$C$53)*100 -> 0.80428954 | AC19: (14) Tumores malignos del tejido linfático, de los órganos hematopoyéticos y tejidos afines | AD19: =(G17/$G$53)*100 -> 0.44303797
A20: (18) Tumores de comportamiento incierto o desconocido | B20: 2 | E20: (18) Tumores de comportamiento incierto o desconocido | F20: 8 | G20: 6 | K20: (15) Tumores malignos (primarios) de sitios múltiples independientes | L20: =(B18/Poblacion!$M$24)*1000 -> 0.020946923 | M20: (15) Tumores malignos (primarios) de sitios múltiples independientes | N20: 0 | P20: (15) Tumores malignos (primarios) de sitios múltiples independientes | Q20: =(B18/$B$53)*100 -> 1.0845987 | R20: (15) Tumores malignos (primarios) de sitios múltiples independientes | S20: 0 | V20: (15) Tumores malignos (primarios) de sitios múltiples independientes | W20: =(C18/Poblacion!$N$24)*1000 -> 0.012050713 | X20: (15) Tumores malignos (primarios) de sitios múltiples independientes | Y20: 0 | AA20: (15) Tumores malignos (primarios) de sitios múltiples independientes | AB20: =(C18/$C$53)*100 -> 0.80428954 | AC20: (15) Tumores malignos (primarios) de sitios múltiples independientes | AD20: 0
A21: (19) Enfermedades de la sangre y de los órganos hematopoyéticos, y ciertos trastornos que afectan el mecanismo de la inmunidad | C21: 2 | E21: (19) Enfermedades de la sangre y de los órganos hematopoyéticos, y ciertos trastornos que afectan el mecanismo de la inmunidad | F21: 4 | G21: 8 | K21: (17) Tumores Benignos | L21: 0 | M21: (17) Tumores Benignos | N21: =(F19/Poblacion!$Q$24)*1000 -> 0.0079297149 | P21: (17) Tumores Benignos | Q21: 0 | R21: (17) Tumores Benignos | S21: =(F19/$F$53)*100 -> 0.085178876 | V21: (17) Tumores Benignos | W21: 0 | X21: (17) Tumores Benignos | Y21: =(G19/Poblacion!$R$24)*1000 -> 0.011298125 | AA21: (17) Tumores Benignos | AB21: 0 | AC21: (17) Tumores Benignos | AD21: =(G19/$G$53)*100 -> 0.18987342
A22: (20) Enfermedades endocrinas y metabólicas | B22: 77 | C22: 67 | E22: (20) Enfermedades endocrinas y metabólicas | F22: 399 | G22: 324 | K22: (18) Tumores de comportamiento incierto o desconocido | L22: =(B20/Poblacion!$M$24)*1000 -> 0.0083787691 | M22: (18) Tumores de comportamiento incierto o desconocido | N22: =(F20/Poblacion!$Q$24)*1000 -> 0.031718859 | P22: (18) Tumores de comportamiento incierto o desconocido | Q22: =(B20/$B$53)*100 -> 0.43383948 | R22: (18) Tumores de comportamiento incierto o desconocido | S22: =(F20/$F$53)*100 -> 0.3407155 | V22: (18) Tumores de comportamiento incierto o desconocido | W22: 0 | X22: (18) Tumores de comportamiento incierto o desconocido | Y22: =(G20/Poblacion!$R$24)*1000 -> 0.02259625 | AA22: (18) Tumores de comportamiento incierto o desconocido | AB22: 0 | AC22: (18) Tumores de comportamiento incierto o desconocido | AD22: =(G20/$G$53)*100 -> 0.37974684
A23: (21) Desnutrición y otras deficiencias nutricionales | B23: 8 | C23: 6 | E23: (21) Desnutrición y otras deficiencias nutricionales | F23: 3 | G23: 5 | K23: (19) Enfermedades de la sangre y de los órganos hematopoyéticos, y ciertos trastornos que afectan el mecanismo de la inmunidad | L23: 0 | M23: (19) Enfermedades de la sangre y de los órganos hematopoyéticos, y ciertos trastornos que afectan el mecanismo de la inmunidad | N23: =(F21/Poblacion!$Q$24)*1000 -> 0.01585943 | P23: (19) Enfermedades de la sangre y de los órganos hematopoyéticos, y ciertos trastornos que afectan el mecanismo de la inmunidad | Q23: 0 | R23: (19) Enfermedades de la sangre y de los órganos hematopoyéticos, y ciertos trastornos que afectan el mecanismo de la inmunidad | S23: =(F21/$F$53)*100 -> 0.17035775 | V23: (19) Enfermedades de la sangre y de los órganos hematopoyéticos, y ciertos trastornos que afectan el mecanismo de la inmunidad | W23: =(C21/Poblacion!$N$24)*1000 -> 0.0080338088 | X23: (19) Enfermedades de la sangre y de los órganos hematopoyéticos, y ciertos trastornos que afectan el mecanismo de la inmunidad | Y23: =(G21/Poblacion!$R$24)*1000 -> 0.030128333 | AA23: (19) Enfermedades de la sangre y de los órganos hematopoyéticos, y ciertos trastornos que afectan el mecanismo de la inmunidad | AB23: =(C21/$C$53)*100 -> 0.53619303 | AC23: (19) Enfermedades de la sangre y de los órganos hematopoyéticos, y ciertos trastornos que afectan el mecanismo de la inmunidad | AD23: =(G21/$G$53)*100 -> 0.50632911
A24: (22) Trastornos mentales y del comportamiento | B24: 2 | C24: 3 | E24: (22) Trastornos mentales y del comportamiento | F24: 12 | G24: 5 | K24: (20) Enfermedades endocrinas y metabólicas | L24: =(B22/Poblacion!$M$24)*1000 -> 0.32258261 | M24: (20) Enfermedades endocrinas y metabólicas | N24: =(F22/Poblacion!$Q$24)*1000 -> 1.5819781 | P24: (20) Enfermedades endocrinas y metabólicas | Q24: =(B22/$B$53)*100 -> 16.70282 | R24: (20) Enfermedades endocrinas y metabólicas | S24: =(F22/$F$53)*100 -> 16.993186 | V24: (20) Enfermedades endocrinas y metabólicas | W24: =(C22/Poblacion!$N$24)*1000 -> 0.2691326 | X24: (20) Enfermedades endocrinas y metabólicas | Y24: =(G22/Poblacion!$R$24)*1000 -> 1.2201975 | AA24: (20) Enfermedades endocrinas y metabólicas | AB24: =(C22/$C$53)*100 -> 17.962466 | AC24: (20) Enfermedades endocrinas y metabólicas | AD24: =(G22/$G$53)*100 -> 20.506329
A25: (23) Enfermedades del sistema nervioso | B25: 11 | C25: 8 | E25: (23) Enfermedades del sistema nervioso | F25: 15 | G25: 15 | K25: (21) Desnutrición y otras deficiencias nutricionales | L25: =(B23/Poblacion!$M$24)*1000 -> 0.033515076 | M25: (21) Desnutrición y otras deficiencias nutricionales | N25: =(F23/Poblacion!$Q$24)*1000 -> 0.011894572 | P25: (21) Desnutrición y otras deficiencias nutricionales | Q25: =(B23/$B$53)*100 -> 1.7353579 | R25: (21) Desnutrición y otras deficiencias nutricionales | S25: =(F23/$F$53)*100 -> 0.12776831 | V25: (21) Desnutrición y otras deficiencias nutricionales | W25: =(C23/Poblacion!$N$24)*1000 -> 0.024101427 | X25: (21) Desnutrición y otras deficiencias nutricionales | Y25: =(G23/Poblacion!$R$24)*1000 -> 0.018830208 | AA25: (21) Desnutrición y otras deficiencias nutricionales | AB25: =(C23/$C$53)*100 -> 1.6085791 | AC25: (21) Desnutrición y otras deficiencias nutricionales | AD25: =(G23/$G$53)*100 -> 0.3164557
A26: (26) Fiebre reumática aguda y enfermedades cardíacas reumáticas crónicas | C26: 2 | E26: (26) Fiebre reumática aguda y enfermedades cardíacas reumáticas crónicas | G26: 3 | K26: (22) Trastornos mentales y del comportamiento | L26: =(B24/Poblacion!$M$24)*1000 -> 0.0083787691 | M26: (22) Trastornos mentales y del comportamiento | N26: =(F24/Poblacion!$Q$24)*1000 -> 0.047578289 | P26: (22) Trastornos mentales y del comportamiento | Q26: =(B24/$B$53)*100 -> 0.43383948 | R26: (22) Trastornos mentales y del comportamiento | S26: =(F24/$F$53)*100 -> 0.51107325 | V26: (22) Trastornos mentales y del comportamiento | W26: =(C24/Poblacion!$N$24)*1000 -> 0.012050713 | X26: (22) Trastornos mentales y del comportamiento | Y26: =(G24/Poblacion!$R$24)*1000 -> 0.018830208 | AA26: (22) Trastornos mentales y del comportamiento | AB26: =(C24/$C$53)*100 -> 0.80428954 | AC26: (22) Trastornos mentales y del comportamiento | AD26: =(G24/$G$53)*100 -> 0.3164557
A27: (27) Enfermedades hipertensivas | B27: 10 | C27: 15 | E27: (27) Enfermedades hipertensivas | F27: 61 | G27: 47 | K27: (23) Enfermedades del sistema nervioso | L27: =(B25/Poblacion!$M$24)*1000 -> 0.04608323 | M27: (23) Enfermedades del sistema nervioso | N27: =(F25/Poblacion!$Q$24)*1000 -> 0.059472861 | P27: (23) Enfermedades del sistema nervioso | Q27: =(B25/$B$53)*100 -> 2.3861171 | R27: (23) Enfermedades del sistema nervioso | S27: =(F25/$F$53)*100 -> 0.63884157 | V27: (23) Enfermedades del sistema nervioso | W27: =(C25/Poblacion!$N$24)*1000 -> 0.032135235 | X27: (23) Enfermedades del sistema nervioso | Y27: =(G25/Poblacion!$R$24)*1000 -> 0.056490625 | AA27: (23) Enfermedades del sistema nervioso | AB27: =(C25/$C$53)*100 -> 2.1447721 | AC27: (23) Enfermedades del sistema nervioso | AD27: =(G25/$G$53)*100 -> 0.94936709
A28: (28) Enfermedades isquémicas del corazón | B28: 70 | C28: 55 | E28: (28) Enfermedades isquémicas del corazón | F28: 387 | G28: 286 | K28: (26) Fiebre reumática aguda y enfermedades cardíacas reumáticas crónicas | L28: 0 | M28: (26) Fiebre reumática aguda y enfermedades cardíacas reumáticas crónicas | N28: 0 | P28: (26) Fiebre reumática aguda y enfermedades cardíacas reumáticas crónicas | Q28: 0 | R28: (26) Fiebre reumática aguda y enfermedades cardíacas reumáticas crónicas | S28: 0 | V28: (26) Fiebre reumática aguda y enfermedades cardíacas reumáticas crónicas | W28: =(C26/Poblacion!$N$24)*1000 -> 0.0080338088 | X28: (26) Fiebre reumática aguda y enfermedades cardíacas reumáticas crónicas | Y28: =(G26/Poblacion!$R$24)*1000 -> 0.011298125 | AA28: (26) Fiebre reumática aguda y enfermedades cardíacas reumáticas crónicas | AB28: =(C26/$C$53)*100 -> 0.53619303 | AC28: (26) Fiebre reumática aguda y enfermedades cardíacas reumáticas crónicas | AD28: =(G26/$G$53)*100 -> 0.18987342
A29: (29) Enfermedades de la circulación pulmonar y otras enfermedades del corazón | B29: 6 | C29: 6 | E29: (29) Enfermedades de la circulación pulmonar y otras enfermedades del corazón | F29: 8 | G29: 17 | K29: (27) Enfermedades hipertensivas | L29: =(B27/Poblacion!$M$24)*1000 -> 0.041893846 | M29: (27) Enfermedades hipertensivas | N29: =(F27/Poblacion!$Q$24)*1000 -> 0.2418563 | P29: (27) Enfermedades hipertensivas | Q29: =(B27/$B$53)*100 -> 2.1691974 | R29: (27) Enfermedades hipertensivas | S29: =(F27/$F$53)*100 -> 2.5979557 | V29: (27) Enfermedades hipertensivas | W29: =(C27/Poblacion!$N$24)*1000 -> 0.060253566 | X29: (27) Enfermedades hipertensivas | Y29: =(G27/Poblacion!$R$24)*1000 -> 0.17700396 | AA29: (27) Enfermedades hipertensivas | AB29: =(C27/$C$53)*100 -> 4.0214477 | AC29: (27) Enfermedades hipertensivas | AD29: =(G27/$G$53)*100 -> 2.9746835
A30: (30) Enfermedades cerebrovasculares | B30: 7 | C30: 20 | E30: (30) Enfermedades cerebrovasculares | F30: 36 | G30: 53 | K30: (28) Enfermedades isquémicas del corazón | L30: =(B28/Poblacion!$M$24)*1000 -> 0.29325692 | M30: (28) Enfermedades isquémicas del corazón | N30: =(F28/Poblacion!$Q$24)*1000 -> 1.5343998 | P30: (28) Enfermedades isquémicas del corazón | Q30: =(B28/$B$53)*100 -> 15.184382 | R30: (28) Enfermedades isquémicas del corazón | S30: =(F28/$F$53)*100 -> 16.482112 | V30: (28) Enfermedades isquémicas del corazón | W30: =(C28/Poblacion!$N$24)*1000 -> 0.22092974 | X30: (28) Enfermedades isquémicas del corazón | Y30: =(G28/Poblacion!$R$24)*1000 -> 1.0770879 | AA30: (28) Enfermedades isquémicas del corazón | AB30: =(C28/$C$53)*100 -> 14.745308 | AC30: (28) Enfermedades isquémicas del corazón | AD30: =(G28/$G$53)*100 -> 18.101266
A31: (31) Otras enfermedades del aparato circulatorio | B31: 3 | C31: 2 | E31: (31) Otras enfermedades del aparato circulatorio | F31: 9 | G31: 9 | K31: (29) Enfermedades de la circulación pulmonar y otras enfermedades del corazón | L31: =(B29/Poblacion!$M$24)*1000 -> 0.025136307 | M31: (29) Enfermedades de la circulación pulmonar y otras enfermedades del corazón | N31: =(F29/Poblacion!$Q$24)*1000 -> 0.031718859 | P31: (29) Enfermedades de la circulación pulmonar y otras enfermedades del corazón | Q31: =(B29/$B$53)*100 -> 1.3015184 | R31: (29) Enfermedades de la circulación pulmonar y otras enfermedades del corazón | S31: =(F29/$F$53)*100 -> 0.3407155 | V31: (29) Enfermedades de la circulación pulmonar y otras enfermedades del corazón | W31: =(C29/Poblacion!$N$24)*1000 -> 0.024101427 | X31: (29) Enfermedades de la circulación pulmonar y otras enfermedades del corazón | Y31: =(G29/Poblacion!$R$24)*1000 -> 0.064022708 | AA31: (29) Enfermedades de la circulación pulmonar y otras enfermedades del corazón | AB31: =(C29/$C$53)*100 -> 1.6085791 | AC31: (29) Enfermedades de la circulación pulmonar y otras enfermedades del corazón | AD31: =(G29/$G$53)*100 -> 1.0759494
A32: (32) Infecciones y otras enfermedades de las vías respiratorias superiores | C32: 2 | E32: (32) Infecciones y otras enfermedades de las vías respiratorias superiores | K32: (30) Enfermedades cerebrovasculares | L32: =(B30/Poblacion!$M$24)*1000 -> 0.029325692 | M32: (30) Enfermedades cerebrovasculares | N32: =(F30/Poblacion!$Q$24)*1000 -> 0.14273487 | P32: (30) Enfermedades cerebrovasculares | Q32: =(B30/$B$53)*100 -> 1.5184382 | R32: (30) Enfermedades cerebrovasculares | S32: =(F30/$F$53)*100 -> 1.5332198 | V32: (30) Enfermedades cerebrovasculares | W32: =(C30/Poblacion!$N$24)*1000 -> 0.080338088 | X32: (30) Enfermedades cerebrovasculares | Y32: =(G30/Poblacion!$R$24)*1000 -> 0.19960021 | AA32: (30) Enfermedades cerebrovasculares | AB32: =(C30/$C$53)*100 -> 5.3619303 | AC32: (30) Enfermedades cerebrovasculares | AD32: =(G30/$G$53)*100 -> 3.3544304
A33: (33) Otras enfermedades del aparato respiratorio | B33: 28 | C33: 41 | E33: (33) Otras enfermedades del aparato respiratorio | F33: 190 | G33: 136 | K33: (31) Otras enfermedades del aparato circulatorio | L33: =(B31/Poblacion!$M$24)*1000 -> 0.012568154 | M33: (31) Otras enfermedades del aparato circulatorio | N33: =(F31/Poblacion!$Q$24)*1000 -> 0.035683717 | P33: (31) Otras enfermedades del aparato circulatorio | Q33: =(B31/$B$53)*100 -> 0.65075922 | R33: (31) Otras enfermedades del aparato circulatorio | S33: =(F31/$F$53)*100 -> 0.38330494 | V33: (31) Otras enfermedades del aparato circulatorio | W33: =(C31/Poblacion!$N$24)*1000 -> 0.0080338088 | X33: (31) Otras enfermedades del aparato circulatorio | Y33: =(G31/Poblacion!$R$24)*1000 -> 0.033894375 | AA33: (31) Otras enfermedades del aparato circulatorio | AB33: =(C31/$C$53)*100 -> 0.53619303 | AC33: (31) Otras enfermedades del aparato circulatorio | AD33: =(G31/$G$53)*100 -> 0.56962025
A34: (35) Enfermedades de otras partes del aparato digestivo | B34: 49 | C34: 25 | E34: (35) Enfermedades de otras partes del aparato digestivo | F34: 191 | G34: 99 | K34: (32) Infecciones y otras enfermedades de las vías respiratorias superiores | L34: 0 | M34: (32) Infecciones y otras enfermedades de las vías respiratorias superiores | N34: 0 | P34: (32) Infecciones y otras enfermedades de las vías respiratorias superiores | Q34: 0 | R34: (32) Infecciones y otras enfermedades de las vías respiratorias superiores | S34: 0 | V34: (32) Infecciones y otras enfermedades de las vías respiratorias superiores | W34: =(C32/Poblacion!$N$24)*1000 -> 0.0080338088 | X34: (32) Infecciones y otras enfermedades de las vías respiratorias superiores | Y34: 0 | AA34: (32) Infecciones y otras enfermedades de las vías respiratorias superiores | AB34: =(C32/$C$53)*100 -> 0.53619303 | AC34: (32) Infecciones y otras enfermedades de las vías respiratorias superiores | AD34: 0
A35: (36) Enfermedades de la piel y del tejido subcutáneo | E35: (36) Enfermedades de la piel y del tejido subcutáneo | F35: 6 | G35: 11 | K35: (33) Otras enfermedades del aparato respiratorio | L35: =(B33/Poblacion!$M$24)*1000 -> 0.11730277 | M35: (33) Otras enfermedades del aparato respiratorio | N35: =(F33/Poblacion!$Q$24)*1000 -> 0.75332291 | P35: (33) Otras enfermedades del aparato respiratorio | Q35: =(B33/$B$53)*100 -> 6.0737527 | R35: (33) Otras enfermedades del aparato respiratorio | S35: =(F33/$F$53)*100 -> 8.0919932 | V35: (33) Otras enfermedades del aparato respiratorio | W35: =(C33/Poblacion!$N$24)*1000 -> 0.16469308 | X35: (33) Otras enfermedades del aparato respiratorio | Y35: =(G33/Poblacion!$R$24)*1000 -> 0.51218166 | AA35: (33) Otras enfermedades del aparato respiratorio | AB35: =(C33/$C$53)*100 -> 10.991957 | AC35: (33) Otras enfermedades del aparato respiratorio | AD35: =(G33/$G$53)*100 -> 8.6075949
A36: (37) Enfermedades del sistema osteomuscular y del tejido conjuntivo | B36: 1 | C36: 6 | E36: (37) Enfermedades del sistema osteomuscular y del tejido conjuntivo | F36: 4 | G36: 18 | K36: (35) Enfermedades de otras partes del aparato digestivo | L36: =(B34/Poblacion!$M$24)*1000 -> 0.20527984 | M36: (35) Enfermedades de otras partes del aparato digestivo | N36: =(F34/Poblacion!$Q$24)*1000 -> 0.75728777 | P36: (35) Enfermedades de otras partes del aparato digestivo | Q36: =(B34/$B$53)*100 -> 10.629067 | R36: (35) Enfermedades de otras partes del aparato digestivo | S36: =(F34/$F$53)*100 -> 8.1345826 | V36: (35) Enfermedades de otras partes del aparato digestivo | W36: =(C34/Poblacion!$N$24)*1000 -> 0.10042261 | X36: (35) Enfermedades de otras partes del aparato digestivo | Y36: =(G34/Poblacion!$R$24)*1000 -> 0.37283812 | AA36: (35) Enfermedades de otras partes del aparato digestivo | AB36: =(C34/$C$53)*100 -> 6.7024129 | AC36: (35) Enfermedades de otras partes del aparato digestivo | AD36: =(G34/$G$53)*100 -> 6.2658228
A37: (38) Enfermedades del aparato urinario | B37: 10 | C37: 12 | E37: (38) Enfermedades del aparato urinario | F37: 67 | G37: 34 | K37: (36) Enfermedades de la piel y del tejido subcutáneo | L37: 0 | M37: (36) Enfermedades de la piel y del tejido subcutáneo | N37: =(F35/Poblacion!$Q$24)*1000 -> 0.023789145 | P37: (36) Enfermedades de la piel y del tejido subcutáneo | Q37: 0 | R37: (36) Enfermedades de la piel y del tejido subcutáneo | S37: =(F35/$F$53)*100 -> 0.25553663 | V37: (36) Enfermedades de la piel y del tejido subcutáneo | W37: 0 | X37: (36) Enfermedades de la piel y del tejido subcutáneo | Y37: =(G35/Poblacion!$R$24)*1000 -> 0.041426458 | AA37: (36) Enfermedades de la piel y del tejido subcutáneo | AB37: 0 | AC37: (36) Enfermedades de la piel y del tejido subcutáneo | AD37: =(G35/$G$53)*100 -> 0.69620253
A38: (39) Enfermedades de los órganos genitales masculinos | B38: 4 | E38: (39) Enfermedades de los órganos genitales masculinos | F38: 3 | K38: (37) Enfermedades del sistema osteomuscular y del tejido conjuntivo | L38: =(B36/Poblacion!$M$24)*1000 -> 0.0041893846 | M38: (37) Enfermedades del sistema osteomuscular y del tejido conjuntivo | N38: =(F36/Poblacion!$Q$24)*1000 -> 0.01585943 | P38: (37) Enfermedades del sistema osteomuscular y del tejido conjuntivo | Q38: =(B36/$B$53)*100 -> 0.21691974 | R38: (37) Enfermedades del sistema osteomuscular y del tejido conjuntivo | S38: =(F36/$F$53)*100 -> 0.17035775 | V38: (37) Enfermedades del sistema osteomuscular y del tejido conjuntivo | W38: =(C36/Poblacion!$N$24)*1000 -> 0.024101427 | X38: (37) Enfermedades del sistema osteomuscular y del tejido conjuntivo | Y38: =(G36/Poblacion!$R$24)*1000 -> 0.067788749 | AA38: (37) Enfermedades del sistema osteomuscular y del tejido conjuntivo | AB38: =(C36/$C$53)*100 -> 1.6085791 | AC38: (37) Enfermedades del sistema osteomuscular y del tejido conjuntivo | AD38: =(G36/$G$53)*100 -> 1.1392405
A39: (41) Enfermedades de los órganos genitales femeninos | E39: (41) Enfermedades de los órganos genitales femeninos | G39: 3 | K39: (38) Enfermedades del aparato urinario | L39: =(B37/Poblacion!$M$24)*1000 -> 0.041893846 | M39: (38) Enfermedades del aparato urinario | N39: =(F37/Poblacion!$Q$24)*1000 -> 0.26564545 | P39: (38) Enfermedades del aparato urinario | Q39: =(B37/$B$53)*100 -> 2.1691974 | R39: (38) Enfermedades del aparato urinario | S39: =(F37/$F$53)*100 -> 2.8534923 | V39: (38) Enfermedades del aparato urinario | W39: =(C37/Poblacion!$N$24)*1000 -> 0.048202853 | X39: (38) Enfermedades del aparato urinario | Y39: =(G37/Poblacion!$R$24)*1000 -> 0.12804542 | AA39: (38) Enfermedades del aparato urinario | AB39: =(C37/$C$53)*100 -> 3.2171582 | AC39: (38) Enfermedades del aparato urinario | AD39: =(G37/$G$53)*100 -> 2.1518987
A40: (43) Causas obstétricas directas | C40: 1 | E40: (43) Causas obstétricas directas | G40: 2 | K40: (39) Enfermedades de los órganos genitales masculinos | L40: =(B38/Poblacion!$M$24)*1000 -> 0.016757538 | M40: (39) Enfermedades de los órganos genitales masculinos | N40: =(F38/Poblacion!$Q$24)*1000 -> 0.011894572 | P40: (39) Enfermedades de los órganos genitales masculinos | Q40: =(B38/$B$53)*100 -> 0.86767896 | R40: (39) Enfermedades de los órganos genitales masculinos | S40: =(F38/$F$53)*100 -> 0.12776831 | V40: (39) Enfermedades de los órganos genitales masculinos | W40: 0 | X40: (39) Enfermedades de los órganos genitales masculinos | Y40: 0 | AA40: (39) Enfermedades de los órganos genitales masculinos | AB40: 0 | AC40: (39) Enfermedades de los órganos genitales masculinos | AD40: 0
A41: (46) Ciertas afecciones originadas en el período perinatal | B41: 3 | C41: 6 | E41: (46) Ciertas afecciones originadas en el período perinatal | F41: 14 | G41: 6 | K41: (41) Enfermedades de los órganos genitales femeninos | L41: 0 | M41: (41) Enfermedades de los órganos genitales femeninos | N41: 0 | P41: (41) Enfermedades de los órganos genitales femeninos | Q41: 0 | R41: (41) Enfermedades de los órganos genitales femeninos | S41: 0 | V41: (41) Enfermedades de los órganos genitales femeninos | W41: 0 | X41: (41) Enfermedades de los órganos genitales femeninos | Y41: =(G39/Poblacion!$R$24)*1000 -> 0.011298125 | AA41: (41) Enfermedades de los órganos genitales femeninos | AB41: 0 | AC41: (41) Enfermedades de los órganos genitales femeninos | AD41: =(G39/$G$53)*100 -> 0.18987342
...

Sheet Tablas de Vida
B1: TABLAS DE VIDA
A3: HOMBRES 2010 | P3: MUJERES 2010 | AE3: Intervalo C50
E4: poblacion lab2 | G4: TMI /1000 | T4: población lab2 | V4: TMI /1000 | AE4: 2010 | AG4: 2020
A5: Edad | B5: n | C5: nax | D5: nDx | E5: nNx | F5: nMx | G5: nmx | H5: nqx | I5: npx | J5: lx | K5: ndx | L5: nLx | M5: Tx | N5: ex | P5: Edad | Q5: n | R5: nax | S5: nDx | T5: nNx | U5: nMx | V5: nmx | W5: nqx | X5: npx | Y5: lx | Z5: ndx | AA5: nLx | AB5: Tx | AC5: ex | AE5: Hombres | AF5: Mujeres | AG5: Hombres | AH5: Mujeres
A6: 0 | B6: 1 | C6: 0.5 | D6: =Defunciones!N8 -> 19.421286 | E6: =Poblacion!M5 -> 3907.1773 | F6: =D6/E6 -> 0.0049706693 | G6: =Defunciones!AG5/1000 -> 0.012881684 | H6: =(B6*G6)/(1+((B6-C6)*G6)) -> 0.012799246 | I6: =1-H6 -> 0.98720075 | J6: 100000 | K6: =J6*H6 -> 1279.9246 | L6: =B6*J7+C6*K6 -> 99360.038 | M6: =SUM(L6:L24) -> 8267746.5 | N6: =M6/J6 -> 82.677465 | P6: 0 | Q6: 1 | R6: 0.5 | S6: =Defunciones!O8 -> 13.070081 | T6: =Poblacion!N5 -> 3864.5627 | U6: =S6/T6 -> 0.0033820336 | V6: =Defunciones!AH5/1000 -> 0.0088152524 | W6: =(Q6*V6)/(1+(Q6-R6)*V6) -> 0.0087765685 | X6: =1-W6 -> 0.99122343 | Y6: 100000 | Z6: =Y6*W6 -> 877.65685 | AA6: =Q6*Y7+R6*Z6 -> 99561.172 | AB6: =SUM(AA6:$AA$24) -> 8648608.8 | AC6: =AB6/Y6 -> 86.486088 | AE6: =A22+((50000-J22)/(J22-J23)) -> 72.418689 | AF6: =P23+((50000-Y23)/(Y23-Y24)) -> 78.221392 | AG6: =A62+((50000-Y64)/(Y64-Y65)) -> 70.22118 | AH6: =P64+((50000-Y64)/(Y64-Y65)) -> 80.22118
A7: 1 | B7: 4 | C7: 2 | D7: =Defunciones!N9 -> 5.1108647 | E7: =Poblacion!M6 -> 18182.401 | F7: =D7/E7 -> 0.00028108856 | G7: =F7 -> 0.00028108856 | H7: =(B7*G7)/(1+((B7-C7)*G7)) -> 0.0011237225 | I7: =1-H7 -> 0.99887628 | J7: =J6*I6 -> 98720.075 | K7: =J7*H7 -> 110.93397 | L7: =B7*J8+C7*K7 -> 394658.43 | M7: =SUM(L7:$L$24) -> 8168386.5 | N7: =M7/J7 -> 82.742912 | P7: 1 | Q7: 4 | R7: 2 | S7: =Defunciones!O9 -> 1.0053908 | T7: =Poblacion!N6 -> 17457.319 | U7: =S7/T7 -> 5.7591366e-05 | V7: =U7 -> 5.7591366e-05 | W7: =(Q7*V7)/(1+(Q7-R7)*V7) -> 0.00023033893 | X7: =1-W7 -> 0.99976966 | Y7: =Y6*X6 -> 99122.343 | Z7: =Y7*W7 -> 22.831735 | AA7: =Q7*Y8+R7*Z7 -> 396443.71 | AB7: =SUM(AA7:$AA$24) -> 8549047.6 | AC7: =AB7/Y7 -> 86.247433
