Workbook

Sheet DATOS
A1: DATOS
B3: censo 2010 | F3: censo 2020 | J3: Población Corregida 2010 | N3: Población Corregida 2020
B5: Tabla Prorrateada | F5: Tabla Prorrateada | J5: Grupo Quintenal | N5: Grupo Quintenal
B6: Edad | C6: Hombres | D6: Mujeres | F6: Edad | G6: Hombres | H6: Mujeres | K6: HOMBRES | L6: MUJERES | O6: HOMBRES | P6: MUJERES
B7: 0 | C7: 3911.4134 | D7: 3868.93 | F7: 0 | G7: 3136.9322 | H7: 3074.0323 | J7: 0 -- 4 | K7: 22111.128 | L7: 21342.107 | N7: 0 -- 4 | O7: 18130.168 | P7: 17597.634
B8: 1 | C8: 4194.0682 | D8: 4051.8101 | F8: 1 | G8: 3533.1763 | H8: 3323.197 | J8: 5 -- 9 | K8: 23487.799 | L8: 22411.956 | N8: 5 -- 9 | O8: 19387.942 | P8: 18898.494
B9: 2 | C9: 4606.8662 | D9: 4479.5463 | F9: 2 | G9: 3711.286 | H9: 3615.3902 | J9: 10 -- 14 | K9: 22933.737 | L9: 22323.754 | N9: 10 -- 14 | O9: 20778.299 | P9: 19851.249
B10: 3 | C10: 4651.6029 | D10: 4585.2104 | F10: 3 | G10: 3825.3563 | H10: 3775.496 | J10: 15 -- 19 | K10: 23506.545 | L10: 23221.581 | N10: 15 -- 19 | O10: 21574.164 | P10: 20669.54
B11: 4 | C11: 4747.1768 | D11: 4356.6102 | F11: 4 | G11: 3923.4167 | H11: 3809.5185 | J11: 20 -- 24 | K11: 22931.449 | L11: 23029.176 | N11: 20 -- 24 | O11: 21618.691 | P11: 21212.086
B12: 5 | C12: 4600.7657 | D12: 4312.9222 | F12: 5 | G12: 4052.4962 | H12: 3988.637 | J12: 25 -- 29 | K12: 20139.916 | L12: 21173.514 | N12: 25 -- 29 | O12: 20883.926 | P12: 21280.694
B13: 6 | C13: 4689.2224 | D13: 4487.6743 | F13: 5 | G13: 3793.3366 | H13: 3669.4259 | J13: 30 -- 34 | K13: 18225.323 | L13: 20296.515 | N13: 30 -- 34 | O13: 19524.714 | P13: 20657.032
B14: 7 | C14: 4565.1797 | D14: 4479.5463 | F14: 5 | G14: 3758.315 | H14: 3695.4431 | J14: 35 -- 39 | K14: 17984.419 | L14: 20437.867 | N14: 35 -- 39 | O14: 17915.473 | P14: 19662.937
B15: 8 | C15: 4937.3079 | D15: 4611.6264 | F15: 5 | G15: 4160.5628 | H15: 3891.5728 | J15: 40 -- 44 | K15: 16905.971 | L15: 18998.067 | N15: 40 -- 44 | O15: 16818.172 | P15: 19052.471
B16: 9 | C16: 4695.3229 | D16: 4520.1863 | F16: 5 | G16: 3623.2318 | H16: 3653.4153 | J16: 45 -- 49 | K16: 14713.999 | L16: 16329.414 | N16: 45 -- 49 | O16: 16639.749 | P16: 19148.972
B17: 10 | C17: 4812.2484 | D17: 4581.1464 | F17: 5 | G17: 4326.6651 | H17: 4017.6561 | J17: 50 -- 54 | K17: 12167.627 | L17: 13324.656 | N17: 50 -- 54 | O17: 15761.271 | P17: 18130.111
B18: 11 | C18: 4336.4123 | D18: 4360.6742 | F18: 5 | G18: 3947.4315 | H18: 3749.4788 | J18: 55 -- 59 | K18: 9131.0584 | L18: 9613.9684 | N18: 55 -- 59 | O18: 13641.278 | P18: 15456.969
... B24: 17 | C24: 4920.0233 | D24: 4831.0825 | F24: 5 | G24: 4445.7384 | H24: 4261.8176 | J24: 85 y más | K24: 505.32167 | L24: 880.87245 | N24: 85 y más | O24: 908.55964 | P24: 1616.0684
B25: 18 | C25: 5204.7116 | D25: 5091.1786 | F25: 5 | G25: 4874.0022 | H25: 4455.9459 | K25: =SUM(K7:K24) -> 238669.55 | L25: =SUM(L7:L24) -> 248911.94 | O25: =SUM(O7:O24) -> 251568.64 | P25: =SUM(P7:P24) -> 264737.71
B26: 19 | C26: 4532.6439 | D26: 4633.9784 | F26: 5 | G26: 3968.4444 | H26: 3937.6032
B27: 20 | C27: 5126.4223 | D27: 5038.3466 | F27: 5 | G27: 4828.9745 | H27: 4710.1139
B28: 21 | C28: 4462.4886 | D28: 4408.4263 | F28: 5 | G28: 4019.4759 | H28: 3911.586
B29: 22 | C29: 4696.3397 | D29: 4818.8905 | F29: 5 | G29: 4371.6928 | H29: 4313.852
B30: 23 | C30: 4582.4643 | D30: 4455.1623 | F30: 5 | G30: 4159.5621 | H30: 4008.6502
B31: 24 | C31: 4314.044 | D31: 4455.1623 | F31: 5 | G31: 4164.5652 | H31: 4107.7157
B32: 25 | C32: 4437.07 | D32: 4570.9864 | F32: 5 | G32: 4495.7692 | H32: 4727.1252
B33: 26 | C33: 3971.4013 | D33: 4203.1942 | F33: 5 | G33: 4009.4697 | H33: 4195.7739
B34: 27 | C34: 3962.2506 | D34: 4207.2582 | F34: 5 | G34: 4072.5085 | H34: 4152.7455
B35: 28 | C35: 4089.3436 | D35: 4340.3542 | F35: 5 | G35: 4696.8931 | H35: 4481.9631
B36: 29 | C36: 3581.9884 | D36: 3765.2979 | F36: 5 | G36: 3760.3162 | H36: 3934.6012
B37: 30 | C37: 4296.7593 | D37: 4708.1464 | F37: 5 | G37: 5068.1218 | H37: 5497.6346
... B107: 100 | C107: 11.184182 | D107: 16.256008 | F107: 5 | G107: 5.0030817 | H107: 28.018524
C108: 49090 | D108: 50500 | G108: 64219 | H108: 65710

Sheet Gráficas
A1: PIRAMIDE POBLACIONAL
B3: Censo del 2010 | N3: Censo del 2020
B5: Grupo Quintenal | N5: Grupo Quintenal
B6: Quinquenios | C6: HOMBRES | D6: MUJERES | E6: Hombres | O6: HOMBRES | P6: MUJERES | Q6: HOMBRES
B7: Menor 1 | C7: =DATOS!C7 -> 3911.4134 | D7: =DATOS!D7 -> 3868.93 | E7: =C7*-1 -> -3911.4134 | N7: Menor 1 | O7: =DATOS!G7 -> 3136.9322 | P7: =DATOS!H7 -> 3074.0323 | Q7: =O7*-1 -> -3136.9322
B8: 1-- 4 | C8: =DATOS!K7-Gráficas!C7 -> 18199.714 | D8: =DATOS!L7-Gráficas!D7 -> 17473.177 | E8: =C8*-1 -> -18199.714 | N8: 1-- 4 | O8: =DATOS!O7-Gráficas!O7 -> 14993.235 | P8: =DATOS!P7-Gráficas!P7 -> 14523.602 | Q8: =O8*-1 -> -14993.235
B9: 5 -- 9 | C9: =DATOS!K8 -> 23487.799 | D9: =DATOS!L8 -> 22411.956 | E9: =C9*-1 -> -23487.799 | N9: 5 -- 9 | O9: =DATOS!O8 -> 19387.942 | P9: =DATOS!P8 -> 18898.494 | Q9: =O9*-1 -> -19387.942
B10: 10 -- 14 | C10: =DATOS!K9 -> 22933.737 | D10: =DATOS!L9 -> 22323.754 | E10: =C10*-1 -> -22933.737 | N10: 10 -- 14 | O10: =DATOS!O9 -> 20778.299 | P10: =DATOS!P9 -> 19851.249 | Q10: =O10*-1 -> -20778.299
B11: 15 -- 19 | C11: =DATOS!K10 -> 23506.545 | D11: =DATOS!L10 -> 23221.581 | E11: =C11*-1 -> -23506.545 | N11: 15 -- 19 | O11: =DATOS!O10 -> 21574.164 | P11: =DATOS!P10 -> 20669.54 | Q11: =O11*-1 -> -21574.164
B12: 20 -- 24 | C12: =DATOS!K11 -> 22931.449 | D12: =DATOS!L11 -> 23029.176 | E12: =C12*-1 -> -22931.449 | N12: 20 -- 24 | O12: =DATOS!O11 -> 21618.691 | P12: =DATOS!P11 -> 21212.086 | Q12: =O12*-1 -> -21618.691
B13: 25 -- 29 | C13: =DATOS!K12 -> 20139.916 | D13: =DATOS!L12 -> 21173.514 | E13: =C13*-1 -> -20139.916 | N13: 25 -- 29 | O13: =DATOS!O12 -> 20883.926 | P13: =DATOS!P12 -> 21280.694 | Q13: =O13*-1 -> -20883.926
B14: 30 -- 34 | C14: =DATOS!K13 -> 18225.323 | D14: =DATOS!L13 -> 20296.515 | E14: =C14*-1 -> -18225.323 | N14: 30 -- 34 | O14: =DATOS!O13 -> 19524.714 | P14: =DATOS!P13 -> 20657.032 | Q14: =O14*-1 -> -19524.714
B15: 35 -- 39 | C15: =DATOS!K14 -> 17984.419 | D15: =DATOS!L14 -> 20437.867 | E15: =C15*-1 -> -17984.419 | N15: 35 -- 39 | O15: =DATOS!O14 -> 17915.473 | P15: =DATOS!P14 -> 19662.937 | Q15: =O15*-1 -> -17915.473
B16: 40 -- 44 | C16: =DATOS!K15 -> 16905.971 | D16: =DATOS!L15 -> 18998.067 | E16: =C16*-1 -> -16905.971 | N16: 40 -- 44 | O16: =DATOS!O15 -> 16818.172 | P16: =DATOS!P15 -> 19052.471 | Q16: =O16*-1 -> -16818.172
B17: 45 -- 49 | C17: =DATOS!K16 -> 14713.999 | D17: =DATOS!L16 -> 16329.414 | E17: =C17*-1 -> -14713.999 | N17: 45 -- 49 | O17: =DATOS!O16 -> 16639.749 | P17: =DATOS!P16 -> 19148.972 | Q17: =O17*-1 -> -16639.749
B18: 50 -- 54 | C18: =DATOS!K17 -> 12167.627 | D18: =DATOS!L17 -> 13324.656 | E18: =C18*-1 -> -12167.627 | N18: 50 -- 54 | O18: =DATOS!O17 -> 15761.271 | P18: =DATOS!P17 -> 18130.111 | Q18: =O18*-1 -> -15761.271
B19: 55 -- 59 | C19: =DATOS!K18 -> 9131.0584 | D19: =DATOS!L18 -> 9613.9684 | E19: =C19*-1 -> -9131.0584 | N19: 55 -- 59 | O19: =DATOS!O18 -> 13641.278 | P19: =DATOS!P18 -> 15456.969 | Q19: =O19*-1 -> -13641.278
B20: 60 -- 64 | C20: =DATOS!K19 -> 6113.9347 | D20: =DATOS!L19 -> 6244.9742 | E20: =C20*-1 -> -6113.9347 | N20: 60 -- 64 | O20: =DATOS!O19 -> 11045.053 | P20: =DATOS!P19 -> 12470.369 | Q20: =O20*-1 -> -11045.053
... B25: 85 y más | C25: =DATOS!K24 -> 505.32167 | D25: =DATOS!L24 -> 880.87245 | E25: =C25*-1 -> -505.32167 | N25: 85 y más | O25: =DATOS!O24 -> 908.55964 | P25: =DATOS!P24 -> 1616.0684 | Q25: =O25*-1 -> -908.55964
C26: =SUM(C7:C25) -> 238669.55 | D26: =SUM(D7:D25) -> 248911.94 | O26: =SUM(O7:O25) -> 251568.64 | P26: =SUM(P7:P25) -> 264737.71

Sheet Geometrico
A1: GEOMETRICO
B3: Grupos | E3: Censo 2010 | H3: Censo 2020 | K3: Tasa Geométrica | N3: Proyección mitad de año 2010 | R3: Proyección 2015 | V3: Proyección mitad de año 2020 | Z3: Proyección 2025
B4: Edad inicial | C4: Edad final | E4: HOMBRES | F4: MUJERES | H4: HOMBRES | I4: MUJERES | K4: HOMBRES | L4: MUJERES | N4: HOMBRES | O4: MUJERES | P4: Total | R4: HOMBRES | S4: MUJERES | T4: Total | V4: HOMBRES | W4: MUJERES | X4: Total | Z4: HOMBRES | AA4: MUJERES | AB4: Total
B5: 0 | C5: 0 | E5: =Gráficas!C7 -> 3911.4134 | F5: =Gráficas!D7 -> 3868.93 | H5: =Gráficas!O7 -> 3136.9322 | I5: =Gráficas!P7 -> 3074.0323 | K5: =(H5/E5)^(1/$I$30)-1 -> -0.022347471 | L5: =(I5/F5)^(1/$I$30)-1 -> -0.023281751 | N5: =E5*POWER(1+K5,$I$31) -> 3907.1773 | O5: =F5*POWER(1+L5,$I$31) -> 3864.5627 | P5: =SUM(N5,O5) -> 7771.74 | R5: =E5*POWER(1+K5,$I$32) -> 3489.4652 | S5: =F5*POWER(1+L5,$I$32) -> 3434.9375 | T5: =SUM(R5,S5) -> 6924.4027 | V5: =H5*POWER(1+K5,$I$33) -> 3116.2172 | W5: =I5*POWER(1+L5,$I$33) -> 3052.8769 | X5: =SUM(V5,W5) -> 6169.0941 | Z5: =H5*POWER(1+K5,$I$34) -> 2783.0658 | AA5: =I5*POWER(1+L5,$I$34) -> 2713.4872 | AB5: =SUM(Z5,AA5) -> 5496.553
B6: 1 | C6: 4 | E6: =Gráficas!C8 -> 18199.714 | F6: =Gráficas!D8 -> 17473.177 | H6: =Gráficas!O8 -> 14993.235 | I6: =Gráficas!P8 -> 14523.602 | K6: =(H6/E6)^(1/$I$30)-1 -> -0.019655385 | L6: =(I6/F6)^(1/$I$30)-1 -> -0.0187598 | N6: =E6*POWER(1+K6,$I$31) -> 18182.401 | O6: =F6*POWER(1+L6,$I$31) -> 17457.319 | P6: =SUM(N6,O6) -> 35639.719 | R6: =E6*POWER(1+K6,$I$32) -> 16463.472 | S6: =F6*POWER(1+L6,$I$32) -> 15879.312 | T6: =SUM(R6,S6) -> 32342.784 | V6: =H6*POWER(1+K6,$I$33) -> 14906.237 | W6: =I6*POWER(1+L6,$I$33) -> 14443.195 | X6: =SUM(V6,W6) -> 29349.432 | Z6: =H6*POWER(1+K6,$I$34) -> 13497.031 | AA6: =I6*POWER(1+L6,$I$34) -> 13137.641 | AB6: =SUM(Z6,AA6) -> 26634.672
B7: 5 | C7: 9 | E7: =Gráficas!C9 -> 23487.799 | F7: =Gráficas!D9 -> 22411.956 | H7: =Gráficas!O9 -> 19387.942 | I7: =Gráficas!P9 -> 18898.494 | K7: =(H7/E7)^(1/$I$30)-1 -> -0.019456844 | L7: =(I7/F7)^(1/$I$30)-1 -> -0.017313499 | N7: =E7*POWER(1+K7,$I$31) -> 23465.682 | O7: =F7*POWER(1+L7,$I$31) -> 22393.196 | P7: =SUM(N7,O7) -> 45858.879 | R7: =E7*POWER(1+K7,$I$32) -> 21268.819 | S7: =F7*POWER(1+L7,$I$32) -> 20519.665 | T7: =SUM(R7,S7) -> 41788.483 | V7: =H7*POWER(1+K7,$I$33) -> 19276.589 | W7: =I7*POWER(1+L7,$I$33) -> 18801.983 | X7: =SUM(V7,W7) -> 38078.571 | Z7: =H7*POWER(1+K7,$I$34) -> 17471.909 | AA7: =I7*POWER(1+L7,$I$34) -> 17228.911 | AB7: =SUM(Z7,AA7) -> 34700.82
B8: 10 | C8: 14 | E8: =Gráficas!C10 -> 22933.737 | F8: =Gráficas!D10 -> 22323.754 | H8: =Gráficas!O10 -> 20778.299 | I8: =Gráficas!P10 -> 19851.249 | K8: =(H8/E8)^(1/$I$30)-1 -> -0.010058648 | L8: =(I8/F8)^(1/$I$30)-1 -> -0.011951384 | N8: =E8*POWER(1+K8,$I$31) -> 22922.623 | O8: =F8*POWER(1+L8,$I$31) -> 22310.889 | P8: =SUM(N8,O8) -> 45233.512 | R8: =E8*POWER(1+K8,$I$32) -> 21792.127 | S8: =F8*POWER(1+L8,$I$32) -> 21008.456 | T8: =SUM(R8,S8) -> 42800.583 | V8: =H8*POWER(1+K8,$I$33) -> 20716.811 | W8: =I8*POWER(1+L8,$I$33) -> 19781.403 | X8: =SUM(V8,W8) -> 40498.214 | Z8: =H8*POWER(1+K8,$I$34) -> 19695.1 | AA8: =I8*POWER(1+L8,$I$34) -> 18626.633 | AB8: =SUM(Z8,AA8) -> 38321.734
B9: 15 | C9: 19 | E9: =Gráficas!C11 -> 23506.545 | F9: =Gráficas!D11 -> 23221.581 | H9: =Gráficas!O11 -> 21574.164 | I9: =Gráficas!P11 -> 20669.54 | K9: =(H9/E9)^(1/$I$30)-1 -> -0.0087479798 | L9: =(I9/F9)^(1/$I$30)-1 -> -0.011853876 | N9: =E9*POWER(1+K9,$I$31) -> 23496.644 | O9: =F9*POWER(1+L9,$I$31) -> 23208.308 | P9: =SUM(N9,O9) -> 46704.953 | R9: =E9*POWER(1+K9,$I$32) -> 22486.187 | S9: =F9*POWER(1+L9,$I$32) -> 21864.279 | T9: =SUM(R9,S9) -> 44350.466 | V9: =H9*POWER(1+K9,$I$33) -> 21518.666 | W9: =I9*POWER(1+L9,$I$33) -> 20597.411 | X9: =SUM(V9,W9) -> 42116.077 | Z9: =H9*POWER(1+K9,$I$34) -> 20593.27 | AA9: =I9*POWER(1+L9,$I$34) -> 19404.583 | AB9: =SUM(Z9,AA9) -> 39997.852
B10: 20 | C10: 24 | E10: =Gráficas!C12 -> 22931.449 | F10: =Gráficas!D12 -> 23029.176 | H10: =Gráficas!O12 -> 21618.691 | I10: =Gráficas!P12 -> 21212.086 | K10: =(H10/E10)^(1/$I$30)-1 -> -0.0060200054 | L10: =(I10/F10)^(1/$I$30)-1 -> -0.0083832524 | N10: =E10*POWER(1+K10,$I$31) -> 22924.811 | O10: =F10*POWER(1+L10,$I$31) -> 23019.882 | P10: =SUM(N10,O10) -> 45944.694 | R10: =E10*POWER(1+K10,$I$32) -> 22242.664 | S10: =F10*POWER(1+L10,$I$32) -> 22070.509 | T10: =SUM(R10,S10) -> 44313.173 | V10: =H10*POWER(1+K10,$I$33) -> 21580.458 | W10: =I10*POWER(1+L10,$I$33) -> 21159.801 | X10: =SUM(V10,W10) -> 42740.259 | Z10: =H10*POWER(1+K10,$I$34) -> 20938.313 | AA10: =I10*POWER(1+L10,$I$34) -> 20287.14 | AB10: =SUM(Z10,AA10) -> 41225.453
B11: 25 | C11: 29 | E11: =Gráficas!C13 -> 20139.916 | F11: =Gráficas!D13 -> 21173.514 | H11: =Gráficas!O13 -> 20883.926 | I11: =Gráficas!P13 -> 21280.694 | K11: =(H11/E11)^(1/$I$30)-1 -> 0.0037225768 | L11: =(I11/F11)^(1/$I$30)-1 -> 0.00051731008 | N11: =E11*POWER(1+K11,$I$31) -> 20143.504 | O11: =F11*POWER(1+L11,$I$31) -> 21174.039 | P11: =SUM(N11,O11) -> 41317.543 | R11: =E11*POWER(1+K11,$I$32) -> 20521.443 | S11: =F11*POWER(1+L11,$I$32) -> 21228.894 | T11: =SUM(R11,S11) -> 41750.337 | V11: =H11*POWER(1+K11,$I$33) -> 20906.686 | W11: =I11*POWER(1+L11,$I$33) -> 21283.921 | X11: =SUM(V11,W11) -> 42190.607 | Z11: =H11*POWER(1+K11,$I$34) -> 21298.945 | AA11: =I11*POWER(1+L11,$I$34) -> 21339.06 | AB11: =SUM(Z11,AA11) -> 42638.005
B12: 30 | C12: 34 | E12: =Gráficas!C14 -> 18225.323 | F12: =Gráficas!D14 -> 20296.515 | H12: =Gráficas!O14 -> 19524.714 | I12: =Gráficas!P14 -> 20657.032 | K12: =(H12/E12)^(1/$I$30)-1 -> 0.007079013 | L12: =(I12/F12)^(1/$I$30)-1 -> 0.0018050214 | N12: =E12*POWER(1+K12,$I$31) -> 18231.488 | O12: =F12*POWER(1+L12,$I$31) -> 20298.27 | P12: =SUM(N12,O12) -> 38529.759 | R12: =E12*POWER(1+K12,$I$32) -> 18886.359 | S12: =F12*POWER(1+L12,$I$32) -> 20482.228 | T12: =SUM(R12,S12) -> 39368.588 | V12: =H12*POWER(1+K12,$I$33) -> 19565.131 | W12: =I12*POWER(1+L12,$I$33) -> 20667.955 | X12: =SUM(V12,W12) -> 40233.086 | Z12: =H12*POWER(1+K12,$I$34) -> 20267.906 | AA12: =I12*POWER(1+L12,$I$34) -> 20855.263 | AB12: =SUM(Z12,AA12) -> 41123.17
B13: 35 | C13: 39 | E13: =Gráficas!C15 -> 17984.419 | F13: =Gráficas!D15 -> 20437.867 | H13: =Gráficas!O15 -> 17915.473 | I13: =Gráficas!P15 -> 19662.937 | K13: =(H13/E13)^(1/$I$30)-1 -> -0.00039334755 | L13: =(I13/F13)^(1/$I$30)-1 -> -0.0039513894 | N13: =E13*POWER(1+K13,$I$31) -> 17984.079 | O13: =F13*POWER(1+L13,$I$31) -> 20433.987 | P13: =SUM(N13,O13) -> 38418.067 | R13: =E13*POWER(1+K13,$I$32) -> 17948.718 | S13: =F13*POWER(1+L13,$I$32) -> 20033.235 | T13: =SUM(R13,S13) -> 37981.953 | V13: =H13*POWER(1+K13,$I$33) -> 17913.407 | W13: =I13*POWER(1+L13,$I$33) -> 19640.129 | X13: =SUM(V13,W13) -> 37553.535 | Z13: =H13*POWER(1+K13,$I$34) -> 17878.184 | AA13: =I13*POWER(1+L13,$I$34) -> 19254.945 | AB13: =SUM(Z13,AA13) -> 37133.129
B14: 40 | C14: 44 | E14: =Gráficas!C16 -> 16905.971 | F14: =Gráficas!D16 -> 18998.067 | H14: =Gráficas!O16 -> 16818.172 | I14: =Gráficas!P16 -> 19052.471 | K14: =(H14/E14)^(1/$I$30)-1 -> -0.00053318951 | L14: =(I14/F14)^(1/$I$30)-1 -> 0.00029294176 | N14: =E14*POWER(1+K14,$I$31) -> 16905.539 | O14: =F14*POWER(1+L14,$I$31) -> 18998.334 | P14: =SUM(N14,O14) -> 35903.873 | R14: =E14*POWER(1+K14,$I$32) -> 16860.493 | S14: =F14*POWER(1+L14,$I$32) -> 19026.192 | T14: =SUM(R14,S14) -> 35886.685 | V14: =H14*POWER(1+K14,$I$33) -> 16815.543 | W14: =I14*POWER(1+L14,$I$33) -> 19054.107 | X14: =SUM(V14,W14) -> 35869.65 | Z14: =H14*POWER(1+K14,$I$34) -> 16770.737 | AA14: =I14*POWER(1+L14,$I$34) -> 19082.047 | AB14: =SUM(Z14,AA14) -> 35852.784
B15: 45 | C15: 49 | E15: =Gráficas!C17 -> 14713.999 | F15: =Gráficas!D17 -> 16329.414 | H15: =Gráficas!O17 -> 16639.749 | I15: =Gráficas!P17 -> 19148.972 | K15: =(H15/E15)^(1/$I$30)-1 -> 0.012677752 | L15: =(I15/F15)^(1/$I$30)-1 -> 0.016448549 | N15: =E15*POWER(1+K15,$I$31) -> 14722.889 | O15: =F15*POWER(1+L15,$I$31) -> 16342.192 | P15: =SUM(N15,O15) -> 31065.081 | R15: =E15*POWER(1+K15,$I$32) -> 15680.661 | S15: =F15*POWER(1+L15,$I$32) -> 17731.96 | T15: =SUM(R15,S15) -> 33412.621 | V15: =H15*POWER(1+K15,$I$33) -> 16701.316 | W15: =I15*POWER(1+L15,$I$33) -> 19240.775 | X15: =SUM(V15,W15) -> 35942.091 | Z15: =H15*POWER(1+K15,$I$34) -> 17787.791 | AA15: =I15*POWER(1+L15,$I$34) -> 20877.042 | AB15: =SUM(Z15,AA15) -> 38664.834
B16: 50 | C16: 54 | E16: =Gráficas!C18 -> 12167.627 | F16: =Gráficas!D18 -> 13324.656 | H16: =Gráficas!O18 -> 15761.271 | I16: =Gráficas!P18 -> 18130.111 | K16: =(H16/E16)^(1/$I$30)-1 -> 0.026860235 | L16: =(I16/F16)^(1/$I$30)-1 -> 0.032046094 | N16: =E16*POWER(1+K16,$I$31) -> 12183.1 | O16: =F16*POWER(1+L16,$I$31) -> 13344.823 | P16: =SUM(N16,O16) -> 25527.923 | R16: =E16*POWER(1+K16,$I$32) -> 13910.605 | S16: =F16*POWER(1+L16,$I$32) -> 15625.928 | T16: =SUM(R16,S16) -> 29536.534 | V16: =H16*POWER(1+K16,$I$33) -> 15884.216 | W16: =I16*POWER(1+L16,$I$33) -> 18298.537 | X16: =SUM(V16,W16) -> 34182.753 | Z16: =H16*POWER(1+K16,$I$34) -> 18136.522 | AA16: =I16*POWER(1+L16,$I$34) -> 21426.408 | AB16: =SUM(Z16,AA16) -> 39562.93
... B22: 80 | C22: 84 | E22: =Gráficas!C24 -> 704.60346 | F22: =Gráficas!D24 -> 1096.2646 | H22: =Gráficas!O24 -> 1380.8506 | I22: =Gráficas!P24 -> 1792.1848 | K22: =(H22/E22)^(1/$I$30)-1 -> 0.071345324 | L22: =(I22/F22)^(1/$I$30)-1 -> 0.051634708 | N22: =E22*POWER(1+K22,$I$31) -> 706.93543 | O22: =F22*POWER(1+L22,$I$31) -> 1098.914 | P22: =SUM(N22,O22) -> 1805.8494 | R22: =E22*POWER(1+K22,$I$32) -> 997.95081 | S22: =F22*POWER(1+L22,$I$32) -> 1413.6704 | T22: =SUM(R22,S22) -> 2411.6212 | V22: =H22*POWER(1+K22,$I$33) -> 1409.0309 | W22: =I22*POWER(1+L22,$I$33) -> 1818.8317 | X22: =SUM(V22,W22) -> 3227.8626 | Z22: =H22*POWER(1+K22,$I$34) -> 1989.0693 | AA22: =I22*POWER(1+L22,$I$34) -> 2339.7905 | AB22: =SUM(Z22,AA22) -> 4328.8598
B23: 85 y más | E23: =Gráficas!C25 -> 505.32167 | F23: =Gráficas!D25 -> 880.87245 | H23: =Gráficas!O25 -> 908.55964 | I23: =Gráficas!P25 -> 1616.0684 | K23: =(H23/E23)^(1/$I$30)-1 -> 0.061932751 | L23: =(I23/F23)^(1/$I$30)-1 -> 0.064129301 | N23: =E23*POWER(1+K23,$I$31) -> 506.77963 | O23: =F23*POWER(1+L23,$I$31) -> 883.50148 | P23: =SUM(N23,O23) -> 1390.2811 | R23: =E23*POWER(1+K23,$I$32) -> 684.50358 | S23: =F23*POWER(1+L23,$I$32) -> 1205.7388 | T23: =SUM(R23,S23) -> 1890.2424 | V23: =H23*POWER(1+K23,$I$33) -> 924.70626 | W23: =I23*POWER(1+L23,$I$33) -> 1645.7853 | X23: =SUM(V23,W23) -> 2570.4915 | Z23: =H23*POWER(1+K23,$I$34) -> 1248.9941 | AA23: =I23*POWER(1+L23,$I$34) -> 2246.0485 | AB23: =SUM(Z23,AA23) -> 3495.0426
B24: Totales | E24: =SUM(E5:E23) -> 238669.55 | F24: =SUM(F5:F23) -> 248911.94 | H24: =SUM(H5:H23) -> 251568.64 | I24: =SUM(I5:I23) -> 264737.71 | K24: =(H24/E24)^(1/I30)-1 -> 0.00540592 | L24: =(I24/F24)^(1/I30)-1 -> 0.0063336382 | N24: =SUM(N5:N23) -> 238698.55 | O24: =SUM(O5:O23) -> 248947.92 | P24: =SUM(P5:P23) -> 487646.47 | R24: =SUM(R5:R23) -> 243431.73 | S24: =SUM(S5:S23) -> 254769.22 | T24: =SUM(T5:T23) -> 498200.94 | V24: =SUM(V5:V23) -> 252215.88 | W24: =SUM(W5:W23) -> 265530.79 | X24: =SUM(X5:X23) -> 517746.67 | Z24: =SUM(Z5:Z23) -> 266358.71 | AA24: =SUM(AA5:AA23) -> 282877.69 | AB24: =SUM(AB5:AB23) -> 549236.4
B25: Total Global | E25: =SUM(E24,F24) -> 487581.49 | H25: =SUM(H24,I24) -> 516306.36 | K25: =(H25/E25)^(1/I30)-1 -> 0.0058804599
B28: Fechas censales
B29: Censo | C29: Inicio | D29: Fin | E29: Referencia
B30: 2010 | C30: 40329 | D30: 40354 | E30: 40341.5 | H30: n | I30: =(E31-E30)/365 -> 9.7630137 | J30: 2010 - 2020 | N30: Tiempo de Duplicación Población | R30: Año que se duplicará población 2010 | U30: =RIGHT(R30,4)+$P$31 -> 2128.2192 | V30: =U30-P31 -> 2010
B31: 2020 | C31: 43892 | D31: 43917 | E31: 43905 | H31: n1 | I31: =(E32-E30)/365 -> 0.047945205 | J31: 2010 - 2010 | P31: =LN(2)/LN(1+K25) -> 118.21919 | R31: Año que se duplicará población 2020 | U31: =RIGHT(R31,4)+$P$31 -> 2138.2192 | V31: =U31-P31 -> 2020
B32: 2010 | E32: 40359 | H32: n2 | I32: =(E33-E30)/365 -> 5.0506849 | J32: 2010 - 2015
B33: 2015 | E33: 42185 | H33: n3 | I33: =(E34-E31)/365 -> 0.29315068 | J33: 2020 - 2020
B34: 2020 | E34: 44012 | H34: n4 | I34: =(E35-E31)/365 -> 5.2958904 | J34: 2020 - 2025
B35: 2025 | E35: 45838
B37: Hombres | R37: Mujeres
B38: Grupos | C38: 2010 | D38: 2015 | E38: 2020 | F38: 2025 | R38: Grupos | S38: 2010 | T38: 2015 | U38: 2020 | V38: 2025
B39: 0 | C39: =N5 -> 3907.1773 | D39: =R5 -> 3489.4652 | E39: =V5 -> 3116.2172 | F39: =Z5 -> 2783.0658 | R39: =B39 -> 0 | S39: =O5 -> 3864.5627 | T39: =S5 -> 3434.9375 | U39: =W5 -> 3052.8769 | V39: =AA5 -> 2713.4872
B40: 1 | C40: =N6 -> 18182.401 | D40: =R6 -> 16463.472 | E40: =V6 -> 14906.237 | F40: =Z6 -> 13497.031 | R40: =B40 -> 1 | S40: =O6 -> 17457.319 | T40: =S6 -> 15879.312 | U40: =W6 -> 14443.195 | V40: =AA6 -> 13137.641
B41: 5 | C41: =N7 -> 23465.682 | D41: =R7 -> 21268.819 | E41: =V7 -> 19276.589 | F41: =Z7 -> 17471.909 | R41: =B41 -> 5 | S41: =O7 -> 22393.196 | T41: =S7 -> 20519.665 | U41: =W7 -> 18801.983 | V41: =AA7 -> 17228.911
B42: =B41+5 -> 10 | C42: =N8 -> 22922.623 | D42: =R8 -> 21792.127 | E42: =V8 -> 20716.811 | F42: =Z8 -> 19695.1 | R42: =B42 -> 10 | S42: =O8 -> 22310.889 | T42: =S8 -> 21008.456 | U42: =W8 -> 19781.403 | V42: =AA8 -> 18626.633
B43: =B42+5 -> 15 | C43: =N9 -> 23496.644 | D43: =R9 -> 22486.187 | E43: =V9 -> 21518.666 | F43: =Z9 -> 20593.27 | R43: =B43 -> 15 | S43: =O9 -> 23208.308 | T43: =S9 -> 21864.279 | U43: =W9 -> 20597.411 | V43: =AA9 -> 19404.583
B44: =B43+5 -> 20 | C44: =N10 -> 22924.811 | D44: =R10 -> 22242.664 | E44: =V10 -> 21580.458 | F44: =Z10 -> 20938.313 | R44: =B44 -> 20 | S44: =O10 -> 23019.882 | T44: =S10 -> 22070.509 | U44: =W10 -> 21159.801 | V44: =AA10 -> 20287.14
B45: =B44+5 -> 25 | C45: =N11 -> 20143.504 | D45: =R11 -> 20521.443 | E45: =V11 -> 20906.686 | F45: =Z11 -> 21298.945 | R45: =B45 -> 25 | S45: =O11 -> 21174.039 | T45: =S11 -> 21228.894 | U45: =W11 -> 21283.921 | V45: =AA11 -> 21339.06
B46: =B45+5 -> 30 | C46: =N12 -> 18231.488 | D46: =R12 -> 18886.359 | E46: =V12 -> 19565.131 | F46: =Z12 -> 20267.906 | R46: =B46 -> 30 | S46: =O12 -> 20298.27 | T46: =S12 -> 20482.228 | U46: =W12 -> 20667.955 | V46: =AA12 -> 20855.263
B47: =B46+5 -> 35 | C47: =N13 -> 17984.079 | D47: =R13 -> 17948.718 | E47: =V13 -> 17913.407 | F47: =Z13 -> 17878.184 | R47: =B47 -> 35 | S47: =O13 -> 20433.987 | T47: =S13 -> 20033.235 | U47: =W13 -> 19640.129 | V47: =AA13 -> 19254.945
B48: =B47+5 -> 40 | C48: =N14 -> 16905.539 | D48: =R14 -> 16860.493 | E48: =V14 -> 16815.543 | F48: =Z14 -> 16770.737 | R48: =B48 -> 40 | S48: =O14 -> 18998.334 | T48: =S14 -> 19026.192 | U48: =W14 -> 19054.107 | V48: =AA14 -> 19082.047
B49: =B48+5 -> 45 | C49: =N15 -> 14722.889 | D49: =R15 -> 15680.661 | E49: =V15 -> 16701.316 | F49: =Z15 -> 17787.791 | R49: =B49 -> 45 | S49: =O15 -> 16342.192 | T49: =S15 -> 17731.96 | U49: =W15 -> 19240.775 | V49: =AA15 -> 20877.042
...

Sheet Exponencial
A1: EXPONENCIAL
B3: Grupos | E3: Censo 2010 | H3: Censo 2020 | K3: Tasa Exponencial | N3: Proyección mitad de año 2010 | R3: Proyección 2015 | V3: Proyección mitad de año 2020 | Z3: Proyección 2025
B4: Edad inicial | C4: Edad final | E4: HOMBRES | F4: MUJERES | H4: HOMBRES | I4: MUJERES | K4: HOMBRES | L4: MUJERES | N4: HOMBRES | O4: MUJERES | P4: TOTALES | R4: HOMBRES | S4: MUJERES | T4: TOTALES | V4: HOMBRES | W4: MUJERES | X4: TOTALES | Z4: HOMBRES | AA4: MUJERES | AB4: TOTALES
B5: 0 | C5: 0 | E5: =Gráficas!C7 -> 3911.4134 | F5: =Gráficas!D7 -> 3868.93 | H5: =Gráficas!O7 -> 3136.9322 | I5: =Gráficas!P7 -> 3074.0323 | K5: =(LN(H5/E5))/$I$30 -> -0.022600959 | L5: =(LN(I5/F5))/$I$30 -> -0.023557053 | N5: =E5*EXP(K5*$I$31) -> 3907.1773 | O5: =F5*EXP(L5*$I$31) -> 3864.5627 | P5: =SUM(N5,O5) -> 7771.74 | R5: =E5*EXP(K5*$I$32) -> 3489.4652 | S5: =F5*EXP(L5*$I$32) -> 3434.9375 | T5: =SUM(R5,S5) -> 6924.4027 | V5: =H5*EXP(K5*$I$33) -> 3116.2172 | W5: =I5*EXP(L5*$I$33) -> 3052.8769 | X5: =SUM(V5,W5) -> 6169.0941 | Z5: =H5*EXP(K5*$I$34) -> 2783.0658 | AA5: =I5*EXP(L5*$I$34) -> 2713.4872 | AB5: =SUM(Z5,AA5) -> 5496.553
B6: 1 | C6: 4 | E6: =Gráficas!C8 -> 18199.714 | F6: =Gráficas!D8 -> 17473.177 | H6: =Gráficas!O8 -> 14993.235 | I6: =Gráficas!P8 -> 14523.602 | K6: =(LN(H6/E6))/$I$30 -> -0.019851121 | L6: =(LN(I6/F6))/$I$30 -> -0.018937997 | N6: =E6*EXP(K6*$I$31) -> 18182.401 | O6: =F6*EXP(L6*$I$31) -> 17457.319 | P6: =SUM(N6,O6) -> 35639.719 | R6: =E6*EXP(K6*$I$32) -> 16463.472 | S6: =F6*EXP(L6*$I$32) -> 15879.312 | T6: =SUM(R6,S6) -> 32342.784 | V6: =H6*EXP(K6*$I$33) -> 14906.237 | W6: =I6*EXP(L6*$I$33) -> 14443.195 | X6: =SUM(V6,W6) -> 29349.432 | Z6: =H6*EXP(K6*$I$34) -> 13497.031 | AA6: =I6*EXP(L6*$I$34) -> 13137.641 | AB6: =SUM(Z6,AA6) -> 26634.672
B7: 5 | C7: 9 | E7: =Gráficas!C9 -> 23487.799 | F7: =Gráficas!D9 -> 22411.956 | H7: =Gráficas!O9 -> 19387.942 | I7: =Gráficas!P9 -> 18898.494 | K7: =(LN(H7/E7))/$I$30 -> -0.01964862 | L7: =(LN(I7/F7))/$I$30 -> -0.01746513 | N7: =E7*EXP(K7*$I$31) -> 23465.682 | O7: =F7*EXP(L7*$I$31) -> 22393.196 | P7: =SUM(N7,O7) -> 45858.879 | R7: =E7*EXP(K7*$I$32) -> 21268.819 | S7: =F7*EXP(L7*$I$32) -> 20519.665 | T7: =SUM(R7,S7) -> 41788.483 | V7: =H7*EXP(K7*$I$33) -> 19276.589 | W7: =I7*EXP(L7*$I$33) -> 18801.983 | X7: =SUM(V7,W7) -> 38078.571 | Z7: =H7*EXP(K7*$I$34) -> 17471.909 | AA7: =I7*EXP(L7*$I$34) -> 17228.911 | AB7: =SUM(Z7,AA7) -> 34700.82
B8: 10 | C8: 14 | E8: =Gráficas!C10 -> 22933.737 | F8: =Gráficas!D10 -> 22323.754 | H8: =Gráficas!O10 -> 20778.299 | I8: =Gráficas!P10 -> 19851.249 | K8: =(LN(H8/E8))/$I$30 -> -0.010109578 | L8: =(LN(I8/F8))/$I$30 -> -0.012023376 | N8: =E8*EXP(K8*$I$31) -> 22922.623 | O8: =F8*EXP(L8*$I$31) -> 22310.889 | P8: =SUM(N8,O8) -> 45233.512 | R8: =E8*EXP(K8*$I$32) -> 21792.127 | S8: =F8*EXP(L8*$I$32) -> 21008.456 | T8: =SUM(R8,S8) -> 42800.583 | V8: =H8*EXP(K8*$I$33) -> 20716.811 | W8: =I8*EXP(L8*$I$33) -> 19781.403 | X8: =SUM(V8,W8) -> 40498.214 | Z8: =H8*EXP(K8*$I$34) -> 19695.1 | AA8: =I8*EXP(L8*$I$34) -> 18626.633 | AB8: =SUM(Z8,AA8) -> 38321.734
B9: 15 | C9: 19 | E9: =Gráficas!C11 -> 23506.545 | F9: =Gráficas!D11 -> 23221.581 | H9: =Gráficas!O11 -> 21574.164 | I9: =Gráficas!P11 -> 20669.54 | K9: =(LN(H9/E9))/$I$30 -> -0.008786468 | L9: =(LN(I9/F9))/$I$30 -> -0.011924693 | N9: =E9*EXP(K9*$I$31) -> 23496.644 | O9: =F9*EXP(L9*$I$31) -> 23208.308 | P9: =SUM(N9,O9) -> 46704.953 | R9: =E9*EXP(K9*$I$32) -> 22486.187 | S9: =F9*EXP(L9*$I$32) -> 21864.279 | T9: =SUM(R9,S9) -> 44350.466 | V9: =H9*EXP(K9*$I$33) -> 21518.666 | W9: =I9*EXP(L9*$I$33) -> 20597.411 | X9: =SUM(V9,W9) -> 42116.077 | Z9: =H9*EXP(K9*$I$34) -> 20593.27 | AA9: =I9*EXP(L9*$I$34) -> 19404.583 | AB9: =SUM(Z9,AA9) -> 39997.852
B10: 20 | C10: 24 | E10: =Gráficas!C12 -> 22931.449 | F10: =Gráficas!D12 -> 23029.176 | H10: =Gráficas!O12 -> 21618.691 | I10: =Gráficas!P12 -> 21212.086 | K10: =(LN(H10/E10))/$I$30 -> -0.0060381987 | L10: =(LN(I10/F10))/$I$30 -> -0.0084185895 | N10: =E10*EXP(K10*$I$31) -> 22924.811 | O10: =F10*EXP(L10*$I$31) -> 23019.882 | P10: =SUM(N10,O10) -> 45944.694 | R10: =E10*EXP(K10*$I$32) -> 22242.664 | S10: =F10*EXP(L10*$I$32) -> 22070.509 | T10: =SUM(R10,S10) -> 44313.173 | V10: =H10*EXP(K10*$I$33) -> 21580.458 | W10: =I10*EXP(L10*$I$33) -> 21159.801 | X10: =SUM(V10,W10) -> 42740.259 | Z10: =H10*EXP(K10*$I$34) -> 20938.313 | AA10: =I10*EXP(L10*$I$34) -> 20287.14 | AB10: =SUM(Z10,AA10) -> 41225.453
B11: 25 | C11: 29 | E11: =Gráficas!C13 -> 20139.916 | F11: =Gráficas!D13 -> 21173.514 | H11: =Gráficas!O13 -> 20883.926 | I11: =Gráficas!P13 -> 21280.694 | K11: =(LN(H11/E11))/$I$30 -> 0.0037156651 | L11: =(LN(I11/F11))/$I$30 -> 0.00051717632 | N11: =E11*EXP(K11*$I$31) -> 20143.504 | O11: =F11*EXP(L11*$I$31) -> 21174.039 | P11: =SUM(N11,O11) -> 41317.543 | R11: =E11*EXP(K11*$I$32) -> 20521.443 | S11: =F11*EXP(L11*$I$32) -> 21228.894 | T11: =SUM(R11,S11) -> 41750.337 | V11: =H11*EXP(K11*$I$33) -> 20906.686 | W11: =I11*EXP(L11*$I$33) -> 21283.921 | X11: =SUM(V11,W11) -> 42190.607 | Z11: =H11*EXP(K11*$I$34) -> 21298.945 | AA11: =I11*EXP(L11*$I$34) -> 21339.06 | AB11: =SUM(Z11,AA11) -> 42638.005
B12: 30 | C12: 34 | E12: =Gráficas!C14 -> 18225.323 | F12: =Gráficas!D14 -> 20296.515 | H12: =Gráficas!O14 -> 19524.714 | I12: =Gráficas!P14 -> 20657.032 | K12: =(LN(H12/E12))/$I$30 -> 0.0070540745 | L12: =(LN(I12/F12))/$I$30 -> 0.0018033943 | N12: =E12*EXP(K12*$I$31) -> 18231.488 | O12: =F12*EXP(L12*$I$31) -> 20298.27 | P12: =SUM(N12,O12) -> 38529.759 | R12: =E12*EXP(K12*$I$32) -> 18886.359 | S12: =F12*EXP(L12*$I$32) -> 20482.228 | T12: =SUM(R12,S12) -> 39368.588 | V12: =H12*EXP(K12*$I$33) -> 19565.131 | W12: =I12*EXP(L12*$I$33) -> 20667.955 | X12: =SUM(V12,W12) -> 40233.086 | Z12: =H12*EXP(K12*$I$34) -> 20267.906 | AA12: =I12*EXP(L12*$I$34) -> 20855.263 | AB12: =SUM(Z12,AA12) -> 41123.17
B13: 35 | C13: 39 | E13: =Gráficas!C15 -> 17984.419 | F13: =Gráficas!D15 -> 20437.867 | H13: =Gráficas!O15 -> 17915.473 | I13: =Gráficas!P15 -> 19662.937 | K13: =(LN(H13/E13))/$I$30 -> -0.00039342493 | L13: =(LN(I13/F13))/$I$30 -> -0.0039592168 | N13: =E13*EXP(K13*$I$31) -> 17984.079 | O13: =F13*EXP(L13*$I$31) -> 20433.987 | P13: =SUM(N13,O13) -> 38418.067 | R13: =E13*EXP(K13*$I$32) -> 17948.718 | S13: =F13*EXP(L13*$I$32) -> 20033.235 | T13: =SUM(R13,S13) -> 37981.953 | V13: =H13*EXP(K13*$I$33) -> 17913.407 | W13: =I13*EXP(L13*$I$33) -> 19640.129 | X13: =SUM(V13,W13) -> 37553.535 | Z13: =H13*EXP(K13*$I$34) -> 17878.184 | AA13: =I13*EXP(L13*$I$34) -> 19254.945 | AB13: =SUM(Z13,AA13) -> 37133.129
B14: 40 | C14: 44 | E14: =Gráficas!C16 -> 16905.971 | F14: =Gráficas!D16 -> 18998.067 | H14: =Gráficas!O16 -> 16818.172 | I14: =Gráficas!P16 -> 19052.471 | K14: =(LN(H14/E14))/$I$30 -> -0.00053333171 | L14: =(LN(I14/F14))/$I$30 -> 0.00029289886 | N14: =E14*EXP(K14*$I$31) -> 16905.539 | O14: =F14*EXP(L14*$I$31) -> 18998.334 | P14: =SUM(N14,O14) -> 35903.873 | R14: =E14*EXP(K14*$I$32) -> 16860.493 | S14: =F14*EXP(L14*$I$32) -> 19026.192 | T14: =SUM(R14,S14) -> 35886.685 | V14: =H14*EXP(K14*$I$33) -> 16815.543 | W14: =I14*EXP(L14*$I$33) -> 19054.107 | X14: =SUM(V14,W14) -> 35869.65 | Z14: =H14*EXP(K14*$I$34) -> 16770.737 | AA14: =I14*EXP(L14*$I$34) -> 19082.047 | AB14: =SUM(Z14,AA14) -> 35852.784
B15: 45 | C15: 49 | E15: =Gráficas!C17 -> 14713.999 | F15: =Gráficas!D17 -> 16329.414 | H15: =Gráficas!O17 -> 16639.749 | I15: =Gráficas!P17 -> 19148.972 | K15: =(LN(H15/E15))/$I$30 -> 0.012598062 | L15: =(LN(I15/F15))/$I$30 -> 0.016314737 | N15: =E15*EXP(K15*$I$31) -> 14722.889 | O15: =F15*EXP(L15*$I$31) -> 16342.192 | P15: =SUM(N15,O15) -> 31065.081 | R15: =E15*EXP(K15*$I$32) -> 15680.661 | S15: =F15*EXP(L15*$I$32) -> 17731.96 | T15: =SUM(R15,S15) -> 33412.621 | V15: =H15*EXP(K15*$I$33) -> 16701.316 | W15: =I15*EXP(L15*$I$33) -> 19240.775 | X15: =SUM(V15,W15) -> 35942.091 | Z15: =H15*EXP(K15*$I$34) -> 17787.791 | AA15: =I15*EXP(L15*$I$34) -> 20877.042 | AB15: =SUM(Z15,AA15) -> 38664.834
B16: 50 | C16: 54 | E16: =Gráficas!C18 -> 12167.627 | F16: =Gráficas!D18 -> 13324.656 | H16: =Gráficas!O18 -> 15761.271 | I16: =Gráficas!P18 -> 18130.111 | K16: =(LN(H16/E16))/$I$30 -> 0.026505831 | L16: =(LN(I16/F16))/$I$30 -> 0.031543331 | N16: =E16*EXP(K16*$I$31) -> 12183.1 | O16: =F16*EXP(L16*$I$31) -> 13344.823 | P16: =SUM(N16,O16) -> 25527.923 | R16: =E16*EXP(K16*$I$32) -> 13910.605 | S16: =F16*EXP(L16*$I$32) -> 15625.928 | T16: =SUM(R16,S16) -> 29536.534 | V16: =H16*EXP(K16*$I$33) -> 15884.216 | W16: =I16*EXP(L16*$I$33) -> 18298.537 | X16: =SUM(V16,W16) -> 34182.753 | Z16: =H16*EXP(K16*$I$34) -> 18136.522 | AA16: =I16*EXP(L16*$I$34) -> 21426.408 | AB16: =SUM(Z16,AA16) -> 39562.93
... B22: 80 | C22: 84 | E22: =Gráficas!C24 -> 704.60346 | F22: =Gráficas!D24 -> 1096.2646 | H22: =Gráficas!O24 -> 1380.8506 | I22: =Gráficas!P24 -> 1792.1848 | K22: =(LN(H22/E22))/$I$30 -> 0.068915171 | L22: =(LN(I22/F22))/$I$30 -> 0.050345818 | N22: =E22*EXP(K22*$I$31) -> 706.93543 | O22: =F22*EXP(L22*$I$31) -> 1098.914 | P22: =SUM(N22,O22) -> 1805.8494 | R22: =E22*EXP(K22*$I$32) -> 997.95081 | S22: =F22*EXP(L22*$I$32) -> 1413.6704 | T22: =SUM(R22,S22) -> 2411.6212 | V22: =H22*EXP(K22*$I$33) -> 1409.0309 | W22: =I22*EXP(L22*$I$33) -> 1818.8317 | X22: =SUM(V22,W22) -> 3227.8626 | Z22: =H22*EXP(K22*$I$34) -> 1989.0693 | AA22: =I22*EXP(L22*$I$34) -> 2339.7905 | AB22: =SUM(Z22,AA22) -> 4328.8598
B23: 85 y más | E23: =Gráficas!C25 -> 505.32167 | F23: =Gráficas!D25 -> 880.87245 | H23: =Gráficas!O25 -> 908.55964 | I23: =Gráficas!P25 -> 1616.0684 | K23: =(LN(H23/E23))/$I$30 -> 0.060090598 | L23: =(LN(I23/F23))/$I$30 -> 0.062156907 | N23: =E23*EXP(K23*$I$31) -> 506.77963 | O23: =F23*EXP(L23*$I$31) -> 883.50148 | P23: =SUM(N23,O23) -> 1390.2811 | R23: =E23*EXP(K23*$I$32) -> 684.50358 | S23: =F23*EXP(L23*$I$32) -> 1205.7388 | T23: =SUM(R23,S23) -> 1890.2424 | V23: =H23*EXP(K23*$I$33) -> 924.70626 | W23: =I23*EXP(L23*$I$33) -> 1645.7853 | X23: =SUM(V23,W23) -> 2570.4915 | Z23: =H23*EXP(K23*$I$34) -> 1248.9941 | AA23: =I23*EXP(L23*$I$34) -> 2246.0485 | AB23: =SUM(Z23,AA23) -> 3495.0426
B24: Totales | E24: =SUM(E5:E23) -> 238669.55 | F24: =SUM(F5:F23) -> 248911.94 | H24: =SUM(H5:H23) -> 251568.64 | I24: =SUM(I5:I23) -> 264737.71 | K24: =(LN(H24/E24))/I30 -> 0.0053913604 | L24: =(LN(I24/F24))/I30 -> 0.006313665 | N24: =SUM(N5:N23) -> 238698.55 | O24: =SUM(O5:O23) -> 248947.92 | P24: =SUM(P5:P23) -> 487646.47 | R24: =SUM(R5:R23) -> 243431.73 | S24: =SUM(S5:S23) -> 254769.22 | T24: =SUM(T5:T23) -> 498200.94 | V24: =SUM(V5:V23) -> 252215.88 | W24: =SUM(W5:W23) -> 265530.79 | X24: =SUM(X5:X23) -> 517746.67 | Z24: =SUM(Z5:Z23) -> 266358.71 | AA24: =SUM(AA5:AA23) -> 282877.69 | AB24: =SUM(AB5:AB23) -> 549236.4
B25: Total Global | E25: =SUM(E24,F24) -> 487581.49 | H25: =SUM(H24,I24) -> 516306.36 | L25: =(LN(H25/E25))/I30 -> 0.0058632375
B28: Fechas censales
B29: Censo | C29: Inicio | D29: Fin | E29: Referencia
B30: 2010 | C30: 40329 | D30: 40354 | E30: 40341.5 | H30: n | I30: =(E31-E30)/365 -> 9.7630137 | J30: 2010 - 2020 | N30: Tiempo de Duplicación Población | R30: Año que se duplicará población 2010 | U30: =RIGHT(R30,4)+$P$31 -> 2128.2192 | V30: 2010
B31: 2020 | C31: 43892 | D31: 43917 | E31: 43905 | H31: n1 | I31: =(E32-E30)/365 -> 0.047945205 | J31: 2010 - 2010 | P31: =LN(2)/L25 -> 118.21919 | R31: Año que se duplicará población 2020 | U31: =RIGHT(R31,4)+$P$31 -> 2138.2192 | V31: 2020
B32: 2010 | E32: 40359 | H32: n2 | I32: =(E33-E30)/365 -> 5.0506849 | J32: 2010 - 2015
B33: 2015 | E33: 42185 | H33: n3 | I33: =(E34-E31)/365 -> 0.29315068 | J33: 2020 - 2020
B34: 2020 | E34: 44012 | H34: n4 | I34: =(E35-E31)/365 -> 5.2958904 | J34: 2020 - 2025
B35: 2025 | E35: 45838
B37: Hombres | R37: Mujeres
B38: Grupos | C38: 2010 | D38: 2015 | E38: 2020 | F38: 2025 | R38: Grupos | S38: 2010 | T38: 2015 | U38: 2020 | V38: 2025
B39: 0 | C39: =N5 -> 3907.1773 | D39: =R5 -> 3489.4652 | E39: =V5 -> 3116.2172 | F39: =Z5 -> 2783.0658 | R39: =B39 -> 0 | S39: =O5 -> 3864.5627 | T39: =S5 -> 3434.9375 | U39: =W5 -> 3052.8769 | V39: =AA5 -> 2713.4872
B40: 1 | C40: =N6 -> 18182.401 | D40: =R6 -> 16463.472 | E40: =V6 -> 14906.237 | F40: =Z6 -> 13497.031 | R40: =B40 -> 1 | S40: =O6 -> 17457.319 | T40: =S6 -> 15879.312 | U40: =W6 -> 14443.195 | V40: =AA6 -> 13137.641
B41: 5 | C41: =N7 -> 23465.682 | D41: =R7 -> 21268.819 | E41: =V7 -> 19276.589 | F41: =Z7 -> 17471.909 | R41: =B41 -> 5 | S41: =O7 -> 22393.196 | T41: =S7 -> 20519.665 | U41: =W7 -> 18801.983 | V41: =AA7 -> 17228.911
B42: =B41+5 -> 10 | C42: =N8 -> 22922.623 | D42: =R8 -> 21792.127 | E42: =V8 -> 20716.811 | F42: =Z8 -> 19695.1 | R42: =B42 -> 10 | S42: =O8 -> 22310.889 | T42: =S8 -> 21008.456 | U42: =W8 -> 19781.403 | V42: =AA8 -> 18626.633
B43: =B42+5 -> 15 | C43: =N9 -> 23496.644 | D43: =R9 -> 22486.187 | E43: =V9 -> 21518.666 | F43: =Z9 -> 20593.27 | R43: =B43 -> 15 | S43: =O9 -> 23208.308 | T43: =S9 -> 21864.279 | U43: =W9 -> 20597.411 | V43: =AA9 -> 19404.583
B44: =B43+5 -> 20 | C44: =N10 -> 22924.811 | D44: =R10 -> 22242.664 | E44: =V10 -> 21580.458 | F44: =Z10 -> 20938.313 | R44: =B44 -> 20 | S44: =O10 -> 23019.882 | T44: =S10 -> 22070.509 | U44: =W10 -> 21159.801 | V44: =AA10 -> 20287.14
B45: =B44+5 -> 25 | C45: =N11 -> 20143.504 | D45: =R11 -> 20521.443 | E45: =V11 -> 20906.686 | F45: =Z11 -> 21298.945 | R45: =B45 -> 25 | S45: =O11 -> 21174.039 | T45: =S11 -> 21228.894 | U45: =W11 -> 21283.921 | V45: =AA11 -> 21339.06
B46: =B45+5 -> 30 | C46: =N12 -> 18231.488 | D46: =R12 -> 18886.359 | E46: =V12 -> 19565.131 | F46: =Z12 -> 20267.906 | R46: =B46 -> 30 | S46: =O12 -> 20298.27 | T46: =S12 -> 20482.228 | U46: =W12 -> 20667.955 | V46: =AA12 -> 20855.263
B47: =B46+5 -> 35 | C47: =N13 -> 17984.079 | D47: =R13 -> 17948.718 | E47: =V13 -> 17913.407 | F47: =Z13 -> 17878.184 | R47: =B47 -> 35 | S47: =O13 -> 20433.987 | T47: =S13 -> 20033.235 | U47: =W13 -> 19640.129 | V47: =AA13 -> 19254.945
B48: =B47+5 -> 40 | C48: =N14 -> 16905.539 | D48: =R14 -> 16860.493 | E48: =V14 -> 16815.543 | F48: =Z14 -> 16770.737 | R48: =B48 -> 40 | S48: =O14 -> 18998.334 | T48: =S14 -> 19026.192 | U48: =W14 -> 19054.107 | V48: =AA14 -> 19082.047
B49: =B48+5 -> 45 | C49: =N15 -> 14722.889 | D49: =R15 -> 15680.661 | E49: =V15 -> 16701.316 | F49: =Z15 -> 17787.791 | R49: =B49 -> 45 | S49: =O15 -> 16342.192 | T49: =S15 -> 17731.96 | U49: =W15 -> 19240.775 | V49: =AA15 -> 20877.042
...
