Workbook

Sheet Nacimientos
A1: Nacimientos
B3: DESCARGA DE INEGI | C3: .
C4: 2009 | E4: 2010 | G4: 2011 | I4: 2019 | K4: 2020
B5: edad | C5: Hombre | D5: Mujer | E5: Hombre | F5: Mujer | G5: Hombre | H5: Mujer | I5: Hombre | J5: Mujer | K5: Hombre | L5: Mujer
B6: Menor de 15 años | C6: 3 | D6: 8 | E6: 3 | F6: 6 | G6: 3 | H6: 7 | I6: 3 | J6: 7 | K6: 4 | L6: 2
B7: De 15 a 19 años | C7: 283 | D7: 275 | E7: 270 | F7: 283 | G7: 341 | H7: 292 | I7: 484 | J7: 429 | K7: 254 | L7: 235
B8: De 20 a 24 años | C8: 405 | D8: 393 | E8: 438 | F8: 410 | G8: 531 | H8: 500 | I8: 827 | J8: 800 | K8: 559 | L8: 587
B9: De 25 a 29 años | C9: 312 | D9: 305 | E9: 315 | F9: 334 | G9: 525 | H9: 453 | I9: 883 | J9: 878 | K9: 648 | L9: 592
B10: De 30 a 34 años | C10: 180 | D10: 204 | E10: 173 | F10: 193 | G10: 260 | H10: 285 | I10: 658 | J10: 641 | K10: 442 | L10: 468
B11: De 35 a 39 años | C11: 86 | D11: 81 | E11: 89 | F11: 101 | G11: 165 | H11: 143 | I11: 298 | J11: 277 | K11: 195 | L11: 197
B12: De 40 a 44 años | C12: 24 | D12: 20 | E12: 21 | F12: 12 | G12: 19 | H12: 28 | I12: 70 | J12: 67 | K12: 49 | L12: 49
B13: De 45 a 49 años | D13: 3 | E13: 1 | F13: 2 | G13: 1 | H13: 2 | I13: 2 | J13: 3 | K13: 6 | L13: 1
B14: De 50 y más años | I14: 1 | J14: 2
B15: No especificado | C15: 20 | D15: 19 | E15: 18 | F15: 53 | G15: 37 | H15: 36 | I15: 12 | J15: 7 | K15: 44 | L15: 35
B19: PRORRATEO
C20: 2009 | E20: 2010 | G20: 2011 | I20: 2019 | K20: 2020
B21: edad | C21: Hombre | D21: Mujer | E21: Hombre | F21: Mujer | G21: Hombre | H21: Mujer | I21: Hombre | J21: Mujer | K21: Hombre | L21: Mujer
B22: Menor de 15 años | C22: =C6+C6*($C$15/SUM($C$6:$C$14)) -> 3.0464037 | D22: =D6+D6*($D$15/SUM($D$6:$D$14)) -> 8.1179209 | E22: =E6+E6*($E$15/SUM($E$6:$E$14)) -> 3.0412214 | F22: =F6+F6*($F$15/SUM($F$6:$F$14)) -> 6.2371365 | G22: =G6+G6*($G$15/SUM($G$6:$G$14)) -> 3.0601626 | H22: =H6+H6*($H$15/SUM($H$6:$H$14)) -> 7.1473684 | I22: =I6+I6*($I$15/SUM($I$6:$I$14)) -> 3.0111593 | J22: =J6+J6*($J$15/SUM($J$6:$J$14)) -> 7.0157861 | K22: =K6+K6*($K$15/SUM($K$6:$K$14)) -> 4.0815948 | L22: =L6+L6*($L$15/SUM($L$6:$L$14)) -> 2.0328484
B23: De 15 a 19 años | C23: =C7+C7*($C$15/SUM($C$6:$C$14)) -> 287.37742 | D23: =D7+D7*($D$15/SUM($D$6:$D$14)) -> 279.05353 | E23: =E7+E7*($E$15/SUM($E$6:$E$14)) -> 273.70992 | F23: =F7+F7*($F$15/SUM($F$6:$F$14)) -> 294.18494 | G23: =G7+G7*($G$15/SUM($G$6:$G$14)) -> 347.83848 | H23: =H7+H7*($H$15/SUM($H$6:$H$14)) -> 298.14737 | I23: =I7+I7*($I$15/SUM($I$6:$I$14)) -> 485.80037 | J23: =J7+J7*($J$15/SUM($J$6:$J$14)) -> 429.96746 | K23: =K7+K7*($K$15/SUM($K$6:$K$14)) -> 259.18127 | L23: =L7+L7*($L$15/SUM($L$6:$L$14)) -> 238.85969
B24: De 20 a 24 años | C24: =C8+C8*($C$15/SUM($C$6:$C$14)) -> 411.2645 | D24: =D8+D8*($D$15/SUM($D$6:$D$14)) -> 398.79286 | E24: =E8+E8*($E$15/SUM($E$6:$E$14)) -> 444.01832 | F24: =F8+F8*($F$15/SUM($F$6:$F$14)) -> 426.20433 | G24: =G8+G8*($G$15/SUM($G$6:$G$14)) -> 541.64878 | H24: =H8+H8*($H$15/SUM($H$6:$H$14)) -> 510.52632 | I24: =I8+I8*($I$15/SUM($I$6:$I$14)) -> 830.07626 | J24: =J8+J8*($J$15/SUM($J$6:$J$14)) -> 801.80412 | K24: =K8+K8*($K$15/SUM($K$6:$K$14)) -> 570.40287 | L24: =L8+L8*($L$15/SUM($L$6:$L$14)) -> 596.64101
B25: De 25 a 29 años | C25: =C9+C9*($C$15/SUM($C$6:$C$14)) -> 316.82599 | D25: =D9+D9*($D$15/SUM($D$6:$D$14)) -> 309.49573 | E25: =E9+E9*($E$15/SUM($E$6:$E$14)) -> 319.32824 | F25: =F9+F9*($F$15/SUM($F$6:$F$14)) -> 347.2006 | G25: =G9+G9*($G$15/SUM($G$6:$G$14)) -> 535.52846 | H25: =H9+H9*($H$15/SUM($H$6:$H$14)) -> 462.53684 | I25: =I9+I9*($I$15/SUM($I$6:$I$14)) -> 886.28456 | J25: =J9+J9*($J$15/SUM($J$6:$J$14)) -> 879.98003 | K25: =K9+K9*($K$15/SUM($K$6:$K$14)) -> 661.21836 | L25: =L9+L9*($L$15/SUM($L$6:$L$14)) -> 601.72313
B26: De 30 a 34 años | C26: =C10+C10*($C$15/SUM($C$6:$C$14)) -> 182.78422 | D26: =D10+D10*($D$15/SUM($D$6:$D$14)) -> 207.00698 | E26: =E10+E10*($E$15/SUM($E$6:$E$14)) -> 175.3771 | F26: =F10+F10*($F$15/SUM($F$6:$F$14)) -> 200.62789 | G26: =G10+G10*($G$15/SUM($G$6:$G$14)) -> 265.21409 | H26: =H10+H10*($H$15/SUM($H$6:$H$14)) -> 291 | I26: =I10+I10*($I$15/SUM($I$6:$I$14)) -> 660.44761 | J26: =J10+J10*($J$15/SUM($J$6:$J$14)) -> 642.44555 | K26: =K10+K10*($K$15/SUM($K$6:$K$14)) -> 451.01623 | L26: =L10+L10*($L$15/SUM($L$6:$L$14)) -> 475.68653
B27: De 35 a 39 años | C27: =C11+C11*($C$15/SUM($C$6:$C$14)) -> 87.33024 | D27: =D11+D11*($D$15/SUM($D$6:$D$14)) -> 82.193949 | E27: =E11+E11*($E$15/SUM($E$6:$E$14)) -> 90.222901 | F27: =F11+F11*($F$15/SUM($F$6:$F$14)) -> 104.9918 | G27: =G11+G11*($G$15/SUM($G$6:$G$14)) -> 168.30894 | H27: =H11+H11*($H$15/SUM($H$6:$H$14)) -> 146.01053 | I27: =I11+I11*($I$15/SUM($I$6:$I$14)) -> 299.10849 | J27: =J11+J11*($J$15/SUM($J$6:$J$14)) -> 277.62468 | K27: =K11+K11*($K$15/SUM($K$6:$K$14)) -> 198.97775 | L27: =L11+L11*($L$15/SUM($L$6:$L$14)) -> 200.23557
B28: De 40 a 44 años | C28: =C12+C12*($C$15/SUM($C$6:$C$14)) -> 24.37123 | D28: =D12+D12*($D$15/SUM($D$6:$D$14)) -> 20.294802 | E28: =E12+E12*($E$15/SUM($E$6:$E$14)) -> 21.28855 | F28: =F12+F12*($F$15/SUM($F$6:$F$14)) -> 12.474273 | G28: =G12+G12*($G$15/SUM($G$6:$G$14)) -> 19.38103 | H28: =H12+H12*($H$15/SUM($H$6:$H$14)) -> 28.589474 | I28: =I12+I12*($I$15/SUM($I$6:$I$14)) -> 70.260384 | J28: =J12+J12*($J$15/SUM($J$6:$J$14)) -> 67.151095 | K28: =K12+K12*($K$15/SUM($K$6:$K$14)) -> 49.999536 | L28: =L12+L12*($L$15/SUM($L$6:$L$14)) -> 49.804786
B29: De 45 a 49 años | C29: =C13+C13*($C$15/SUM($C$6:$C$14)) -> 0 | D29: =D13+D13*($D$15/SUM($D$6:$D$14)) -> 3.0442203 | E29: =E13+E13*($E$15/SUM($E$6:$E$14)) -> 1.0137405 | F29: =F13+F13*($F$15/SUM($F$6:$F$14)) -> 2.0790455 | G29: =G13+G13*($G$15/SUM($G$6:$G$14)) -> 1.0200542 | H29: =H13+H13*($H$15/SUM($H$6:$H$14)) -> 2.0421053 | I29: =I13+I13*($I$15/SUM($I$6:$I$14)) -> 2.0074396 | J29: =J13+J13*($J$15/SUM($J$6:$J$14)) -> 3.0067655 | K29: =K13+K13*($K$15/SUM($K$6:$K$14)) -> 6.1223922 | L29: =L13+L13*($L$15/SUM($L$6:$L$14)) -> 1.0164242
B30: De 50 y más años | C30: =C14+C14*($C$15/SUM($C$6:$C$14)) -> 0 | D30: =D14+D14*($D$15/SUM($D$6:$D$14)) -> 0 | E30: =E14+E14*($E$15/SUM($E$6:$E$14)) -> 0 | F30: =F14+F14*($F$15/SUM($F$6:$F$14)) -> 0 | G30: =G14+G14*($G$15/SUM($G$6:$G$14)) -> 0 | H30: =H14+H14*($H$15/SUM($H$6:$H$14)) -> 0 | I30: =I14+I14*($I$15/SUM($I$6:$I$14)) -> 1.0037198 | J30: =J14+J14*($J$15/SUM($J$6:$J$14)) -> 2.0045103 | K30: 0 | L30: 0
B34: PROMEDIO
C35: 2010 | E35: 2020
B36: edad | C36: Hombre | D36: Mujer | E36: Hombre | F36: Mujer
B37: Menor de 15 años | C37: =(C22+E22+G22)/3 -> 3.0492626 | D37: =(D22+F22+H22)/3 -> 7.1674753 | E37: =(I22+K22)/2 -> 3.5463771 | F37: =(J22+L22)/2 -> 4.5243173
B38: De 15 a 19 años | C38: =(C23+E23+G23)/3 -> 302.97527 | D38: =(D23+F23+H23)/3 -> 290.46194 | E38: =(I23+K23)/2 -> 372.49082 | F38: =(J23+L23)/2 -> 334.41358
B39: De 20 a 24 años | C39: =(C24+E24+G24)/3 -> 465.64387 | D39: =(D24+F24+H24)/3 -> 445.1745 | E39: =(I24+K24)/2 -> 700.23956 | F39: =(J24+L24)/2 -> 699.22257
B40: De 25 a 29 años | C40: =(C25+E25+G25)/3 -> 390.5609 | D40: =(D25+F25+H25)/3 -> 373.07772 | E40: =(I25+K25)/2 -> 773.75146 | F40: =(J25+L25)/2 -> 740.85158
B41: De 30 a 34 años | C41: =(C26+E26+G26)/3 -> 207.7918 | D41: =(D26+F26+H26)/3 -> 232.87829 | E41: =(I26+K26)/2 -> 555.73192 | F41: =(J26+L26)/2 -> 559.06604
B42: De 35 a 39 años | C42: =(C27+E27+G27)/3 -> 115.28736 | D42: =(D27+F27+H27)/3 -> 111.06542 | E42: =(I27+K27)/2 -> 249.04312 | F42: =(J27+L27)/2 -> 238.93012
B43: De 40 a 44 años | C43: =(C28+E28+G28)/3 -> 21.68027 | D43: =(D28+F28+H28)/3 -> 20.45285 | E43: =(I28+K28)/2 -> 60.12996 | F43: =(J28+L28)/2 -> 58.477941
B44: De 45 a 49 años | C44: =(C29+E29+G29)/3 -> 0.67793155 | D44: =(D29+F29+H29)/3 -> 2.388457 | E44: =(I29+K29)/2 -> 4.0649159 | F44: =(J29+L29)/2 -> 2.0115948
B45: De 50 y más años | C45: =(C30+E30+G30)/3 -> 0 | D45: =(D30+F30+H30)/3 -> 0 | E45: 1 | F45: 1
B49: AGREGACIÓN DE GRUPOS
C50: 2010 | E50: 2020
...

Sheet Defunciones
A2: TABLA PRORRATEADA
A4: Edad inicial | B4: Edad Final | C4: 2010 | F4: 2020
C5: Total | D5: Hombre | E5: Mujer | F5: Total | G5: Hombre | H5: Mujer
A6: 0 | B6: 0 | C6: 32.491367 | D6: 19.421286 | E6: 13.070081 | F6: 40.068376 | G6: 20.034188 | H6: 20.034188
A7: 1 | B7: 4 | C7: 6.1162556 | D7: 5.1108647 | E7: 1.0053908 | F7: 3.0051282 | G7: 2.0034188 | H7: 1.0017094
A8: 5 | B8: 9 | C8: 5.0773005 | D8: 3.0665188 | E8: 2.0107817 | F8: 6.0102564 | G8: 5.008547 | H8: 1.0017094
A9: 10 | B9: 14 | C9: 5.0437363 | D9: 1.0221729 | E9: 4.0215633 | F9: 9.0153846 | G9: 3.0051282 | H9: 6.0102564
A10: 15 | B10: 19 | C10: 16.304421 | D10: 13.288248 | E10: 3.0161725 | F10: 29.049573 | G10: 26.044444 | H10: 3.0051282
A11: 20 | B11: 24 | C11: 27.430848 | D11: 17.37694 | E11: 10.053908 | F11: 58.099145 | G11: 45.076923 | H11: 13.022222
A12: 25 | B12: 29 | C12: 28.52015 | D12: 22.487805 | E12: 6.032345 | F12: 64.109402 | G12: 56.095726 | H12: 8.0136752
A13: 30 | B13: 34 | C13: 22.420676 | D13: 18.399113 | E13: 4.0215633 | F13: 83.14188 | G13: 66.112821 | H13: 17.02906
A14: 35 | B14: 39 | C14: 28.536932 | D14: 23.509978 | E14: 5.0269542 | F14: 104.17778 | G14: 82.140171 | H14: 22.037607
A15: 40 | B15: 44 | C15: 30.463803 | D15: 18.399113 | E15: 12.06469 | F15: 144.24615 | G15: 104.17778 | H15: 40.068376
A16: 45 | B16: 49 | C16: 42.763443 | D16: 32.709534 | E16: 10.053908 | F16: 194.33162 | G16: 133.22735 | H16: 61.104274
A17: 50 | B17: 54 | C17: 44.690314 | D17: 27.59867 | E17: 17.091644 | F17: 254.43419 | G17: 161.27521 | H17: 93.158974
... A24: 85 | B24: 100 | C24: 141.72808 | D24: 59.286031 | E24: 82.442049 | F24: 449.76752 | G24: 192.32821 | H24: 257.43932

Sheet Poblacion
A3: Grupos quinquenales | D3: Proyeccion mitad de año 2010 | H3: Proyeccion 2015 | L3: Proyeccion mitad de año 2020
A4: Edad inicial | B4: Edad final | D4: Hombres | E4: Mujeres | F4: Total | H4: Hombres | I4: Mujeres | J4: Total | L4: Hombres | M4: Mujeres | N4: Total
A5: 0 | B5: 0 | D5: 3907.1773 | E5: 3864.5627 | F5: 7771.74 | H5: 3489.4652 | I5: 3434.9375 | J5: 6924.4027 | L5: 3116.2172 | M5: 3052.8769 | N5: 6169.0941
A6: 1 | B6: 4 | D6: 18182.401 | E6: 17457.319 | F6: 35639.719 | H6: 16463.472 | I6: 15879.312 | J6: 32342.784 | L6: 14906.237 | M6: 14443.195 | N6: 29349.432
A7: 5 | B7: 9 | D7: 23465.682 | E7: 22393.196 | F7: 45858.879 | H7: 21268.819 | I7: 20519.665 | J7: 41788.483 | L7: 19276.589 | M7: 18801.983 | N7: 38078.571
A8: 10 | B8: 14 | D8: 22922.623 | E8: 22310.889 | F8: 45233.512 | H8: 21792.127 | I8: 21008.456 | J8: 42800.583 | L8: 20716.811 | M8: 19781.403 | N8: 40498.214
A9: 15 | B9: 19 | D9: 23496.644 | E9: 23208.308 | F9: 46704.953 | H9: 22486.187 | I9: 21864.279 | J9: 44350.466 | L9: 21518.666 | M9: 20597.411 | N9: 42116.077
A10: 20 | B10: 24 | D10: 22924.811 | E10: 23019.882 | F10: 45944.694 | H10: 22242.664 | I10: 22070.509 | J10: 44313.173 | L10: 21580.458 | M10: 21159.801 | N10: 42740.259
A11: 25 | B11: 29 | D11: 20143.504 | E11: 21174.039 | F11: 41317.543 | H11: 20521.443 | I11: 21228.894 | J11: 41750.337 | L11: 20906.686 | M11: 21283.921 | N11: 42190.607
A12: 30 | B12: 34 | D12: 18231.488 | E12: 20298.27 | F12: 38529.759 | H12: 18886.359 | I12: 20482.228 | J12: 39368.588 | L12: 19565.131 | M12: 20667.955 | N12: 40233.086
A13: 35 | B13: 39 | D13: 17984.079 | E13: 20433.987 | F13: 38418.067 | H13: 17948.718 | I13: 20033.235 | J13: 37981.953 | L13: 17913.407 | M13: 19640.129 | N13: 37553.535
A14: 40 | B14: 44 | D14: 16905.539 | E14: 18998.334 | F14: 35903.873 | H14: 16860.493 | I14: 19026.192 | J14: 35886.685 | L14: 16815.543 | M14: 19054.107 | N14: 35869.65
A15: 45 | B15: 49 | D15: 14722.889 | E15: 16342.192 | F15: 31065.081 | H15: 15680.661 | I15: 17731.96 | J15: 33412.621 | L15: 16701.316 | M15: 19240.775 | N15: 35942.091
A16: 50 | B16: 54 | D16: 12183.1 | E16: 13344.823 | F16: 25527.923 | H16: 13910.605 | I16: 15625.928 | J16: 29536.534 | L16: 15884.216 | M16: 18298.537 | N16: 34182.753
... A22: 80 | B22: 84 | D22: 706.93543 | E22: 1098.914 | F22: 1805.8494 | H22: 997.95081 | I22: 1413.6704 | J22: 2411.6212 | L22: 1409.0309 | M22: 1818.8317 | N22: 3227.8626
A23: 85 y mas | D23: 506.77963 | E23: 883.50148 | F23: 1390.2811 | H23: 684.50358 | I23: 1205.7388 | J23: 1890.2424 | L23: 924.70626 | M23: 1645.7853 | N23: 2570.4915
A24: TOTAL | D24: 238698.55 | E24: 248947.92 | F24: 487646.47 | H24: 243431.73 | I24: 254769.22 | J24: 498200.94 | L24: 252215.88 | M24: 265530.79 | N24: 517746.67

Sheet Tablas de vida
A2: HOMBRES 2010 | P2: MUJERES 2010
E3: poblacion lab2 | G3: TMI /1000 | T3: población lab 2 | V3: TMI /1000
A4: Edad | B4: n | C4: nax | D4: nDx | E4: nNx | F4: nMx | G4: nmx | H4: nqx | I4: npx | J4: lx | K4: ndx | L4: nLx | M4: Tx | N4: ex | P4: Edad | Q4: n | R4: nax | S4: nDx | T4: nNx | U4: nMx | V4: nmx | W4: nqx | X4: npx | Y4: lx | Z4: ndx | AA4: nLx | AB4: Tx | AC4: ex
A5: 0 | B5: 1 | C5: 0.5 | D5: 19.421286 | E5: 3907.1773 | F5: 0.0049706693 | G5: 0.012881684 | H5: 0.012799246 | I5: 0.98720075 | J5: 100000 | K5: 1279.9246 | L5: 99360.038 | M5: 8267746.5 | N5: 82.677465 | P5: 0 | Q5: 1 | R5: 0.5 | S5: 13.070081 | T5: 3864.5627 | U5: 0.0033820336 | V5: 0.0088152524 | W5: 0.0087765685 | X5: 0.99122343 | Y5: 100000 | Z5: 877.65685 | AA5: 99561.172 | AB5: 8648608.8 | AC5: 86.486088
A6: 1 | B6: 4 | C6: 2 | D6: 5.1108647 | E6: 18182.401 | F6: 0.00028108856 | G6: 0.00028108856 | H6: 0.0011237225 | I6: 0.99887628 | J6: 98720.075 | K6: 110.93397 | L6: 394658.43 | M6: 8168386.5 | N6: 82.742912 | P6: 1 | Q6: 4 | R6: 2 | S6: 1.0053908 | T6: 17457.319 | U6: 5.7591366e-05 | V6: 5.7591366e-05 | W6: 0.00023033893 | X6: 0.99976966 | Y6: 99122.343 | Z6: 22.831735 | AA6: 396443.71 | AB6: 8549047.6 | AC6: 86.247433
A7: 5 | B7: 5 | C7: 2.5 | D7: 3.0665188 | E7: 23465.682 | F7: 0.000130681 | G7: 0.000130681 | H7: 0.0006531916 | I7: 0.99934681 | J7: 98609.141 | K7: 64.410663 | L7: 492884.68 | M7: 7773728 | N7: 78.833746 | P7: 5 | Q7: 5 | R7: 2.5 | S7: 2.0107817 | T7: 22393.196 | U7: 8.9794313e-05 | V7: 8.9794313e-05 | W7: 0.0004488708 | X7: 0.99955113 | Y7: 99099.511 | Z7: 44.482877 | AA7: 495386.35 | AB7: 8152603.9 | AC7: 82.266843
A8: 10 | B8: 5 | C8: 2.5 | D8: 1.0221729 | E8: 22922.623 | F8: 4.4592319e-05 | G8: 4.4592319e-05 | H8: 0.00022293674 | I8: 0.99977706 | J8: 98544.731 | K8: 21.969241 | L8: 492668.73 | M8: 7280843.4 | N8: 73.88364 | P8: 10 | Q8: 5 | R8: 2.5 | S8: 4.0215633 | T8: 22310.889 | U8: 0.00018025115 | V8: 0.00018025115 | W8: 0.00090084979 | X8: 0.99909915 | Y8: 99055.029 | Z8: 89.233702 | AA8: 495052.06 | AB8: 7657217.6 | AC8: 77.302664
A9: 15 | B9: 5 | C9: 2.5 | D9: 13.288248 | E9: 23496.644 | F9: 0.00056553813 | G9: 0.00056553813 | H9: 0.0028236984 | I9: 0.9971763 | J9: 98522.761 | K9: 278.19856 | L9: 491918.31 | M9: 6788174.6 | N9: 68.899557 | P9: 15 | Q9: 5 | R9: 2.5 | S9: 3.0161725 | T9: 23208.308 | U9: 0.00012996089 | V9: 0.00012996089 | W9: 0.00064959342 | X9: 0.99935041 | Y9: 98965.795 | Z9: 64.287529 | AA9: 494668.26 | AB9: 7162165.5 | AC9: 72.370111
A10: 20 | B10: 5 | C10: 2.5 | D10: 17.37694 | E10: 22924.811 | F10: 0.00075799708 | G10: 0.00075799708 | H10: 0.003782817 | I10: 0.99621718 | J10: 98244.563 | K10: 371.6412 | L10: 490293.71 | M10: 6296256.3 | N10: 64.08758 | P10: 20 | Q10: 5 | R10: 2.5 | S10: 10.053908 | T10: 23019.882 | U10: 0.0004367489 | V10: 0.0004367489 | W10: 0.0021813627 | X10: 0.99781864 | Y10: 98901.507 | Z10: 215.74006 | AA10: 493968.19 | AB10: 6667497.3 | AC10: 67.415527
A11: 25 | B11: 5 | C11: 2.5 | D11: 22.487805 | E11: 20143.504 | F11: 0.00111638 | G11: 0.00111638 | H11: 0.0055663646 | I11: 0.99443364 | J11: 97872.922 | K11: 544.79637 | L11: 488002.62 | M11: 5805962.6 | N11: 59.32144 | P11: 25 | Q11: 5 | R11: 2.5 | S11: 6.032345 | T11: 21174.039 | U11: 0.00028489344 | V11: 0.00028489344 | W11: 0.0014234534 | X11: 0.99857655 | Y11: 98685.767 | Z11: 140.47459 | AA11: 493077.65 | AB11: 6173529.1 | AC11: 62.557441
A12: 30 | B12: 5 | C12: 2.5 | D12: 18.399113 | E12: 18231.488 | F12: 0.0010091942 | G12: 0.0010091942 | H12: 0.0050332723 | I12: 0.99496673 | J12: 97328.125 | K12: 489.87896 | L12: 485415.93 | M12: 5317960 | N12: 54.639499 | P12: 30 | Q12: 5 | R12: 2.5 | S12: 4.0215633 | T12: 20298.27 | U12: 0.00019812345 | V12: 0.00019812345 | W12: 0.00099012682 | X12: 0.99900987 | Y12: 98545.293 | Z12: 97.572338 | AA12: 492482.53 | AB12: 5680451.4 | AC12: 57.643052
A13: 35 | B13: 5 | C13: 2.5 | D13: 23.509978 | E13: 17984.079 | F13: 0.0013072661 | G13: 0.0013072661 | H13: 0.0065150384 | I13: 0.99348496 | J13: 96838.246 | K13: 630.90489 | L13: 482613.97 | M13: 4832544.1 | N13: 49.903259 | P13: 35 | Q13: 5 | R13: 2.5 | S13: 5.0269542 | T13: 20433.987 | U13: 0.00024600946 | V13: 0.00024600946 | W13: 0.0012292913 | X13: 0.99877071 | Y13: 98447.72 | Z13: 121.02092 | AA13: 491936.05 | AB13: 5187968.9 | AC13: 52.697705
A14: 40 | B14: 5 | C14: 2.5 | D14: 18.399113 | E14: 16905.539 | F14: 0.0010883482 | G14: 0.0010883482 | H14: 0.005426975 | I14: 0.99457303 | J14: 96207.342 | K14: 522.11483 | L14: 479731.42 | M14: 4349930.1 | N14: 45.214118 | P14: 40 | Q14: 5 | R14: 2.5 | S14: 12.06469 | T14: 18998.334 | U14: 0.00063503938 | V14: 0.00063503938 | W14: 0.003170164 | X14: 0.99682984 | Y14: 98326.699 | Z14: 311.71176 | AA14: 490854.22 | AB14: 4696032.8 | AC14: 47.759488
A15: 45 | B15: 5 | C15: 2.5 | D15: 32.709534 | E15: 14722.889 | F15: 0.0022216791 | G15: 0.0022216791 | H15: 0.011047038 | I15: 0.98895296 | J15: 95685.227 | K15: 1057.0383 | L15: 475783.54 | M15: 3870198.7 | N15: 40.447191 | P15: 45 | Q15: 5 | R15: 2.5 | S15: 10.053908 | T15: 16342.192 | U15: 0.00061521172 | V15: 0.00061521172 | W15: 0.0030713348 | X15: 0.99692867 | Y15: 98014.988 | Z15: 301.03684 | AA15: 489322.35 | AB15: 4205178.6 | AC15: 42.903425
A16: 50 | B16: 5 | C16: 2.5 | D16: 27.59867 | E16: 12183.1 | F16: 0.002265324 | G16: 0.002265324 | H16: 0.011262835 | I16: 0.98873716 | J16: 94628.188 | K16: 1065.7817 | L16: 470476.49 | M16: 3394415.1 | N16: 35.871078 | P16: 50 | Q16: 5 | R16: 2.5 | S16: 17.091644 | T16: 13344.823 | U16: 0.0012807696 | V16: 0.0012807696 | W16: 0.0063834089 | X16: 0.99361659 | Y16: 97713.951 | Z16: 623.74811 | AA16: 487010.38 | AB16: 3715856.3 | AC16: 38.027899
... A23: 85 | B23: 0 | C23: 0 | D23: 59.286031 | E23: 506.77963 | F23: 0.11698582 | G23: 0.11698582 | H23: 1 | I23: 0 | J23: 56690.945 | K23: 56690.945 | L23: 484596.72 | M23: 484596.72 | N23: 8.5480445 | P23: 85 | Q23: 0 | R23: 0 | S23: 82.442049 | T23: 883.50148 | U23: 0.093312858 | V23: 0.093312858 | W23: 1 | X23: 0 | Y23: 59915.402 | Z23: 59915.402 | AA23: 642091.6 | AB23: 642091.6 | AC23: 10.716637
A27: HOMBRES 2020 | P27: MUJERES 2020
E28: poblacion lab2 | G28: TMI /1000 | T28: poblacion lab 2 | V28: TMI /1000
A29: Edad | B29: n | C29: nax | D29: nDx | E29: nNx | F29: nMx | G29: nmx | H29: nqx | I29: npx | J29: lx | K29: ndx | L29: nLx | M29: Tx | N29: ex | P29: Edad | Q29: n | R29: nax | S29: nDx | T29: nNx | U29: nMx | V29: nmx | W29: nqx | X29: npx | Y29: lx | Z29: ndx | AA29: nLx | AB29: Tx | AC29: ex
A30: 0 | B30: 1 | C30: 0.5 | D30: 20 | E30: 3116.2172 | F30: 0.0064180378 | G30: 0.0073668645 | H30: 0.0073398287 | I30: 0.99266017 | J30: 100000 | K30: 733.98287 | L30: 99633.009 | M30: 6869504.9 | N30: 68.695049 | P30: 0 | Q30: 1 | R30: 0.5 | S30: 20.034188 | T30: 3052.8769 | U30: 0.0065623963 | V30: 0.0075930218 | W30: 0.0075643038 | X30: 0.9924357 | Y30: 100000 | Z30: 756.43038 | AA30: 99621.785 | AB30: 7651685.4 | AC30: 76.516854
A31: 1 | B31: 4 | C31: 2 | D31: 2 | E31: 14906.237 | F31: 0.00013417202 | G31: 0.00013417202 | H31: 0.0005365441 | I31: 0.99946346 | J31: 99266.017 | K31: 53.260596 | L31: 396957.55 | M31: 6769871.9 | N31: 68.19929 | P31: 1 | Q31: 4 | R31: 2 | S31: 1.0017094 | T31: 14443.195 | U31: 6.9355113e-05 | V31: 6.9355113e-05 | W31: 0.00027738198 | X31: 0.99972262 | Y31: 99243.57 | Z31: 27.528377 | AA31: 396919.22 | AB31: 7552063.6 | AC31: 76.096251
A32: 5 | B32: 5 | C32: 2.5 | D32: 5 | E32: 19276.589 | F32: 0.00025938199 | G32: 0.00025938199 | H32: 0.0012960695 | I32: 0.99870393 | J32: 99212.757 | K32: 128.58663 | L32: 495742.32 | M32: 6372914.3 | N32: 64.234828 | P32: 5 | Q32: 5 | R32: 2.5 | S32: 1.0017094 | T32: 18801.983 | U32: 5.3276796e-05 | V32: 5.3276796e-05 | W32: 0.00026634851 | X32: 0.99973365 | Y32: 99216.041 | Z32: 26.426044 | AA32: 496014.14 | AB32: 7155144.4 | AC32: 72.11681
A33: 10 | B33: 5 | C33: 2.5 | D33: 3 | E33: 20716.811 | F33: 0.00014480993 | G33: 0.00014480993 | H33: 0.00072378764 | I33: 0.99927621 | J33: 99084.17 | K33: 71.715898 | L33: 495241.56 | M33: 5877172 | N33: 59.314944 | P33: 10 | Q33: 5 | R33: 2.5 | S33: 6.0102564 | T33: 19781.403 | U33: 0.00030383367 | V33: 0.00030383367 | W33: 0.0015180153 | X33: 0.99848198 | Y33: 99189.615 | Z33: 150.57135 | AA33: 495571.65 | AB33: 6659130.2 | AC33: 67.135357
A34: 15 | B34: 5 | C34: 2.5 | D34: 26 | E34: 21518.666 | F34: 0.0012082534 | G34: 0.0012082534 | H34: 0.0060230733 | I34: 0.99397693 | J34: 99012.454 | K34: 596.35927 | L34: 493571.37 | M34: 5381930.4 | N34: 54.356096 | P34: 15 | Q34: 5 | R34: 2.5 | S34: 3.0051282 | T34: 20597.411 | U34: 0.00014589835 | V34: 0.00014589835 | W34: 0.00072922575 | X34: 0.99927077 | Y34: 99039.044 | Z34: 72.221821 | AA34: 495014.66 | AB34: 6163558.6 | AC34: 62.233624
A35: 20 | B35: 5 | C35: 2.5 | D35: 45 | E35: 21580.458 | F35: 0.0020852199 | G35: 0.0020852199 | H35: 0.01037203 | I35: 0.98962797 | J35: 98416.095 | K35: 1020.7746 | L35: 489528.54 | M35: 4888359.1 | N35: 49.670321 | P35: 20 | Q35: 5 | R35: 2.5 | S35: 13.022222 | T35: 21159.801 | U35: 0.00061542271 | V35: 0.00061542271 | W35: 0.0030723865 | X35: 0.99692761 | Y35: 98966.822 | Z35: 304.06433 | AA35: 494073.95 | AB35: 5668543.9 | AC35: 57.277215
A36: 25 | B36: 5 | C36: 2.5 | D36: 56 | E36: 20906.686 | F36: 0.0026785689 | G36: 0.0026785689 | H36: 0.013303757 | I36: 0.98669624 | J36: 97395.32 | K36: 1295.7237 | L36: 483737.29 | M36: 4398830.5 | N36: 45.164701 | P36: 25 | Q36: 5 | R36: 2.5 | S36: 8.0136752 | T36: 21283.921 | U36: 0.00037651311 | V36: 0.00037651311 | W36: 0.0018807952 | X36: 0.9981192 | Y36: 98662.758 | Z36: 185.56444 | AA36: 492849.88 | AB36: 5174470 | AC36: 52.44603
A37: 30 | B37: 5 | C37: 2.5 | D37: 66 | E37: 19565.131 | F37: 0.0033733482 | G37: 0.0033733482 | H37: 0.016725687 | I37: 0.98327431 | J37: 96099.596 | K37: 1607.3318 | L37: 476479.65 | M37: 3915093.2 | N37: 40.739955 | P37: 30 | Q37: 5 | R37: 2.5 | S37: 17.02906 | T37: 20667.955 | U37: 0.00082393539 | V37: 0.00082393539 | W37: 0.0041112085 | X37: 0.99588879 | Y37: 98477.193 | Z37: 404.86028 | AA37: 491373.82 | AB37: 4681620.1 | AC37: 47.540146
A38: 35 | B38: 5 | C38: 2.5 | D38: 82 | E38: 17913.407 | F38: 0.0045775771 | G38: 0.0045775771 | H38: 0.022628921 | I38: 0.97737108 | J38: 94492.265 | K38: 2138.258 | L38: 467115.68 | M38: 3438613.6 | N38: 36.390424 | P38: 35 | Q38: 5 | R38: 2.5 | S38: 22.037607 | T38: 19640.129 | U38: 0.0011220704 | V38: 0.0011220704 | W38: 0.005594658 | X38: 0.99440534 | Y38: 98072.333 | Z38: 548.68116 | AA38: 488989.96 | AB38: 4190246.3 | AC38: 42.726079
A39: 40 | B39: 5 | C39: 2.5 | D39: 104 | E39: 16815.543 | F39: 0.0061847543 | G39: 0.0061847543 | H39: 0.030452912 | I39: 0.96954709 | J39: 92354.007 | K39: 2812.4485 | L39: 454738.91 | M39: 2971497.9 | N39: 32.175084 | P39: 40 | Q39: 5 | R39: 2.5 | S39: 40.068376 | T39: 19054.107 | U39: 0.0021028735 | V39: 0.0021028735 | W39: 0.010459381 | X39: 0.98954062 | Y39: 97523.652 | Z39: 1020.037 | AA39: 485068.17 | AB39: 3701256.3 | AC39: 37.952397
A40: 45 | B40: 5 | C40: 2.5 | D40: 133 | E40: 16701.316 | F40: 0.0079634444 | G40: 0.0079634444 | H40: 0.03903999 | I40: 0.96096001 | J40: 89541.558 | K40: 3495.7015 | L40: 438968.54 | M40: 2516759 | N40: 28.107161 | P40: 45 | Q40: 5 | R40: 2.5 | S40: 61.104274 | T40: 19240.775 | U40: 0.0031757699 | V40: 0.0031757699 | W40: 0.015753774 | X40: 0.98424623 | Y40: 96503.615 | Z40: 1520.2961 | AA40: 478717.33 | AB40: 3216188.2 | AC40: 33.327126
A41: 50 | B41: 5 | C41: 2.5 | D41: 161 | E41: 15884.216 | F41: 0.010135848 | G41: 0.010135848 | H41: 0.049426784 | I41: 0.95057322 | J41: 86045.857 | K41: 4252.97 | L41: 419596.86 | M41: 2077790.5 | N41: 24.147478 | P41: 50 | Q41: 5 | R41: 2.5 | S41: 93.158974 | T41: 18298.537 | U41: 0.0050910614 | V41: 0.0050910614 | W41: 0.025135392 | X41: 0.97486461 | Y41: 94983.319 | Z41: 2387.443 | AA41: 468947.99 | AB41: 2737470.8 | AC41: 28.820543
... A48: 85 | B48: 0 | C48: 0 | D48: 192 | E48: 924.70626 | F48: 0.2076335 | G48: 0.2076335 | H48: 1 | I48: 0 | J48: 17015.859 | K48: 17015.859 | L48: 81951.411 | M48: 81951.411 | N48: 4.8161784 | P48: 85 | Q48: 0 | R48: 0 | S48: 257.43932 | T48: 1645.7853 | U48: 0.15642339 | V48: 0.15642339 | W48: 1 | X48: 0 | Y48: 30269.688 | Z48: 30269.688 | AA48: 193511.26 | AB48: 193511.26 | AC48: 6.3929057

Sheet Fecundidad
A1: Tasa Bruta de Natalidad | F1: Tasa de Fecundidad General | S1: Tasa Especifica de Fecundidad | AE1: Tasa Global de Fecundidad | AI1: Tasa Bruta de Reproducción | AO1: Tasa Bruta de Reproducción
F5: 2010 | J5: 2020 | N5: Año | O5: Mujeres en Edad Reproductiva | P5: Nacimientos Totales | Q5: Tasa de Fecundidad General | S5: 2010 | Y5: 2020 | AI5: Año | AJ5: Nacimientos Mujeres | AK5: Nacimientos Totales | AL5: TGF | AM5: Tasa Bruta de Reproducción | AO5: 2010 | AU5: 2020 | BA5: Año | BB5: Nacimientos Mujeres | BC5: Nacimientos Totales | BD5: k | BE5: Tasa Bruta de Reproducción
A6: Año | B6: Población Total | C6: Nacimientos Totales | D6: Tasa Bruta de Natalidad | F6: Edad inicial | G6: Edad final | H6: Mujeres | J6: Edad inicial | K6: Edad final | L6: Mujeres | N6: 2010 | O6: =SUM(H11:H17) -> 143475.01 | P6: =Nacimientos!C60 -> 2990.3333 | Q6: =(P6/O6)*1000 -> 20.842189 | S6: Edad inicial | T6: Edad final | U6: Mujeres | V6: Nacimientos | W6: Tasa Especifica de Fecundidad | Y6: Edad inicial | Z6: Edad final | AA6: Mujeres | AB6: Nacimientos | AC6: Tasa Especifica de Fecundidad | AE6: Año | AF6: TEF | AG6: Tasa Global de Fecundidad | AI6: 2010 | AJ6: =Nacimientos!D59 -> 1482.6667 | AK6: =Nacimientos!C60 -> 2990.3333 | AL6: =AG7 -> 0.53302411 | AM6: =(AJ6/AK6)*AL6 -> 0.26428394 | AO6: Edad | AP6: nLx | AQ6: px | AR6: TEF | AS6: px*TEF | AU6: Edad | AV6: nLx | AW6: px | AX6: TEF | AY6: px*TEF | BA6: 2010 | BB6: =Nacimientos!D59 -> 1482.6667 | BC6: =Nacimientos!C60 -> 2990.3333 | BD6: =BB6/BC6 -> 0.49581986 | BE6: =5*BD6*AS26 -> 0.26103464
A7: 2010 | B7: =Poblacion!F24 -> 487646.47 | C7: =Nacimientos!C60 -> 2990.3333 | D7: =(C7/B7)*1000 -> 6.1321747 | F7: 0 | H7: =Poblacion!E5 -> 3864.5627 | J7: 0 | L7: =Poblacion!M5 -> 3052.8769 | N7: 2020 | O7: =SUM(L11:L17) -> 141644.1 | P7: =Nacimientos!E60 -> 5358 | Q7: =(P7/O7)*1000 -> 37.827203 | S7: 15 a 19 | U7: =H11 -> 23208.308 | V7: =W20+X20 -> 910.81837 | W7: =V7/U7 -> 0.039245358 | Y7: 15 a 19 | AA7: =L11 -> 20597.411 | AB7: =Y20+Z20 -> #VALUE! | AC7: =AB7/AA7 -> #VALUE! | AE7: 2010 | AF7: =SUM(W7:W13) -> 0.10660482 | AG7: =5*AF7 -> 0.53302411 | AI7: 2020 | AJ7: =Nacimientos!F59 -> 2638.5 | AK7: =Nacimientos!E60 -> 5358 | AL7: =AG8 -> #VALUE! | AM7: =(AJ7/AK7)*AL7 -> #VALUE! | AO7: 0 | AP7: ='Tablas de vida'!AA5 -> 99561.172 | AQ7: =AP7/(5*100000) -> 0.19912234 | AU7: 0 | AV7: ='Tablas de vida'!AA30 -> 99621.785 | AW7: =AV7/(5*100000) -> 0.19924357 | BA7: 2020 | BB7: =Nacimientos!F59 -> 2638.5 | BC7: =Nacimientos!E60 -> 5358 | BD7: =BB7/BC7 -> 0.49244121 | BE7: =5*BD7*AY26 -> #VALUE!
A8: 2020 | B8: =Poblacion!N24 -> 517746.67 | C8: =Nacimientos!E60 -> 5358 | D8: =(C8/B8)*1000 -> 10.348691 | F8: 1 a 4 | H8: =Poblacion!E6 -> 17457.319 | J8: 1 a 4 | L8: =Poblacion!M6 -> 14443.195 | S8: 20 a 24 | U8: =H12 -> 23019.882 | V8: =W21+X21 -> 763.63862 | W8: =V8/U8 -> 0.033173003 | Y8: 20 a 24 | AA8: =L12 -> 21159.801 | AB8: =Y21+Z21 -> #VALUE! | AC8: =AB8/AA8 -> #VALUE! | AE8: 2020 | AF8: =SUM(AC7:AC13) -> #VALUE! | AG8: =5*AF8 -> #VALUE! | AO8: 1 | AP8: ='Tablas de vida'!AA6 -> 396443.71 | AQ8: =AP8/(5*100000) -> 0.79288742 | AU8: 1 | AV8: ='Tablas de vida'!AA31 -> 396919.22 | AW8: =AV8/(5*100000) -> 0.79383844
F9: 5 a 9 | H9: =Poblacion!E7 -> 22393.196 | J9: 5 a 9 | L9: =Poblacion!M7 -> 18801.983 | S9: 25 a 29 | U9: =H13 -> 21174.039 | V9: =W22+X22 -> 440.6701 | W9: =V9/U9 -> 0.02081181 | Y9: 25 a 29 | AA9: =L13 -> 21283.921 | AB9: =Y22+Z22 -> #VALUE! | AC9: =AB9/AA9 -> #VALUE! | AO9: 5 | AP9: ='Tablas de vida'!AA7 -> 495386.35 | AQ9: =AP9/(5*100000) -> 0.9907727 | AU9: 5 | AV9: ='Tablas de vida'!AA32 -> 496014.14 | AW9: =AV9/(5*100000) -> 0.99202828
F10: 10 a 14 | H10: =Poblacion!E8 -> 22310.889 | J10: 10 a 14 | L10: =Poblacion!M8 -> 19781.403 | S10: 30 a 34 | U10: =H14 -> 20298.27 | V10: =W23+X23 -> 226.35279 | W10: =V10/U10 -> 0.011151334 | Y10: 30 a 34 | AA10: =L14 -> 20667.955 | AB10: =Y23+Z23 -> #VALUE! | AC10: =AB10/AA10 -> #VALUE! | AO10: 10 | AP10: ='Tablas de vida'!AA8 -> 495052.06 | AQ10: =AP10/(5*100000) -> 0.99010412 | AU10: 10 | AV10: ='Tablas de vida'!AA33 -> 495571.65 | AW10: =AV10/(5*100000) -> 0.9911433
F11: 15 a 19 | H11: =Poblacion!E9 -> 23208.308 | J11: 15 a 19 | L11: =Poblacion!M9 -> 20597.411 | S11: 35 a 39 | U11: =H15 -> 20433.987 | V11: =W24+X24 -> 42.133119 | W11: =V11/U11 -> 0.0020619138 | Y11: 35 a 39 | AA11: =L15 -> 19640.129 | AB11: =Y24+Z24 -> #VALUE! | AC11: =AB11/AA11 -> #VALUE! | AO11: 15 | AP11: ='Tablas de vida'!AA9 -> 494668.26 | AQ11: =AP11/(5*100000) -> 0.98933651 | AR11: =W7 -> 0.039245358 | AS11: =AQ11*AR11 -> 0.038826866 | AU11: 15 | AV11: ='Tablas de vida'!AA34 -> 495014.66 | AW11: =AV11/(5*100000) -> 0.99002933 | AX11: =AC7 -> #VALUE! | AY11: =AW11*AX11 -> #VALUE!
F12: 20 a 24 | H12: =Poblacion!E10 -> 23019.882 | J12: 20 a 24 | L12: =Poblacion!M10 -> 21159.801 | S12: 40 a 44 | U12: =H16 -> 18998.334 | V12: =W25+X25 -> 3.0663886 | W12: =V12/U12 -> 0.00016140303 | Y12: 40 a 44 | AA12: =L16 -> 19054.107 | AB12: =Y25+Z25 -> #VALUE! | AC12: =AB12/AA12 -> #VALUE! | AO12: 20 | AP12: ='Tablas de vida'!AA10 -> 493968.19 | AQ12: =AP12/(5*100000) -> 0.98793637 | AR12: =W8 -> 0.033173003 | AS12: =AQ12*AR12 -> 0.032772816 | AU12: 20 | AV12: ='Tablas de vida'!AA35 -> 494073.95 | AW12: =AV12/(5*100000) -> 0.9881479 | AX12: =AC8 -> #VALUE! | AY12: =AW12*AX12 -> #VALUE!
F13: 25 a 29 | H13: =Poblacion!E11 -> 21174.039 | J13: 25 a 29 | L13: =Poblacion!M11 -> 21283.921 | S13: 45 a 49 | U13: =H17 -> 16342.192 | V13: =W26+X26 -> 0 | W13: =V13/U13 -> 0 | Y13: 45 a 49 | AA13: =L17 -> 19240.775 | AB13: =Y26+Z26 -> 0 | AC13: =AB13/AA13 -> 0 | AO13: 25 | AP13: ='Tablas de vida'!AA11 -> 493077.65 | AQ13: =AP13/(5*100000) -> 0.9861553 | AR13: =W9 -> 0.02081181 | AS13: =AQ13*AR13 -> 0.020523677 | AU13: 25 | AV13: ='Tablas de vida'!AA36 -> 492849.88 | AW13: =AV13/(5*100000) -> 0.98569975 | AX13: =AC9 -> #VALUE! | AY13: =AW13*AX13 -> #VALUE!
F14: 30 a 34 | H14: =Poblacion!E12 -> 20298.27 | J14: 30 a 34 | L14: =Poblacion!M12 -> 20667.955 | S14: Suma | U14: =SUM(U7:U13) -> 143475.01 | V14: =SUM(V7:V13) -> 2386.6794 | Y14: SUMA | AA14: =SUM(AA7:AA13) -> 141644.1 | AB14: =SUM(AB7:AB13) -> #VALUE! | AO14: 30 | AP14: ='Tablas de vida'!AA12 -> 492482.53 | AQ14: =AP14/(5*100000) -> 0.98496506 | AR14: =W10 -> 0.011151334 | AS14: =AQ14*AR14 -> 0.010983674 | AU14: 30 | AV14: ='Tablas de vida'!AA37 -> 491373.82 | AW14: =AV14/(5*100000) -> 0.98274763 | AX14: =AC10 -> #VALUE! | AY14: =AW14*AX14 -> #VALUE!
F15: 35 a 39 | H15: =Poblacion!E13 -> 20433.987 | J15: 35 a 39 | L15: =Poblacion!M13 -> 19640.129 | AO15: 35 | AP15: ='Tablas de vida'!AA13 -> 491936.05 | AQ15: =AP15/(5*100000) -> 0.9838721 | AR15: =W11 -> 0.0020619138 | AS15: =AQ15*AR15 -> 0.0020286594 | AU15: 35 | AV15: ='Tablas de vida'!AA38 -> 488989.96 | AW15: =AV15/(5*100000) -> 0.97797992 | AX15: =AC11 -> #VALUE! | AY15: =AW15*AX15 -> #VALUE!
F16: 40 a 44 | H16: =Poblacion!E14 -> 18998.334 | J16: 40 a 44 | L16: =Poblacion!M14 -> 19054.107 | AO16: 40 | AP16: ='Tablas de vida'!AA14 -> 490854.22 | AQ16: =AP16/(5*100000) -> 0.98170844 | AR16: =W12 -> 0.00016140303 | AS16: =AQ16*AR16 -> 0.00015845071 | AU16: 40 | AV16: ='Tablas de vida'!AA39 -> 485068.17 | AW16: =AV16/(5*100000) -> 0.97013633 | AX16: =AC12 -> #VALUE! | AY16: =AW16*AX16 -> #VALUE!
F17: 45 a 49 | H17: =Poblacion!E15 -> 16342.192 | J17: 45 a 49 | L17: =Poblacion!M15 -> 19240.775 | T17: 2010 | Y17: 2020 | AO17: 45 | AP17: ='Tablas de vida'!AA15 -> 489322.35 | AQ17: =AP17/(5*100000) -> 0.97864469 | AR17: =W13 -> 0 | AS17: =AQ17*AR17 -> 0 | AU17: 45 | AV17: ='Tablas de vida'!AA40 -> 478717.33 | AW17: =AV17/(5*100000) -> 0.95743467 | AX17: =AC13 -> 0 | AY17: =AW17*AX17 -> 0
F18: 50 a 54 | H18: =Poblacion!E16 -> 13344.823 | J18: 50 a 54 | L18: =Poblacion!M16 -> 18298.537 | T18: edad de la madre | W18: nacimientos | Y18: edad de la madre | AB18: Nacimientos | AO18: 50 | AP18: ='Tablas de vida'!AA16 -> 487010.38 | AQ18: =AP18/(5*100000) -> 0.97402077 | AU18: 50 | AV18: ='Tablas de vida'!AA41 -> 468947.99 | AW18: =AV18/(5*100000) -> 0.93789597
F19: 55 a 59 | H19: =Poblacion!E17 -> 9636.4135 | J19: 55 a 59 | L19: =Poblacion!M17 -> 15678.932 | T19: De 15 a 19 años | W19: =Nacimientos!C52+Nacimientos!D52 -> 603.65396 | Y19: De 15 a 19 años | AB19: =Nacimientos!E52+Nacimientos!F52 -> 714.97509 | AJ19: 55 | AK19: ='Tablas de vida'!AA17 -> 482681.25 | AL19: =AK19/(5*100000) -> 0.9653625 | AO19: 55 | AP19: ='Tablas de vida'!AA17 -> 482681.25 | AQ19: =AP19/(5*100000) -> 0.9653625 | AU19: 55 | AV19: ='Tablas de vida'!AA42 -> 452640.94 | AW19: =AV19/(5*100000) -> 0.90528187
F20: 60 a 64 | H20: =Poblacion!E18 -> 6266.2199 | J20: 60 a 64 | L20: =Poblacion!M18 -> 12732.034 | T20: De 20 a 24 años | W20: =Nacimientos!C53+Nacimientos!D53 -> 910.81837 | Y20: De 20 a 24 años | AB20: =Nacimientos!E53+Nacimientos!F53 -> 1399.4621 | AJ20: 60 | AK20: ='Tablas de vida'!AA18 -> 475713.54 | AL20: =AK20/(5*100000) -> 0.95142707 | AO20: 60 | AP20: ='Tablas de vida'!AA18 -> 475713.54 | AQ20: =AP20/(5*100000) -> 0.95142707 | AU20: 60 | AV20: ='Tablas de vida'!AA43 -> 426854.17 | AW20: =AV20/(5*100000) -> 0.85370834
F21: 65 a 69 | H21: =Poblacion!E19 -> 3961.1944 | J21: 65 a 69 | L21: =Poblacion!M19 -> 9128.2048 | T21: De 25 a 29 años | W21: =Nacimientos!C54+Nacimientos!D54 -> 763.63862 | Y21: De 25 a 29 años | AB21: =Nacimientos!E54+Nacimientos!F54 -> 1514.603 | AJ21: 65 | AK21: ='Tablas de vida'!AA19 -> 462995.89 | AL21: =AK21/(5*100000) -> 0.92599178 | AO21: 65 | AP21: ='Tablas de vida'!AA19 -> 462995.89 | AQ21: =AP21/(5*100000) -> 0.92599178 | AU21: 65 | AV21: ='Tablas de vida'!AA44 -> 391227.59 | AW21: =AV21/(5*100000) -> 0.78245518
F22: 70 a 74 | H22: =Poblacion!E20 -> 2557.5248 | J22: 70 a 74 | L22: =Poblacion!M20 -> 5485.4794 | T22: De 30 a 34 años | W22: =Nacimientos!C55+Nacimientos!D55 -> 440.6701 | Y22: De 30 a 34 años | AB22: =Nacimientos!E55+Nacimientos!F55 -> 1114.798 | AJ22: 70 | AK22: ='Tablas de vida'!AA20 -> 439781.16 | AL22: =AK22/(5*100000) -> 0.87956233 | AO22: 70 | AP22: ='Tablas de vida'!AA20 -> 439781.16 | AQ22: =AP22/(5*100000) -> 0.87956233 | AU22: 70 | AV22: ='Tablas de vida'!AA45 -> 341003.56 | AW22: =AV22/(5*100000) -> 0.68200711
F23: 75 a 79 | H23: =Poblacion!E21 -> 1698.348 | J23: 75 a 79 | L23: =Poblacion!M21 -> 3019.4269 | T23: De 35 a 39 años | W23: =Nacimientos!C56+Nacimientos!D56 -> 226.35279 | Y23: De 35 a 39 años | AB23: =Nacimientos!E56+Nacimientos!F56 -> 487.97324 | AJ23: 75 | AK23: ='Tablas de vida'!AA21 -> 394168.51 | AL23: =AK23/(5*100000) -> 0.78833702 | AO23: 75 | AP23: ='Tablas de vida'!AA21 -> 394168.51 | AQ23: =AP23/(5*100000) -> 0.78833702 | AU23: 75 | AV23: ='Tablas de vida'!AA46 -> 271545 | AW23: =AV23/(5*100000) -> 0.54309
F24: 80 a 84 | H24: =Poblacion!E22 -> 1098.914 | J24: 80 a 84 | L24: =Poblacion!M22 -> 1818.8317 | T24: De 40 a 44 años | W24: =Nacimientos!C57+Nacimientos!D57 -> 42.133119 | Y24: De 40 a 44 años | AB24: =Nacimientos!E57+Nacimientos!F57 -> 118.6079 | AJ24: 80 | AK24: ='Tablas de vida'!AA22 -> 331413.95 | AL24: =AK24/(5*100000) -> 0.6628279 | AO24: 80 | AP24: ='Tablas de vida'!AA22 -> 331413.95 | AQ24: =AP24/(5*100000) -> 0.6628279 | AU24: 80 | AV24: ='Tablas de vida'!AA47 -> 191740.33 | AW24: =AV24/(5*100000) -> 0.38348066
F25: 85 y más | H25: =Poblacion!E23 -> 883.50148 | J25: 85 y más | L25: =Poblacion!M23 -> 1645.7853 | T25: De 45 a 49 años | W25: =Nacimientos!C58+Nacimientos!D58 -> 3.0663886 | Y25: De 45 a 49 años | AB25: =Nacimientos!E58+Nacimientos!F58 -> 7.5806258 | AJ25: 85 | AK25: ='Tablas de vida'!AA23 -> 642091.6 | AL25: =AK25/(5*100000) -> 1.2841832 | AO25: 85 | AP25: ='Tablas de vida'!AA23 -> 642091.6 | AQ25: =AP25/(5*100000) -> 1.2841832 | AU25: 85 | AV25: ='Tablas de vida'!AA48 -> 193511.26 | AW25: =AV25/(5*100000) -> 0.38702253
F26: Suma | H26: =SUM(H11:H17) -> 143475.01 | J26: Suma | L26: =SUM(L11:L17) -> 141644.1 | AM26: Suma | AN26: =SUM(AS11:AS17) -> 0.10529414 | AR26: Suma | AS26: =SUM(AS11:AS17) -> 0.10529414 | AX26: Suma | AY26: =SUM(AY11:AY17) -> #VALUE!
T28: Tasa de crecimiento | X28: Proyeccion a 2025
T29: Edad de la madre | U29: tasa | X29: Edad de la madre | Y29: Nacimientos
T30: De 15 a 19 años | U30: =(AB19/W19)^(1/$U$39)-1 -> 0.017054558 | X30: De 15 a 19 años | Y30: =AB19*(1+U30)^$U$41 -> 778.09439
T31: De 20 a 24 años | U31: =(AB20/W20)^(1/$U$39)-1 -> 0.043848858 | X31: De 20 a 24 años | Y31: =AB20*(1+U31)^$U$41 -> 1734.6039
T32: De 25 a 29 años | U32: =(AB21/W21)^(1/$U$39)-1 -> 0.070820489 | X32: De 25 a 29 años | Y32: =AB21*(1+U32)^$U$41 -> 2132.8662
T33: De 30 a 34 años | U33: =(AB22/W22)^(1/$U$39)-1 -> 0.097173122 | X33: De 30 a 34 años | Y33: =AB22*(1+U33)^$U$41 -> 1772.8921
T34: De 35 a 39 años | U34: =(AB23/W23)^(1/$U$39)-1 -> 0.079775881 | X34: De 35 a 39 años | Y34: =AB23*(1+U34)^$U$41 -> 716.39979
T35: De 40 a 44 años | U35: =(AB24/W24)^(1/$U$39)-1 -> 0.10895032 | X35: De 40 a 44 años | Y35: =AB24*(1+U35)^$U$41 -> 198.97436
T36: De 45 a 49 años | U36: =(AB25/W25)^(1/$U$39)-1 -> 0.094650575 | X36: De 45 a 49 años | Y36: =AB25*(1+U36)^$U$41 -> 11.917639
T38: Fechas | U38: n
T39: 40359 | U39: 10.008218
T40: 44012
T41: 45838 | U41: 5.0027397
